Workbook

Sheet Planilha1
G2: SELECIONE O ESTADO DESEJADO ---> | H2: PR | M2: PREÇO S/REPASSE | O2: PREÇO C/REPASSE
G3: ALÍCOTA ICMS: | H3: =VLOOKUP($H$2,[1]REPASSE!A:D,3,0) -> 0.195 | I3: =IF(OR(H2="SP",H2="MG",H2="RJ"),"18%","")
G4: % REPASSE: | H4: =VLOOKUP($H$2,[1]REPASSE!A:D,4,0) -> 0.0852
G5: PROCV PF por UF--> | H5: =VLOOKUP($H$2,[2]BASE!$D:$H,5,0) -> 14
G6: PROCV PF 18% --> | H6: =IF(OR(H2="SP",H2="MG",H2="RJ"),6,"")
G7: PARÂMETRO PROCV
B8: Linha | C8: SAP | D8: Ean | E8: Cluster | F8: Família | G8: Produto | H8: Lista | I8: Apresentação | J8: ESTRATEGICOS COMERCIAL | K8: FECP RJ | L8: PF R$ | M8: Atacado | N8: % Repasse | O8: Atacado | P8: Atacado | U8: =_xlfn.XLOOKUP(H3,T10:T22,U10:U22) -> 16
B9: OTC | C9: 33022 | D9: 7896004712673 | E9: INVERNO | F9: ALERGALIV | G9: ALERGALIV CPR 10mg x 15 | H9: NEGATIVA | I9: 3 BLT X 5 COMP | J9: OUTROS | K9: NÃO | L9: =IF(ISERROR(VLOOKUP($C9,[1]TABELA_PREÇOS!B:W,$U$8,FALSE))=TRUE,"",VLOOKUP($C9,[1]TABELA_PREÇOS!B:W,$U$8,FALSE)) -> 18.27 | M9: =$L9-($L9*P9) -> 1.2161426 | N9: =$H$4 -> 0.0852 | O9: =M9*(1-$N9) -> 1.1125272 | P9: =_xlfn.XLOOKUP(C9&$H$2,[1]POLITICA!A:A,[1]POLITICA!F:F)/100 -> 0.933435 | T9: % | U9: coluna
B10: OTC | C10: 32568 | D10: 7894916325684 | E10: INVERNO | F10: ALERGALIV | G10: ALERGALIV XAR. 1.00MG 100ML x 1 /ML | H10: NEGATIVA | I10: FR X 100 ML | J10: OUTROS | K10: NÃO | L10: =IF(ISERROR(VLOOKUP($C10,[1]TABELA_PREÇOS!B:W,$U$8,FALSE))=TRUE,"",VLOOKUP($C10,[1]TABELA_PREÇOS!B:W,$U$8,FALSE)) -> 48.11 | M10: =$L10-($L10*P10) -> 5.2381133 | N10: =$H$4 -> 0.0852 | O10: =M10*(1-$N10) -> 4.791826 | P10: =_xlfn.XLOOKUP(C10&$H$2,[1]POLITICA!A:A,[1]POLITICA!F:F)/100 -> 0.89112215 | T10: 0.2 | U10: 15
B11: TAR | C11: 32468 | D11: 7896004778334 | E11: DERMA | F11: ALLOVITA | G11: ALLOVITA 50MG/ML SOL CAPI 2 FR50ML-L | H11: NEGATIVA | I11: FR C/ 50ML | J11: SUPER MARCAS | K11: NÃO | L11: =IF(ISERROR(VLOOKUP($C11,[1]TABELA_PREÇOS!B:W,$U$8,FALSE))=TRUE,"",VLOOKUP($C11,[1]TABELA_PREÇOS!B:W,$U$8,FALSE)) -> 71.81 | M11: =$L11-($L11*P11) -> 48.597688 | N11: =$H$4 -> 0.0852 | O11: =M11*(1-$N11) -> 44.457165 | P11: =_xlfn.XLOOKUP(C11&$H$2,[1]POLITICA!A:A,[1]POLITICA!F:F)/100 -> 0.32324623
B12: TAR | C12: 32469 | D12: 7896004778341 | E12: DERMA | F12: ALLOVITA | G12: ALLOVITA 50MG/ML SOL CAPI 3 FR50ML-L | H12: NEGATIVA | I12: FR C/ 50ML | J12: SUPER MARCAS | K12: NÃO | L12: =IF(ISERROR(VLOOKUP($C12,[1]TABELA_PREÇOS!B:W,$U$8,FALSE))=TRUE,"",VLOOKUP($C12,[1]TABELA_PREÇOS!B:W,$U$8,FALSE)) -> 103.16 | M12: =$L12-($L12*P12) -> 66.864045 | N12: =$H$4 -> 0.0852 | O12: =M12*(1-$N12) -> 61.167228 | P12: =_xlfn.XLOOKUP(C12&$H$2,[1]POLITICA!A:A,[1]POLITICA!F:F)/100 -> 0.35184137 | T12: 0.18 | U12: 18
B13: TAR | C13: 32576 | D13: 7894916325769 | E13: DERMA | F13: ALLOVITA | G13: ALLOVITA 50MG/ML SOL CAPILAR FR50ML-L | H13: NEGATIVA | I13: FR C/ 50ML | J13: SUPER MARCAS | K13: NÃO | L13: =IF(ISERROR(VLOOKUP($C13,[1]TABELA_PREÇOS!B:W,$U$8,FALSE))=TRUE,"",VLOOKUP($C13,[1]TABELA_PREÇOS!B:W,$U$8,FALSE)) -> 48.29 | M13: =$L13-($L13*P13) -> 32.169426 | N13: =$H$4 -> 0.0852 | O13: =M13*(1-$N13) -> 29.428591 | P13: =_xlfn.XLOOKUP(C13&$H$2,[1]POLITICA!A:A,[1]POLITICA!F:F)/100 -> 0.33382842 | T13: 0.17 | U13: 20
B14: OTC | C14: 60638 | D14: 7896004726793 | E14: OTC | F14: BENGUE | G14: BALSAMO BENGUE AEROSOL 60G | H14: =_xlfn.XLOOKUP($C14,[1]TABELA_PREÇOS!$B:$B,[1]TABELA_PREÇOS!J:J) -> NEGATIVA | J14: OTC | K14: NÃO | L14: =IF(ISERROR(VLOOKUP($C14,[1]TABELA_PREÇOS!B:W,$U$8,FALSE))=TRUE,"",VLOOKUP($C14,[1]TABELA_PREÇOS!B:W,$U$8,FALSE)) -> 37.16 | M14: =$L14-($L14*P14) -> 24.8972 | N14: =$H$4 -> 0.0852 | O14: =M14*(1-$N14) -> 22.775959 | P14: =_xlfn.XLOOKUP(C14&$H$2,[1]POLITICA!A:A,[1]POLITICA!F:F)/100 -> 0.33 | T14: 0.175 | U14: 19
B15: OTC | C15: 60649 | D15: 7896004754130 | E15: OTC | F15: BENGUE | G15: BALSAMO BENGUE AEROSSOL 120G | H15: =_xlfn.XLOOKUP($C15,[1]TABELA_PREÇOS!$B:$B,[1]TABELA_PREÇOS!J:J) -> NEGATIVA | J15: OTC | K15: NÃO | L15: =IF(ISERROR(VLOOKUP($C15,[1]TABELA_PREÇOS!B:W,$U$8,FALSE))=TRUE,"",VLOOKUP($C15,[1]TABELA_PREÇOS!B:W,$U$8,FALSE)) -> 58.08 | M15: =$L15-($L15*P15) -> 38.9136 | N15: =$H$4 -> 0.0852 | O15: =M15*(1-$N15) -> 35.598161 | P15: =_xlfn.XLOOKUP(C15&$H$2,[1]POLITICA!A:A,[1]POLITICA!F:F)/100 -> 0.33 | T15: 0.12 | U15: 21
B16: OTC | C16: 1583 | D16: 7896004753638 | E16: OTC | F16: BENGUE | G16: BALSAMO BENGUE GEL 60G - E | H16: =_xlfn.XLOOKUP($C16,[1]TABELA_PREÇOS!$B:$B,[1]TABELA_PREÇOS!J:J) -> NEGATIVA | J16: OTC | K16: NÃO | L16: =IF(ISERROR(VLOOKUP($C16,[1]TABELA_PREÇOS!B:W,$U$8,FALSE))=TRUE,"",VLOOKUP($C16,[1]TABELA_PREÇOS!B:W,$U$8,FALSE)) -> 36.26 | M16: =$L16-($L16*P16) -> 24.2942 | N16: =$H$4 -> 0.0852 | O16: =M16*(1-$N16) -> 22.224334 | P16: =_xlfn.XLOOKUP(C16&$H$2,[1]POLITICA!A:A,[1]POLITICA!F:F)/100 -> 0.33 | T16: 0.19 | U16: 17
B17: OTC | C17: 60016 | D17: 7896004817576 | E17: OTC | F17: BENGUE | G17: BALSAMO BENGUE GEL20G | H17: =_xlfn.XLOOKUP($C17,[1]TABELA_PREÇOS!$B:$B,[1]TABELA_PREÇOS!J:J) -> NEGATIVA | J17: OTC | K17: NÃO | L17: =IF(ISERROR(VLOOKUP($C17,[1]TABELA_PREÇOS!B:W,$U$8,FALSE))=TRUE,"",VLOOKUP($C17,[1]TABELA_PREÇOS!B:W,$U$8,FALSE)) -> 21.36 | M17: =$L17-($L17*P17) -> 14.3112 | N17: =$H$4 -> 0.0852 | O17: =M17*(1-$N17) -> 13.091886 | P17: =_xlfn.XLOOKUP(C17&$H$2,[1]POLITICA!A:A,[1]POLITICA!F:F)/100 -> 0.33 | T17: 0.21 | U17: 13
B18: OTC | C18: 60015 | D18: 7896004817569 | E18: OTC | F18: BENGUE | G18: BALSAMO BENGUE POM20G | H18: =_xlfn.XLOOKUP($C18,[1]TABELA_PREÇOS!$B:$B,[1]TABELA_PREÇOS!J:J) -> NEGATIVA | J18: OTC | K18: NÃO | L18: =IF(ISERROR(VLOOKUP($C18,[1]TABELA_PREÇOS!B:W,$U$8,FALSE))=TRUE,"",VLOOKUP($C18,[1]TABELA_PREÇOS!B:W,$U$8,FALSE)) -> 22.49 | M18: =$L18-($L18*P18) -> 15.0683 | N18: =$H$4 -> 0.0852 | O18: =M18*(1-$N18) -> 13.784481 | P18: =_xlfn.XLOOKUP(C18&$H$2,[1]POLITICA!A:A,[1]POLITICA!F:F)/100 -> 0.33 | T18: 0.22 | U18: 12
B19: OTC | C19: 1582 | D19: 7896004753621 | E19: OTC | F19: BENGUE | G19: BALSAMO BENGUE POMADA 60G - E | H19: =_xlfn.XLOOKUP($C19,[1]TABELA_PREÇOS!$B:$B,[1]TABELA_PREÇOS!J:J) -> NEGATIVA | J19: OTC | K19: NÃO | L19: =IF(ISERROR(VLOOKUP($C19,[1]TABELA_PREÇOS!B:W,$U$8,FALSE))=TRUE,"",VLOOKUP($C19,[1]TABELA_PREÇOS!B:W,$U$8,FALSE)) -> 38.11 | M19: =$L19-($L19*P19) -> 25.5337 | N19: =$H$4 -> 0.0852 | O19: =M19*(1-$N19) -> 23.358229 | P19: =_xlfn.XLOOKUP(C19&$H$2,[1]POLITICA!A:A,[1]POLITICA!F:F)/100 -> 0.33 | T19: 0.205 | U19: 14
B20: OTC | C20: 2723 | D20: =_xlfn.XLOOKUP(C20,[1]TABELA_PREÇOS!B:B,[1]TABELA_PREÇOS!C:C) -> 7896004793740 | E20: OTC | F20: =_xlfn.XLOOKUP($C20,[1]TABELA_PREÇOS!$B:$B,[1]TABELA_PREÇOS!E:E) -> BALSAMO BENGUE | G20: =_xlfn.XLOOKUP($C20,[1]TABELA_PREÇOS!$B:$B,[1]TABELA_PREÇOS!G:G) -> BENGPRO | H20: =_xlfn.XLOOKUP($C20,[1]TABELA_PREÇOS!$B:$B,[1]TABELA_PREÇOS!J:J) -> NEGATIVA | J20: OTC | K20: NÃO | L20: =IF(ISERROR(VLOOKUP($C20,[1]TABELA_PREÇOS!B:W,$U$8,FALSE))=TRUE,"",VLOOKUP($C20,[1]TABELA_PREÇOS!B:W,$U$8,FALSE)) -> 40.11 | M20: =$L20-($L20*P20) -> 26.8737 | N20: =$H$4 -> 0.0852 | O20: =M20*(1-$N20) -> 24.584061 | P20: =_xlfn.XLOOKUP(C20&$H$2,[1]POLITICA!A:A,[1]POLITICA!F:F)/100 -> 0.33 | T20: 0.195 | U20: 16
B21: OTC | C21: 2724 | D21: =_xlfn.XLOOKUP(C21,[1]TABELA_PREÇOS!B:B,[1]TABELA_PREÇOS!C:C) -> 7896004793757 | E21: OTC | F21: =_xlfn.XLOOKUP($C21,[1]TABELA_PREÇOS!$B:$B,[1]TABELA_PREÇOS!E:E) -> BALSAMO BENGUE | G21: BENGPRO AEROSOL 60G - E | H21: =_xlfn.XLOOKUP($C21,[1]TABELA_PREÇOS!$B:$B,[1]TABELA_PREÇOS!J:J) -> NEGATIVA | J21: OTC | K21: NÃO | L21: =IF(ISERROR(VLOOKUP($C21,[1]TABELA_PREÇOS!B:W,$U$8,FALSE))=TRUE,"",VLOOKUP($C21,[1]TABELA_PREÇOS!B:W,$U$8,FALSE)) -> 40.51 | M21: =$L21-($L21*P21) -> 27.1417 | N21: =$H$4 -> 0.0852 | O21: =M21*(1-$N21) -> 24.829227 | P21: =_xlfn.XLOOKUP(C21&$H$2,[1]POLITICA!A:A,[1]POLITICA!F:F)/100 -> 0.33 | T21: 0.23 | U21: 10
B22: OTC | C22: 36003 | D22: 7896004810140 | E22: GASTROINTESTINAL | F22: BISMU-JET | G22: BISMU-JET LIQD 20ML x 1 | H22: NEGATIVA | I22: FR X 20 ML | J22: SUPER MARCAS | K22: NÃO | L22: =IF(ISERROR(VLOOKUP($C22,[1]TABELA_PREÇOS!B:W,$U$8,FALSE))=TRUE,"",VLOOKUP($C22,[1]TABELA_PREÇOS!B:W,$U$8,FALSE)) -> 33.24 | M22: =$L22-($L22*P22) -> 14.30928 | N22: =$H$4 -> 0.0852 | O22: =M22*(1-$N22) -> 13.09013 | P22: =_xlfn.XLOOKUP(C22&$H$2,[1]POLITICA!A:A,[1]POLITICA!F:F)/100 -> 0.56951624 | T22: 0.225 | U22: 11
B23: OTC | C23: 2532 | D23: 7896004780085 | E23: OTC | F23: CALADRYL | G23: CALADRYL AEROSSOL POS SOL 150ML NP - E | H23: =_xlfn.XLOOKUP($C23,[1]TABELA_PREÇOS!$B:$B,[1]TABELA_PREÇOS!J:J) -> NEGATIVA | J23: OTC | K23: NÃO | L23: =IF(ISERROR(VLOOKUP($C23,[1]TABELA_PREÇOS!B:W,$U$8,FALSE))=TRUE,"",VLOOKUP($C23,[1]TABELA_PREÇOS!B:W,$U$8,FALSE)) -> 40.13 | M23: =$L23-($L23*P23) -> 28.8936 | N23: 0 | O23: =M23*(1-$N23) -> 28.8936 | P23: =_xlfn.XLOOKUP(C23&$H$2,[1]POLITICA!A:A,[1]POLITICA!F:F)/100 -> 0.28
B24: OTC | C24: 2631 | D24: =_xlfn.XLOOKUP(C24,[1]TABELA_PREÇOS!B:B,[1]TABELA_PREÇOS!C:C) -> 7896004800004 | E24: OTC | F24: =_xlfn.XLOOKUP($C24,[1]TABELA_PREÇOS!$B:$B,[1]TABELA_PREÇOS!E:E) -> CALADRYL | G24: CALADRYL CALMANTE X 200 ML | H24: =_xlfn.XLOOKUP($C24,[1]TABELA_PREÇOS!$B:$B,[1]TABELA_PREÇOS!J:J) -> NEGATIVA | J24: OTC | K24: NÃO | L24: =IF(ISERROR(VLOOKUP($C24,[1]TABELA_PREÇOS!B:W,$U$8,FALSE))=TRUE,"",VLOOKUP($C24,[1]TABELA_PREÇOS!B:W,$U$8,FALSE)) -> 67.8 | M24: =$L24-($L24*P24) -> 48.816 | N24: =$H$4 -> 0.0852 | O24: =M24*(1-$N24) -> 44.656877 | P24: =_xlfn.XLOOKUP(C24&$H$2,[1]POLITICA!A:A,[1]POLITICA!F:F)/100 -> 0.28
B25: OTC | C25: 2531 | D25: 7896004780078 | E25: OTC | F25: CALADRYL | G25: CALADRYL CREME POS SOL 28G NP - E | H25: =_xlfn.XLOOKUP($C25,[1]TABELA_PREÇOS!$B:$B,[1]TABELA_PREÇOS!J:J) -> NEGATIVA | J25: OTC | K25: NÃO | L25: =IF(ISERROR(VLOOKUP($C25,[1]TABELA_PREÇOS!B:W,$U$8,FALSE))=TRUE,"",VLOOKUP($C25,[1]TABELA_PREÇOS!B:W,$U$8,FALSE)) -> 23.46 | M25: =$L25-($L25*P25) -> 16.8912 | N25: 0 | O25: =M25*(1-$N25) -> 16.8912 | P25: =_xlfn.XLOOKUP(C25&$H$2,[1]POLITICA!A:A,[1]POLITICA!F:F)/100 -> 0.28
B26: OTC | C26: 2533 | D26: 7896004780092 | E26: OTC | F26: CALADRYL | G26: CALADRYL GEL POS SOL REFRESC. 120G NP-E | H26: =_xlfn.XLOOKUP($C26,[1]TABELA_PREÇOS!$B:$B,[1]TABELA_PREÇOS!J:J) -> NEGATIVA | J26: OTC | K26: NÃO | L26: =IF(ISERROR(VLOOKUP($C26,[1]TABELA_PREÇOS!B:W,$U$8,FALSE))=TRUE,"",VLOOKUP($C26,[1]TABELA_PREÇOS!B:W,$U$8,FALSE)) -> 25.93 | M26: =$L26-($L26*P26) -> 18.6696 | N26: 0 | O26: =M26*(1-$N26) -> 18.6696 | P26: =_xlfn.XLOOKUP(C26&$H$2,[1]POLITICA!A:A,[1]POLITICA!F:F)/100 -> 0.28
B27: OTC | C27: 2632 | D27: =_xlfn.XLOOKUP(C27,[1]TABELA_PREÇOS!B:B,[1]TABELA_PREÇOS!C:C) -> 7896004822464 | E27: OTC | F27: =_xlfn.XLOOKUP($C27,[1]TABELA_PREÇOS!$B:$B,[1]TABELA_PREÇOS!E:E) -> CALADRYL | G27: CALADRYL HIDRATANTE X 200 ML | H27: =_xlfn.XLOOKUP($C27,[1]TABELA_PREÇOS!$B:$B,[1]TABELA_PREÇOS!J:J) -> NEGATIVA | J27: OTC | K27: NÃO | L27: =IF(ISERROR(VLOOKUP($C27,[1]TABELA_PREÇOS!B:W,$U$8,FALSE))=TRUE,"",VLOOKUP($C27,[1]TABELA_PREÇOS!B:W,$U$8,FALSE)) -> 62.15 | M27: =$L27-($L27*P27) -> 44.748 | N27: =$H$4 -> 0.0852 | O27: =M27*(1-$N27) -> 40.93547 | P27: =_xlfn.XLOOKUP(C27&$H$2,[1]POLITICA!A:A,[1]POLITICA!F:F)/100 -> 0.28
B28: OTC | C28: 2633 | D28: =_xlfn.XLOOKUP(C28,[1]TABELA_PREÇOS!B:B,[1]TABELA_PREÇOS!C:C) -> 7896004822556 | E28: OTC | F28: =_xlfn.XLOOKUP($C28,[1]TABELA_PREÇOS!$B:$B,[1]TABELA_PREÇOS!E:E) -> CALADRYL | G28: CALADRYL HIDRATANTE X 400 ML | H28: =_xlfn.XLOOKUP($C28,[1]TABELA_PREÇOS!$B:$B,[1]TABELA_PREÇOS!J:J) -> NEGATIVA | J28: OTC | K28: NÃO | L28: =IF(ISERROR(VLOOKUP($C28,[1]TABELA_PREÇOS!B:W,$U$8,FALSE))=TRUE,"",VLOOKUP($C28,[1]TABELA_PREÇOS!B:W,$U$8,FALSE)) -> 97.08 | M28: =$L28-($L28*P28) -> 69.8976 | N28: =$H$4 -> 0.0852 | O28: =M28*(1-$N28) -> 63.942324 | P28: =_xlfn.XLOOKUP(C28&$H$2,[1]POLITICA!A:A,[1]POLITICA!F:F)/100 -> 0.28
B29: OTC | C29: 2530 | D29: 7896004780061 | E29: OTC | F29: CALADRYL | G29: CALADRYL LOCAO POS SOL 100ML NP - E | H29: =_xlfn.XLOOKUP($C29,[1]TABELA_PREÇOS!$B:$B,[1]TABELA_PREÇOS!J:J) -> NEGATIVA | J29: OTC | K29: NÃO | L29: =IF(ISERROR(VLOOKUP($C29,[1]TABELA_PREÇOS!B:W,$U$8,FALSE))=TRUE,"",VLOOKUP($C29,[1]TABELA_PREÇOS!B:W,$U$8,FALSE)) -> 30.76 | M29: =$L29-($L29*P29) -> 22.1472 | N29: 0 | O29: =M29*(1-$N29) -> 22.1472 | P29: =_xlfn.XLOOKUP(C29&$H$2,[1]POLITICA!A:A,[1]POLITICA!F:F)/100 -> 0.28
B30: OTC | C30: 2725 | D30: =_xlfn.XLOOKUP(C30,[1]TABELA_PREÇOS!B:B,[1]TABELA_PREÇOS!C:C) -> 7896004822525 | E30: OTC | F30: =_xlfn.XLOOKUP($C30,[1]TABELA_PREÇOS!$B:$B,[1]TABELA_PREÇOS!E:E) -> CALADRYL | G30: =_xlfn.XLOOKUP($C30,[1]TABELA_PREÇOS!$B:$B,[1]TABELA_PREÇOS!G:G) -> CALADRYL REPEL 100ML- E | H30: =_xlfn.XLOOKUP($C30,[1]TABELA_PREÇOS!$B:$B,[1]TABELA_PREÇOS!J:J) -> NEUTRA | J30: OTC | K30: NÃO | L30: =IF(ISERROR(VLOOKUP($C30,[1]TABELA_PREÇOS!B:W,$U$8,FALSE))=TRUE,"",VLOOKUP($C30,[1]TABELA_PREÇOS!B:W,$U$8,FALSE)) -> 23.96 | M30: =$L30-($L30*P30) -> 18.6888 | N30: =$H$4 -> 0.0852 | O30: =M30*(1-$N30) -> 17.096514 | P30: =_xlfn.XLOOKUP(C30&$H$2,[1]POLITICA!A:A,[1]POLITICA!F:F)/100 -> 0.22
B31: TAR | C31: 32026 | D31: 7896004813226 | E31: SAUDE FEMININA | F31: CANDERM | G31: CANDERM CPR 250MG x 20 | H31: POSITIVA | I31: 2 BL X 10 | J31: OUTROS | K31: NÃO | L31: =IF(ISERROR(VLOOKUP($C31,[1]TABELA_PREÇOS!B:W,$U$8,FALSE))=TRUE,"",VLOOKUP($C31,[1]TABELA_PREÇOS!B:W,$U$8,FALSE)) -> 19.83 | M31: =$L31-($L31*P31) -> 4.1764446 | N31: =$H$4 -> 0.0852 | O31: =M31*(1-$N31) -> 3.8206115 | P31: =_xlfn.XLOOKUP(C31&$H$2,[1]POLITICA!A:A,[1]POLITICA!F:F)/100 -> 0.78938756
B32: TAR | C32: 32027 | D32: 7896004707570 | E32: SAUDE FEMININA | F32: CANDERM | G32: CANDERM CPR 400MG x 20 | H32: POSITIVA | I32: 2 BL X 10 | J32: OUTROS | K32: NÃO | L32: =IF(ISERROR(VLOOKUP($C32,[1]TABELA_PREÇOS!B:W,$U$8,FALSE))=TRUE,"",VLOOKUP($C32,[1]TABELA_PREÇOS!B:W,$U$8,FALSE)) -> 27.43 | M32: =$L32-($L32*P32) -> 6.6063067 | N32: =$H$4 -> 0.0852 | O32: =M32*(1-$N32) -> 6.0434494 | P32: =_xlfn.XLOOKUP(C32&$H$2,[1]POLITICA!A:A,[1]POLITICA!F:F)/100 -> 0.75915761
B33: TAR | C33: 31287 | D33: 7896004732510 | E33: OUTROS | F33: CARVEGRAN | G33: CARVEGRAN CPR 25mg x 30 | H33: POSITIVA | I33: 25mg x 30 | J33: OUTROS | K33: NÃO | L33: =IF(ISERROR(VLOOKUP($C33,[1]TABELA_PREÇOS!B:W,$U$8,FALSE))=TRUE,"",VLOOKUP($C33,[1]TABELA_PREÇOS!B:W,$U$8,FALSE)) -> 71.81 | M33: =$L33-($L33*P33) -> 8.9510112 | N33: =$H$4 -> 0.0852 | O33: =M33*(1-$N33) -> 8.188385 | P33: =_xlfn.XLOOKUP(C33&$H$2,[1]POLITICA!A:A,[1]POLITICA!F:F)/100 -> 0.87535147
B34: TAR | C34: 31281 | D34: 7896004732442 | E34: OUTROS | F34: CARVEGRAN | G34: CARVEGRAN CPR 3.12MG x 30 | H34: POSITIVA | I34: 3,125mg x 30 | J34: OUTROS | K34: NÃO | L34: =IF(ISERROR(VLOOKUP($C34,[1]TABELA_PREÇOS!B:W,$U$8,FALSE))=TRUE,"",VLOOKUP($C34,[1]TABELA_PREÇOS!B:W,$U$8,FALSE)) -> 31.59 | M34: =$L34-($L34*P34) -> 3.9487284 | N34: =$H$4 -> 0.0852 | O34: =M34*(1-$N34) -> 3.6122968 | P34: =_xlfn.XLOOKUP(C34&$H$2,[1]POLITICA!A:A,[1]POLITICA!F:F)/100 -> 0.87500068
B35: TAR | C35: 32338 | D35: 7896004706528 | E35: INVERNO | F35: CELERG | G35: CELERG CPR x 20 | H35: NEGATIVA | I35: 2 BL X 10 | J35: OUTROS | K35: NÃO | L35: =IF(ISERROR(VLOOKUP($C35,[1]TABELA_PREÇOS!B:W,$U$8,FALSE))=TRUE,"",VLOOKUP($C35,[1]TABELA_PREÇOS!B:W,$U$8,FALSE)) -> 21.16 | M35: =$L35-($L35*P35) -> 7.3265884 | N35: =$H$4 -> 0.0852 | O35: =M35*(1-$N35) -> 6.7023631 | P35: =_xlfn.XLOOKUP(C35&$H$2,[1]POLITICA!A:A,[1]POLITICA!F:F)/100 -> 0.65375291
B36: TAR | C36: 31048 | D36: 7896004706559 | E36: INVERNO | F36: CELERG | G36: CELERG XAR. 120ML x 1 | H36: NEGATIVA | I36: FR X 120 ML | J36: OUTROS | K36: NÃO | L36: =IF(ISERROR(VLOOKUP($C36,[1]TABELA_PREÇOS!B:W,$U$8,FALSE))=TRUE,"",VLOOKUP($C36,[1]TABELA_PREÇOS!B:W,$U$8,FALSE)) -> 29.36 | M36: =$L36-($L36*P36) -> 12.369553 | N36: =$H$4 -> 0.0852 | O36: =M36*(1-$N36) -> 11.315667 | P36: =_xlfn.XLOOKUP(C36&$H$2,[1]POLITICA!A:A,[1]POLITICA!F:F)/100 -> 0.5786937
B37: OTC | C37: 31960 | D37: 7896004774220 | E37: MVM | F37: CENEVIT 1G | G37: CENEVIT CPR EFER 1.00G X 10 | H37: NEUTRA | I37: TUBO X 10 | J37: SUPER MARCAS | K37: NÃO | L37: =IF(ISERROR(VLOOKUP($C37,[1]TABELA_PREÇOS!B:W,$U$8,FALSE))=TRUE,"",VLOOKUP($C37,[1]TABELA_PREÇOS!B:W,$U$8,FALSE)) -> 14.77 | M37: =$L37-($L37*P37) -> 3.936205 | N37: =$H$4 -> 0.0852 | O37: =M37*(1-$N37) -> 3.6008403 | P37: =_xlfn.XLOOKUP(C37&$H$2,[1]POLITICA!A:A,[1]POLITICA!F:F)/100 -> 0.7335
B38: OTC | C38: 32500 | D38: 7896004783871 | E38: MVM | F38: CENEVIT TRIPLA | G38: CENEVIT TRIPLA ACAO C/10 CPR EFER S.A-L | H38: NEUTRA | I38: C/10 CPR EFER S.A-L | J38: SUPER MARCAS | K38: NÃO | L38: =IF(ISERROR(VLOOKUP($C38,[1]TABELA_PREÇOS!B:W,$U$8,FALSE))=TRUE,"",VLOOKUP($C38,[1]TABELA_PREÇOS!B:W,$U$8,FALSE)) -> 23.26 | M38: =$L38-($L38*P38) -> 8.1718412 | N38: =$H$4 -> 0.0852 | O38: =M38*(1-$N38) -> 7.4756004 | P38: =_xlfn.XLOOKUP(C38&$H$2,[1]POLITICA!A:A,[1]POLITICA!F:F)/100 -> 0.64867407
B39: OTC | C39: 32501 | D39: 7896004783888 | E39: MVM | F39: CENEVIT TRIPLA | G39: CENEVIT TRIPLA ACAO C/30 CPR EFER S.A-L | H39: NEUTRA | I39: C/30 CPR EFER S.A-L | J39: SUPER MARCAS | K39: NÃO | L39: =IF(ISERROR(VLOOKUP($C39,[1]TABELA_PREÇOS!B:W,$U$8,FALSE))=TRUE,"",VLOOKUP($C39,[1]TABELA_PREÇOS!B:W,$U$8,FALSE)) -> 52.33 | M39: =$L39-($L39*P39) -> 21.746604 | N39: =$H$4 -> 0.0852 | O39: =M39*(1-$N39) -> 19.893794 | P39: =_xlfn.XLOOKUP(C39&$H$2,[1]POLITICA!A:A,[1]POLITICA!F:F)/100 -> 0.58443332
B40: OTC | C40: 31957 | D40: 7896004774237 | E40: MVM | F40: CENEVIT ZINCO | G40: CENEVIT ZINCO CPR EFER 1.00G X 10 /10 | H40: NEUTRA | I40: TUBO X 10 | J40: SUPER MARCAS | K40: NÃO | L40: =IF(ISERROR(VLOOKUP($C40,[1]TABELA_PREÇOS!B:W,$U$8,FALSE))=TRUE,"",VLOOKUP($C40,[1]TABELA_PREÇOS!B:W,$U$8,FALSE)) -> 18.02 | M40: =$L40-($L40*P40) -> 5.1151796 | N40: =$H$4 -> 0.0852 | O40: =M40*(1-$N40) -> 4.6793663 | P40: =_xlfn.XLOOKUP(C40&$H$2,[1]POLITICA!A:A,[1]POLITICA!F:F)/100 -> 0.71613876
B41: OTC | C41: 31958 | D41: 7896004774244 | E41: MVM | F41: CENEVIT ZINCO | G41: CENEVIT ZINCO CPR EFER 1.00G X 30 /10 | H41: NEUTRA | I41: TUBO X 30 | J41: SUPER MARCAS | K41: NÃO | L41: =IF(ISERROR(VLOOKUP($C41,[1]TABELA_PREÇOS!B:W,$U$8,FALSE))=TRUE,"",VLOOKUP($C41,[1]TABELA_PREÇOS!B:W,$U$8,FALSE)) -> 54.07 | M41: =$L41-($L41*P41) -> 13.608895 | N41: =$H$4 -> 0.0852 | O41: =M41*(1-$N41) -> 12.449417 | P41: =_xlfn.XLOOKUP(C41&$H$2,[1]POLITICA!A:A,[1]POLITICA!F:F)/100 -> 0.7483097
...
