Workbook
Name \0: #REF!
Name \a: #N/A
Name \b: #N/A
Name \c: #N/A
Name \d: #N/A
Name \e: #N/A
Name \f: #N/A
Name \g: #N/A
Name \h: #N/A
Name \i: #N/A
Name \j: #N/A
Name \k: #N/A
Name \l: #N/A
Name \m: #N/A
Name \n: #N/A
Name \o: #N/A
Name \p: #N/A
Name \q: #N/A
Name \s: #N/A
Name \u: '[1]2010-2015'!#REF!
Name \v: #N/A
Name \x: #N/A
Name \z: #N/A
Name ___mds_first_cell___: #N/A
Name ___mds_view_data___: #N/A
Name __DAT2: #N/A
Name __shared_1_0_0: #REF!-#REF!
Name __shared_1_0_1: #REF!*#REF!
Name __shared_1_0_10: #REF!*#REF!
Name __shared_1_0_11: #REF!*#REF!
Name __shared_1_0_12: #REF!*#REF!
Name __shared_1_0_13: #REF!*#REF!
Name __shared_1_0_14: (((#REF!+#REF!)*(1+#REF!)*#REF!)-#REF!)
Name __shared_1_0_15: #REF!+#REF!+#REF!
Name __shared_1_0_16: #REF!/(1-#REF!)
Name __shared_1_0_17: (#REF!/(1-(#REF!+#REF!+#REF!)))
Name __shared_1_0_18: #REF!/(1-#REF!)
Name __shared_1_0_19: (((#REF!+#REF!)*(1+#REF!)*#REF!)-#REF!)
Name __shared_1_0_2: #REF!/(1-#REF!)
Name __shared_1_0_20: #REF!+#REF!+#REF!
Name __shared_1_0_21: IF(#REF!>#REF!,"REVISAR","OK")
Name __shared_1_0_22: (#REF!/(1-(#REF!+#REF!+#REF!)))
Name __shared_1_0_23: #REF!/(1-#REF!)
Name __shared_1_0_24: #REF!*#REF!
Name __shared_1_0_25: (((#REF!+#REF!)*(1+#REF!))*#REF!)-#REF!
Name __shared_1_0_26: #REF!+#REF!+#REF!
Name __shared_1_0_27: #REF!-#REF!-#REF!-#REF!-#REF!
Name __shared_1_0_28: #REF!*#REF!
Name __shared_1_0_29: (#REF!-#REF!)/#REF!
Name __shared_1_0_3: #REF!*#REF!
Name __shared_1_0_30: #REF!-#REF!
Name __shared_1_0_31: (#REF!/(1-(#REF!+#REF!+#REF!)))
Name __shared_1_0_32: #REF!*#REF!
Name __shared_1_0_33: #REF!/(1-#REF!)
Name __shared_1_0_34: (#REF!/(1-(#REF!+#REF!+#REF!)))
Name __shared_1_0_35: #REF!/(1-#REF!)
Name __shared_1_0_36: #REF!*#REF!
Name __shared_1_0_37: #REF!*#REF!
Name __shared_1_0_38: #REF!*#REF!
Name __shared_1_0_39: #REF!*#REF!

Sheet LISTA PREÇO 2022-Vigen 01.02.22
A4: LISTA DE PREÇO: Nº 052021 - Vigência: 01/08/2021
A5: LISTA DE PREÇO FABRICA E PREÇO MÁXIMO CONSUMIDOR | J5: Preço Lista | M5: Politica 1% s/ PV Base | P5: Politica 7% s/ B22 | S5: Politica 13% s/ B22 | V5: Politica 6% s/ B22 | Y5: Politica 12% s/ B22 | AB5: Politica 18% s/ B22 | AF5: Politica NA | AI5: Politica NA | AL5: Politica NA | AO5: Politica NA | AR5: Politica NA | AU5: ICMS 0% | AW5: ICMS 12% | AY5: ICMS 17% | BA5: ICMS 17,5% | BC5: ICMS 18% | BE5: ICMS 20% | BG5: ICMS 17% (ALC) | BI5: ICMS 17,5% (ALC) | BK5: ICMS 18% (ALC)
A6: Empresa | B6: Canal | C6: EAN | D6: Código CIGAM | E6: Código SAP | F6: Descrição | G6: NCM | H6: Status | I6: UN/CX | J6: PV BASE | L6: Preço Médio | M6: B22 | N6: % B21 | P6: DPN | Q6: % DPN | S6: PRIME | T6: % PRIME | V6: COMBATE | W6: % COMBATE | Y6: REGIONAL | Z6: % REGIONAL | AB6: PROFISSIONAL | AC6: % REGIONAL | AE6: MG | AF6: % REGIONAL | AH6: PAGUE MENOS | AI6: % PM | AK6: RD | AL6: % RD | AN6: DPSP | AO6: % DPSP | AQ6: CONDE | AR6: % CONDE | AT6: PF 18% (SAP) | AU6: PF | AV6: PMC | AW6: PF | AX6: PMC | AY6: PF | AZ6: PMC | BA6: PF | BB6: PMC | BC6: PF | BD6: PMC | BE6: PF | BF6: PMC | BG6: PF | BH6: PMC | BI6: PF | BJ6: PMC | BK6: PF | BL6: PMC | BM6: Lista PIS/COFINS | BN6: Categoria de Grupo CMED
A7: Natulab | B7: Medicamentos | C7: 7899470804828 | D7: 43890 | E7: 15000145 | F7: AD-VITAM SOL GOT X 20ML | G7: 30045040 | H7: ATIVO | I7: 50 | J7: 4.23 | L7: 4.15 | M7: 4.23 | N7: =IFERROR(100%-(J7/M7),"") -> 0 | P7: 4.55 | Q7: =IFERROR(100%-(M7/P7),0) -> 0.07032967 | S7: 4.89 | T7: =IFERROR(100%-(M7/S7),0) -> 0.13496933 | V7: 4.2875564 | W7: =IFERROR(100%-(M7/V7),0) -> 0.01342406 | Y7: 4.5798898 | Z7: =IFERROR(100%-(M7/Y7),0) -> 0.076396992 | AB7: 4.9150037 | AC7: =IFERROR(100%-(M7/AB7),0) -> 0.13936992 | AE7: 4.0507614 | AF7: =IFERROR(100%-(M7/AE7),0) -> -0.04424812 | AH7: 0 | AI7: =IFERROR(100%-(M7/AH7),0) -> 0 | AK7: 0 | AL7: =IFERROR(100%-(M7/AK7),0) -> 0 | AN7: 0 | AO7: =IFERROR(100%-(M7/AN7),0) -> 0 | AR7: =IFERROR(100%-(P7/AQ7),0) -> 0 | AT7: 12.14 | AU7: 9.68 | AV7: 12.98 | AW7: 11.19 | AX7: 14.94 | AY7: 11.97 | AZ7: 15.95 | BA7: 12.05 | BB7: 16.05 | BC7: 12.14 | BD7: 16.17 | BE7: 12.49 | BF7: 16.63 | BG7: 10.42 | BH7: 14.41 | BI7: 10.49 | BJ7: 14.5 | BK7: 10.55 | BL7: 14.59 | BM7: Negativa | BN7: Grupo 2
A8: Natulab | B8: Medicamentos | C8: 7898133136535 | D8: 23646 | E8: 15000153 | F8: Afolic Comprimido 5mg 1bl X 20com X 200ct - Farma | G8: 30045090 | H8: ATIVO | I8: 200 | J8: 1.47 | L8: 1.54 | M8: 1.47 | N8: =IFERROR(100%-(J8/M8),0) -> 0 | P8: 1.58 | Q8: =IFERROR(100%-(M8/P8),0) -> 0.069620253 | S8: 1.7 | T8: =IFERROR(100%-(M8/S8),0) -> 0.13529412 | V8: 1.4904449 | W8: =IFERROR(100%-(M8/V8),0) -> 0.013717297 | Y8: 1.5920661 | Z8: =IFERROR(100%-(M8/Y8),0) -> 0.076671512 | AB8: 1.7085588 | AC8: =IFERROR(100%-(M8/AB8),0) -> 0.13962573 | AE8: 1.3401015 | AF8: =IFERROR(100%-(M8/AE8),0) -> -0.096931818 | AH8: 1.4 | AI8: =IFERROR(100%-(M8/AH8),0) -> -0.05 | AK8: 4.3575 | AL8: =IFERROR(100%-(M8/AK8),0) -> 0.6626506 | AN8: 0 | AO8: =IFERROR(100%-(M8/AN8),0) -> 0 | AR8: =IFERROR(100%-(P8/AQ8),0) -> 0 | AT8: 8.83 | AU8: 7.04 | AV8: 9.44 | AW8: 8.14 | AX8: 10.87 | AY8: 8.7 | AZ8: 11.59 | BA8: 8.76 | BB8: 11.67 | BC8: 8.83 | BD8: 11.76 | BE8: 9.09 | BF8: 12.1 | BG8: 7.58 | BH8: 10.48 | BI8: 7.63 | BJ8: 10.55 | BK8: 7.67 | BL8: 10.6 | BM8: Negativa | BN8: Grupo 3
A9: Natulab | B9: Medicamentos | C9: 7898133139741 | D9: 34232 | E9: 15000133 | F9: Aftliv 25ml 1ct X 100fr - Farma | G9: 30042029 | H9: ATIVO | I9: 200 | J9: 7.12 | L9: 6.98 | M9: 7.12 | N9: =IFERROR(100%-(J9/M9),0) -> 0 | P9: 7.66 | Q9: =IFERROR(100%-(M9/P9),0) -> 0.070496084 | S9: 8.23 | T9: =IFERROR(100%-(M9/S9),0) -> 0.13487242 | V9: 7.2156458 | W9: =IFERROR(100%-(M9/V9),0) -> 0.013255337 | Y9: 7.7076217 | Z9: =IFERROR(100%-(M9/Y9),0) -> 0.076239039 | AB9: 8.271594 | AC9: =IFERROR(100%-(M9/AB9),0) -> 0.13922274 | AE9: 6.5076142 | AF9: =IFERROR(100%-(M9/AE9),0) -> -0.094102964 | AH9: 6.78 | AI9: =IFERROR(100%-(M9/AH9),0) -> -0.050147493 | AK9: 9.9596 | AL9: =IFERROR(100%-(M9/AK9),0) -> 0.28511185 | AN9: 0 | AO9: =IFERROR(100%-(M9/AN9),0) -> 0 | AR9: =IFERROR(100%-(P9/AQ9),0) -> 0 | AT9: 35.57 | AU9: 28.38 | AV9: 38.07 | AW9: 32.8 | AX9: 43.81 | AY9: 35.07 | AZ9: 46.74 | BA9: 35.32 | BB9: 47.06 | BC9: 35.57 | BD9: 47.39 | BE9: 36.6 | BF9: 48.72 | BG9: 30.54 | BH9: 42.22 | BI9: 30.72 | BJ9: 42.47 | BK9: 30.91 | BL9: 42.73 | BM9: Negativa | BN9: Grupo 1
A10: Natulab | B10: Medicamentos | C10: 7899470801414 | D10: 23719 | E10: 15000155 | F10: Alcachofra Natulab 300mg 2bl X 15cap X 50ct - Farma | G10: 30044990 | H10: ATIVO | I10: 50 | J10: 7.85 | L10: 7.69 | M10: 7.85 | N10: =IFERROR(100%-(J10/M10),0) -> 0 | P10: 8.44 | Q10: =IFERROR(100%-(M10/P10),0) -> 0.069905213 | S10: 9.07 | T10: =IFERROR(100%-(M10/S10),0) -> 0.13450937 | V10: 7.9490393 | W10: =IFERROR(100%-(M10/V10),0) -> 0.012459283 | Y10: 8.4910193 | Z10: =IFERROR(100%-(M10/Y10),0) -> 0.075493797 | AB10: 9.1123134 | AC10: =IFERROR(100%-(M10/AB10),0) -> 0.13852831 | AE10: 7.1634518 | AF10: =IFERROR(100%-(M10/AE10),0) -> -0.09584042 | AH10: 0 | AI10: =IFERROR(100%-(M10/AH10),0) -> 0 | AK10: 0 | AL10: =IFERROR(100%-(M10/AK10),0) -> 0 | AN10: 0 | AO10: =IFERROR(100%-(M10/AN10),0) -> 0 | AR10: =IFERROR(100%-(P10/AQ10),0) -> 0 | AT10: 28.88 | AU10: 23.04 | AV10: 30.9 | AW10: 26.63 | AX10: 35.57 | AY10: 28.47 | AZ10: 37.94 | BA10: 28.67 | BB10: 38.2 | BC10: 28.88 | BD10: 38.48 | BE10: 29.72 | BF10: 39.56 | BG10: 24.79 | BH10: 34.27 | BI10: 24.94 | BJ10: 34.48 | BK10: 25.09 | BL10: 34.69 | BM10: Negativa | BN10: Grupo 2
A11: Natulab | B11: Medicamentos | C11: 7898133134456 | D11: 28582 | E11: 15000120 | F11: Alumimax 100ml Fn 1ct X 50fr - Farma | G11: 30049099 | H11: ATIVO | I11: 50 | J11: 3.04 | L11: 2.98 | M11: 3.04 | N11: =IFERROR(100%-(J11/M11),0) -> 0 | P11: 3.26 | Q11: =IFERROR(100%-(M11/P11),0) -> 0.067484663 | S11: 3.51 | T11: =IFERROR(100%-(M11/S11),0) -> 0.13390313 | V11: 3.0755212 | W11: =IFERROR(100%-(M11/V11),0) -> 0.011549642 | Y11: 3.2852158 | Z11: =IFERROR(100%-(M11/Y11),0) -> 0.074642218 | AB11: 3.5255974 | AC11: =IFERROR(100%-(M11/AB11),0) -> 0.13773479 | AE11: 2.8105797 | AF11: =IFERROR(100%-(M11/AE11),0) -> -0.081627376 | AH11: 0 | AI11: =IFERROR(100%-(M11/AH11),0) -> 0 | AK11: 0 | AL11: =IFERROR(100%-(M11/AK11),0) -> 0 | AN11: 0 | AO11: =IFERROR(100%-(M11/AN11),0) -> 0 | AR11: =IFERROR(100%-(P11/AQ11),0) -> 0 | AT11: 16.84 | AU11: 13.43 | AV11: 18.01 | AW11: 15.52 | AX11: 20.73 | AY11: 16.6 | AZ11: 22.12 | BA11: 16.72 | BB11: 22.28 | BC11: 16.84 | BD11: 22.44 | BE11: 17.33 | BF11: 23.07 | BG11: 14.46 | BH11: 19.99 | BI11: 14.54 | BJ11: 20.1 | BK11: 14.63 | BL11: 20.23 | BM11: Negativa | BN11: Grupo 1
A12: Natulab | B12: Medicamentos | C12: 7898133134630 | D12: 28578 | E12: 15000119 | F12: Alumimax 150ml Fn 1ct X 60fr - Farma | G12: 30049099 | H12: ATIVO | I12: 60 | J12: 4.02 | L12: 3.94 | M12: 4.02 | N12: =IFERROR(100%-(J12/M12),0) -> 0 | P12: 4.32 | Q12: =IFERROR(100%-(M12/P12),0) -> 0.069444444 | S12: 4.64 | T12: =IFERROR(100%-(M12/S12),0) -> 0.13362069 | V12: 4.0691511 | W12: =IFERROR(100%-(M12/V12),0) -> 0.012078953 | Y12: 4.3465932 | Z12: =IFERROR(100%-(M12/Y12),0) -> 0.075137743 | AB12: 4.6646366 | AC12: =IFERROR(100%-(M12/AB12),0) -> 0.13819653 | AE12: 3.7082554 | AF12: =IFERROR(100%-(M12/AE12),0) -> -0.084067723 | AH12: 0 | AI12: =IFERROR(100%-(M12/AH12),0) -> 0 | AK12: 0 | AL12: =IFERROR(100%-(M12/AK12),0) -> 0 | AN12: 0 | AO12: =IFERROR(100%-(M12/AN12),0) -> 0 | AR12: =IFERROR(100%-(P12/AQ12),0) -> 0 | AT12: 20.91 | AU12: 16.68 | AV12: 22.37 | AW12: 19.28 | AX12: 25.75 | AY12: 20.62 | AZ12: 27.48 | BA12: 20.76 | BB12: 27.66 | BC12: 20.91 | BD12: 27.86 | BE12: 21.52 | BF12: 28.64 | BG12: 17.95 | BH12: 24.82 | BI12: 18.06 | BJ12: 24.97 | BK12: 18.17 | BL12: 25.12 | BM12: Negativa | BN12: Grupo 1
A13: Natulab | B13: Medicamentos | C13: 7898133136634 | D13: 23792 | E13: 15000068 | F13: Arlivry 100ml Cereja 1ct X 50fr - Farma | G13: 30049099 | H13: ATIVO | I13: 50 | J13: 3.61 | L13: 3.54 | M13: 3.61 | N13: =IFERROR(100%-(J13/M13),0) -> 0 | P13: 3.88 | Q13: =IFERROR(100%-(M13/P13),0) -> 0.069587629 | S13: 4.17 | T13: =IFERROR(100%-(M13/S13),0) -> 0.13429257 | V13: 3.6535568 | W13: =IFERROR(100%-(M13/V13),0) -> 0.011921765 | Y13: 3.902663 | Z13: =IFERROR(100%-(M13/Y13),0) -> 0.074990588 | AB13: 4.1882237 | AC13: =IFERROR(100%-(M13/AB13),0) -> 0.13805941 | AE13: 3.43 | AF13: =IFERROR(100%-(M13/AE13),0) -> -0.052478134 | AH13: 3.3 | AI13: =IFERROR(100%-(M13/AH13),0) -> -0.093939394 | AK13: 13.133 | AL13: =IFERROR(100%-(M13/AK13),0) -> 0.72511993 | AN13: 11.826675 | AO13: =IFERROR(100%-(M13/AN13),0) -> 0.69475783 | AR13: =IFERROR(100%-(P13/AQ13),0) -> 0 | AT13: 19.93 | AU13: 15.9 | AV13: 21.32 | AW13: 18.37 | AX13: 24.53 | AY13: 19.65 | AZ13: 26.19 | BA13: 19.79 | BB13: 26.37 | BC13: 19.93 | BD13: 26.55 | BE13: 20.51 | BF13: 27.3 | BG13: 17.11 | BH13: 23.65 | BI13: 17.21 | BJ13: 23.79 | BK13: 17.32 | BL13: 23.94 | BM13: Negativa | BN13: Grupo 2
A14: Natulab | B14: Medicamentos | C14: 7898133136757 | D14: 23794 | E14: 15000069 | F14: Arlivry 100ml Mel 1ct X 50fr - Farma | G14: 30049099 | H14: ATIVO | I14: 50 | J14: 3.61 | L14: 3.54 | M14: 3.61 | N14: =IFERROR(100%-(J14/M14),0) -> 0 | P14: 3.88 | Q14: =IFERROR(100%-(M14/P14),0) -> 0.069587629 | S14: 4.17 | T14: =IFERROR(100%-(M14/S14),0) -> 0.13429257 | V14: 3.6535568 | W14: =IFERROR(100%-(M14/V14),0) -> 0.011921765 | Y14: 3.902663 | Z14: =IFERROR(100%-(M14/Y14),0) -> 0.074990588 | AB14: 4.1882237 | AC14: =IFERROR(100%-(M14/AB14),0) -> 0.13805941 | AE14: 3.43 | AF14: =IFERROR(100%-(M14/AE14),0) -> -0.052478134 | AH14: 3.3 | AI14: =IFERROR(100%-(M14/AH14),0) -> -0.093939394 | AK14: 13.144 | AL14: =IFERROR(100%-(M14/AK14),0) -> 0.72534997 | AN14: 11.826675 | AO14: =IFERROR(100%-(M14/AN14),0) -> 0.69475783 | AR14: =IFERROR(100%-(P14/AQ14),0) -> 0 | AT14: 25.03 | AU14: 19.97 | AV14: 26.78 | AW14: 23.08 | AX14: 30.83 | AY14: 24.68 | AZ14: 32.89 | BA14: 24.85 | BB14: 33.11 | BC14: 25.03 | BD14: 33.35 | BE14: 25.76 | BF14: 34.29 | BG14: 21.49 | BH14: 29.71 | BI14: 21.62 | BJ14: 29.89 | BK14: 21.75 | BL14: 30.07 | BM14: Negativa | BN14: Grupo 2
A15: Natulab | B15: Medicamentos | C15: 7899470802725 | D15: 23670 | E15: 15000154 | F15: Arpynflan 450mg 2bl X 15cap X 100ct - Farma | G15: 30049099 | H15: ATIVO | I15: 100 | J15: 21.2 | L15: 20.79 | M15: 21.2 | N15: =IFERROR(100%-(J15/M15),0) -> 0 | P15: 22.8 | Q15: =IFERROR(100%-(M15/P15),0) -> 0.070175439 | S15: 24.51 | T15: =IFERROR(100%-(M15/S15),0) -> 0.13504692 | V15: 21.480765 | W15: =IFERROR(100%-(M15/V15),0) -> 0.013070535 | Y15: 22.945363 | Z15: =IFERROR(100%-(M15/Y15),0) -> 0.076066033 | AB15: 24.624292 | AC15: =IFERROR(100%-(M15/AB15),0) -> 0.13906153 | AE15: 19.543147 | AF15: =IFERROR(100%-(M15/AE15),0) -> -0.084779221 | AH15: 0 | AI15: =IFERROR(100%-(M15/AH15),0) -> 0 | AK15: 0 | AL15: =IFERROR(100%-(M15/AK15),0) -> 0 | AN15: 0 | AO15: =IFERROR(100%-(M15/AN15),0) -> 0 | AR15: =IFERROR(100%-(P15/AQ15),0) -> 0 | AT15: 82.28 | AU15: 65.66 | AV15: 88.08 | AW15: 75.87 | AX15: 101.34 | AY15: 81.13 | AZ15: 108.14 | BA15: 81.7 | BB15: 108.87 | BC15: 82.28 | BD15: 109.62 | BE15: 84.66 | BF15: 112.69 | BG15: 70.63 | BH15: 97.64 | BI15: 71.06 | BJ15: 98.24 | BK15: 71.49 | BL15: 98.83 | BM15: Negativa | BN15: Grupo 2
A16: Natulab | B16: Medicamentos | C16: 7899470805726 | D16: 27414 | E16: 15000220 | F16: Baby D - Pomada Para Assadura 45g 1bg X 100ct - Farma | G16: 30049099 | H16: ATIVO | I16: 100 | J16: 3.79 | L16: 3.71 | M16: 3.79 | N16: =IFERROR(100%-(J16/M16),0) -> 0 | P16: 4.07 | Q16: =IFERROR(100%-(M16/P16),0) -> 0.068796069 | S16: 4.38 | T16: =IFERROR(100%-(M16/S16),0) -> 0.1347032 | V16: 3.8362347 | W16: =IFERROR(100%-(M16/V16),0) -> 0.012052101 | Y16: 4.0977961 | Z16: =IFERROR(100%-(M16/Y16),0) -> 0.075112605 | AB16: 4.3976349 | AC16: =IFERROR(100%-(M16/AB16),0) -> 0.13817311 | AE16: 3.6243655 | AF16: =IFERROR(100%-(M16/AE16),0) -> -0.04570028 | AH16: 0 | AI16: =IFERROR(100%-(M16/AH16),0) -> 0 | AK16: 0 | AL16: =IFERROR(100%-(M16/AK16),0) -> 0 | AN16: 0 | AO16: =IFERROR(100%-(M16/AN16),0) -> 0 | AR16: =IFERROR(100%-(P16/AQ16),0) -> 0 | AT16: 20.49 | AU16: 16.35 | AV16: 21.93 | AW16: 18.89 | AX16: 25.23 | AY16: 20.2 | AZ16: 26.92 | BA16: 20.34 | BB16: 27.1 | BC16: 20.49 | BD16: 27.3 | BE16: 21.08 | BF16: 28.06 | BG16: 17.59 | BH16: 24.32 | BI16: 17.7 | BJ16: 24.47 | BK16: 17.8 | BL16: 24.61 | BM16: Negativa | BN16: Grupo 1
A17: Natulab | B17: Medicamentos | C17: 7899470805955 | D17: 30023 | E17: 15000130 | F17: Bronqtrat 100ml 1ct X 50fr - Farma Novo | G17: 30049039 | H17: ATIVO | I17: 50 | J17: 2.69 | M17: 0 | N17: =IFERROR(100%-(J17/M17),0) -> 0 | P17: 0 | Q17: =IFERROR(100%-(M17/P17),0) -> 0 | S17: 0 | T17: =IFERROR(100%-(M17/S17),0) -> 0 | V17: 0 | W17: =IFERROR(100%-(M17/V17),0) -> 0 | Y17: 0 | Z17: =IFERROR(100%-(M17/Y17),0) -> 0 | AB17: 0 | AC17: =IFERROR(100%-(M17/AB17),0) -> 0 | AE17: 0 | AF17: =IFERROR(100%-(M17/AE17),0) -> 0 | AH17: 0 | AI17: =IFERROR(100%-(M17/AH17),0) -> 0 | AK17: 0 | AL17: =IFERROR(100%-(M17/AK17),0) -> 0 | AN17: 0 | AO17: =IFERROR(100%-(M17/AN17),0) -> 0 | AR17: =IFERROR(100%-(P17/AQ17),0) -> 0 | AT17: 26.65 | AU17: 21.26 | AV17: 28.52 | AW17: 24.57 | AX17: 32.82 | AY17: 26.28 | AZ17: 35.02 | BA17: 26.46 | BB17: 35.26 | BC17: 26.65 | BD17: 35.51 | BE17: 27.42 | BF17: 36.5 | BG17: 22.88 | BH17: 31.63 | BI17: 23.02 | BJ17: 31.82 | BK17: 23.16 | BL17: 32.02 | BM17: Negativa | BN17: Grupo 2
A18: Natulab | B18: Medicamentos | C18: 7898133135941 | D18: 23805 | E18: 15000071 | F18: Bronqtrat Infantil 100ml 1ct X 50fr - Farma | G18: 30049039 | H18: ATIVO | I18: 50 | J18: 2.81 | L18: 2.76 | M18: 2.81 | N18: =IFERROR(100%-(J18/M18),0) -> 0 | P18: 3.03 | Q18: =IFERROR(100%-(M18/P18),0) -> 0.072607261 | S18: 3.25 | T18: =IFERROR(100%-(M18/S18),0) -> 0.13538462 | V18: 2.8862583 | W18: =IFERROR(100%-(M18/V18),0) -> 0.026421172 | Y18: 3.0830487 | Z18: =IFERROR(100%-(M18/Y18),0) -> 0.088564502 | AB18: 3.3086376 | AC18: =IFERROR(100%-(M18/AB18),0) -> 0.15070783 | AE18: 2.5685279 | AF18: =IFERROR(100%-(M18/AE18),0) -> -0.094011858 | AH18: 0 | AI18: =IFERROR(100%-(M18/AH18),0) -> 0 | AK18: 0 | AL18: =IFERROR(100%-(M18/AK18),0) -> 0 | AN18: 0 | AO18: =IFERROR(100%-(M18/AN18),0) -> 0 | AR18: =IFERROR(100%-(P18/AQ18),0) -> 0 | AT18: 27.79 | AU18: 22.17 | AV18: 29.74 | AW18: 25.62 | AX18: 34.22 | AY18: 27.4 | AZ18: 36.52 | BA18: 27.59 | BB18: 36.76 | BC18: 27.79 | BD18: 37.03 | BE18: 28.6 | BF18: 38.07 | BG18: 23.86 | BH18: 32.99 | BI18: 24 | BJ18: 33.18 | BK18: 24.15 | BL18: 33.39 | BM18: Negativa | BN18: Grupo 2
A19: Natulab | B19: Medicamentos | C19: 7899470802565 | D19: 28440 | E19: 15000117 | F19: Buscoplex Composto Gotas 20ml 1ct X 200fr - Farma | G19: 30044990 | H19: ATIVO | I19: 200 | J19: 5.6 | L19: 5.45 | M19: 5.6 | N19: =IFERROR(100%-(J19/M19),0) -> 0 | P19: 6.02 | Q19: =IFERROR(100%-(M19/P19),0) -> 0.069767442 | S19: 6.47 | T19: =IFERROR(100%-(M19/S19),0) -> 0.13446677 | V19: 5.6702128 | W19: =IFERROR(100%-(M19/V19),0) -> 0.012382739 | Y19: 6.0568182 | Z19: =IFERROR(100%-(M19/Y19),0) -> 0.075422139 | AB19: 6.5 | AC19: =IFERROR(100%-(M19/AB19),0) -> 0.13846154 | AE19: 5.33 | AF19: =IFERROR(100%-(M19/AE19),0) -> -0.05065666 | AH19: 5.29 | AI19: =IFERROR(100%-(M19/AH19),0) -> -0.058601134 | AK19: 8.1765 | AL19: =IFERROR(100%-(M19/AK19),0) -> 0.31511038 | AN19: 0 | AO19: =IFERROR(100%-(M19/AN19),0) -> 0 | AR19: =IFERROR(100%-(P19/AQ19),0) -> 0 | AT19: 10.84 | AU19: 8.65 | AV19: 11.6 | AW19: 9.99 | AX19: 13.34 | AY19: 10.69 | AZ19: 14.24 | BA19: 10.76 | BB19: 14.33 | BC19: 10.84 | BD19: 14.44 | BE19: 11.15 | BF19: 14.84 | BG19: 9.31 | BH19: 12.87 | BI19: 9.36 | BJ19: 12.94 | BK19: 9.42 | BL19: 13.02 | BM19: Negativa | BN19: Grupo 2
A20: Natulab | B20: Medicamentos | C20: 7899470805849 | D20: 33549 | E20: 15000131 | F20: Butalab C/ Cp Med 100ml 1ct X 50fr - Farma | G20: 30039099 | H20: ATIVO | I20: 50 | J20: 1.77 | L20: 1.74 | M20: 1.77 | N20: =IFERROR(100%-(J20/M20),0) -> 0 | P20: 1.91 | Q20: =IFERROR(100%-(M20/P20),0) -> 0.073298429 | S20: 2.05 | T20: =IFERROR(100%-(M20/S20),0) -> 0.13658537 | V20: 1.7978723 | W20: =IFERROR(100%-(M20/V20),0) -> 0.015502959 | Y20: 1.9204545 | Z20: =IFERROR(100%-(M20/Y20),0) -> 0.078343195 | AB20: 2.0609756 | AC20: =IFERROR(100%-(M20/AB20),0) -> 0.14118343 | AE20: 1.5126904 | AF20: =IFERROR(100%-(M20/AE20),0) -> -0.17010067 | AH20: 0 | AI20: =IFERROR(100%-(M20/AH20),0) -> 0 | AK20: 0 | AL20: =IFERROR(100%-(M20/AK20),0) -> 0 | AN20: 0 | AO20: =IFERROR(100%-(M20/AN20),0) -> 0 | AR20: =IFERROR(100%-(P20/AQ20),0) -> 0 | AT20: 5.48 | AU20: 4.49 | AV20: 6.2 | AW20: 5.1 | AX20: 7.05 | AY20: 5.41 | AZ20: 7.47 | BA20: 5.44 | BB20: 7.52 | BC20: 5.48 | BD20: 7.58 | BE20: 5.62 | BF20: 7.77 | BG20: 5.41 | BH20: 7.48 | BI20: 5.45 | BJ20: 7.53 | BK20: 5.48 | BL20: 7.58 | BM20: Positiva | BN20: Grupo 3
A21: Natulab | B21: Medicamentos | C21: 7899470804200 | D21: 44983 | E21: 15000211 | F21: Cardomarin 127mg 2bl X 10com X 100ct - Farma | G21: 30049099 | H21: ATIVO | I21: 100 | J21: 11.98 | L21: 11.75 | M21: 11.98 | N21: =IFERROR(100%-(J21/M21),0) -> 0 | P21: 12.88 | Q21: =IFERROR(100%-(M21/P21),0) -> 0.069875776 | S21: 13.85 | T21: =IFERROR(100%-(M21/S21),0) -> 0.13501805 | V21: 12.13648 | W21: =IFERROR(100%-(M21/V21),0) -> 0.012893334 | Y21: 12.963967 | Z21: =IFERROR(100%-(M21/Y21),0) -> 0.075900143 | AB21: 13.91255 | AC21: =IFERROR(100%-(M21/AB21),0) -> 0.13890695 | AE21: 10.93401 | AF21: =IFERROR(100%-(M21/AE21),0) -> -0.095663881 | AH21: 0 | AI21: =IFERROR(100%-(M21/AH21),0) -> 0 | AK21: 0 | AL21: =IFERROR(100%-(M21/AK21),0) -> 0 | AN21: 0 | AO21: =IFERROR(100%-(M21/AN21),0) -> 0 | AR21: =IFERROR(100%-(P21/AQ21),0) -> 0 | AT21: 50.38 | AU21: 40.2 | AV21: 53.92 | AW21: 46.45 | AX21: 62.04 | AY21: 49.68 | AZ21: 66.22 | BA21: 50.02 | BB21: 66.65 | BC21: 50.38 | BD21: 67.12 | BE21: 51.84 | BF21: 69 | BG21: 43.25 | BH21: 59.79 | BI21: 43.51 | BJ21: 60.15 | BK21: 43.78 | BL21: 60.52 | BM21: Negativa | BN21: Grupo 1
A22: Natulab | B22: Medicamentos | C22: 7899470803647 | D22: 23815 | E22: 15000074 | F22: Cardomarin 18.05mg 100ml 1ct X 50fr - Farma | G22: 30049099 | H22: ATIVO | I22: 50 | J22: 15.39 | L22: 0 | M22: 15.39 | N22: =IFERROR(100%-(J22/M22),0) -> 0 | P22: 16.55 | Q22: =IFERROR(100%-(M22/P22),0) -> 0.070090634 | S22: 17.8 | T22: =IFERROR(100%-(M22/S22),0) -> 0.13539326 | V22: 15.585106 | W22: =IFERROR(100%-(M22/V22),0) -> 0.012518771 | Y22: 16.647727 | Z22: =IFERROR(100%-(M22/Y22),0) -> 0.075549488 | AB22: 17.865854 | AC22: =IFERROR(100%-(M22/AB22),0) -> 0.1385802 | AE22: 14.65 | AF22: =IFERROR(100%-(M22/AE22),0) -> -0.050511945 | AH22: 0 | AI22: =IFERROR(100%-(M22/AH22),0) -> 0 | AK22: 0 | AL22: =IFERROR(100%-(M22/AK22),0) -> 0 | AN22: 0 | AO22: =IFERROR(100%-(M22/AN22),0) -> 0 | AR22: =IFERROR(100%-(P22/AQ22),0) -> 0 | AT22: 50.25 | AU22: 40.1 | AV22: 53.79 | AW22: 46.33 | AX22: 61.88 | AY22: 49.55 | AZ22: 66.04 | BA22: 49.89 | BB22: 66.48 | BC22: 50.25 | BD22: 66.95 | BE22: 51.71 | BF22: 68.83 | BG22: 43.14 | BH22: 59.64 | BI22: 43.4 | BJ22: 60 | BK22: 43.66 | BL22: 60.36 | BM22: Negativa | BN22: Grupo 1
A23: Natulab | B23: Medicamentos | C23: 7899470804149 | D23: 45087 | E23: 15000213 | F23: Cardomarin Cap Dura 254Mg X 20 | G23: 30049099 | H23: ATIVO | I23: 50 | J23: 16.96 | L23: 16.63 | M23: 16.96 | N23: =IFERROR(100%-(J23/M23),0) -> 0 | P23: 18.24 | Q23: =IFERROR(100%-(M23/P23),0) -> 0.070175439 | S23: 19.61 | T23: =IFERROR(100%-(M23/S23),0) -> 0.13513514 | V23: 17.182463 | W23: =IFERROR(100%-(M23/V23),0) -> 0.012947092 | Y23: 18.353994 | Z23: =IFERROR(100%-(M23/Y23),0) -> 0.075950469 | AB23: 19.69697 | AC23: =IFERROR(100%-(M23/AB23),0) -> 0.13895385 | AE23: 16.233503 | AF23: =IFERROR(100%-(M23/AE23),0) -> -0.044752971 | AH23: 16.15 | AI23: =IFERROR(100%-(M23/AH23),0) -> -0.050154799 | AK23: 29.4546 | AL23: =IFERROR(100%-(M23/AK23),0) -> 0.4241986 | AN23: 0 | AO23: =IFERROR(100%-(M23/AN23),0) -> 0 | AR23: =IFERROR(100%-(P23/AQ23),0) -> 0 | AT23: 70.13 | AU23: 55.96 | AV23: 75.06 | AW23: 64.67 | AX23: 86.38 | AY23: 69.15 | AZ23: 92.17 | BA23: 69.64 | BB23: 92.8 | BC23: 70.13 | BD23: 93.44 | BE23: 72.16 | BF23: 96.05 | BG23: 60.2 | BH23: 83.22 | BI23: 60.57 | BJ23: 83.73 | BK23: 60.94 | BL23: 84.25 | BM23: Negativa | BN23: Grupo 1
A24: Natulab | B24: Medicamentos | C24: 7898133137549 | D24: 23780 | E24: 15000158 | F24: Comple B Comprimidos 1fr X 50com X 100ct - Farma | G24: 30045090 | H24: ATIVO | I24: 100 | J24: 4.23 | L24: 3.79 | M24: 4.23 | N24: =IFERROR(100%-(J24/M24),0) -> 0 | P24: 4.55 | Q24: =IFERROR(100%-(M24/P24),0) -> 0.07032967 | S24: 4.89 | T24: =IFERROR(100%-(M24/S24),0) -> 0.13496933 | V24: 3.915375 | W24: =IFERROR(100%-(M24/V24),0) -> -0.08035628 | Y24: 4.1823324 | Z24: =IFERROR(100%-(M24/Y24),0) -> -0.011397369 | AB24: 4.4883567 | AC24: =IFERROR(100%-(M24/AB24),0) -> 0.057561543 | AE24: 3.5284264 | AF24: =IFERROR(100%-(M24/AE24),0) -> -0.1988347 | AH24: 3.68 | AI24: =IFERROR(100%-(M24/AH24),0) -> -0.14945652 | AK24: 5.08 | AL24: =IFERROR(100%-(M24/AK24),0) -> 0.16732283 | AN24: 0 | AO24: =IFERROR(100%-(M24/AN24),0) -> 0 | AR24: =IFERROR(100%-(P24/AQ24),0) -> 0 | AT24: 25.56 | AU24: 20.39 | AV24: 27.35 | AW24: 23.57 | AX24: 31.48 | AY24: 25.2 | AZ24: 33.59 | BA24: 25.38 | BB24: 33.82 | BC24: 25.56 | BD24: 34.05 | BE24: 26.3 | BF24: 35.01 | BG24: 21.94 | BH24: 30.33 | BI24: 22.08 | BJ24: 30.52 | BK24: 22.21 | BL24: 30.7 | BM24: Negativa | BN24: Grupo 2
A25: Natulab | B25: Medicamentos | C25: 7899470802282 | D25: 23783 | E25: 15000159 | F25: Epaphyto Cap Dura 300mg x 30 | G25: 30044990 | H25: ATIVO | I25: 100 | J25: 9.53 | L25: 9.35 | M25: 9.53 | N25: =IFERROR(100%-(J25/M25),0) -> 0 | P25: 10.25 | Q25: =IFERROR(100%-(M25/P25),0) -> 0.070243902 | S25: 11.02 | T25: =IFERROR(100%-(M25/S25),0) -> 0.13520871 | V25: 9.6604341 | W25: =IFERROR(100%-(M25/V25),0) -> 0.013501891 | Y25: 10.3191 | Z25: =IFERROR(100%-(M25/Y25),0) -> 0.076469855 | AB25: 11.074156 | AC25: =IFERROR(100%-(M25/AB25),0) -> 0.13943782 | AE25: 9.1269036 | AF25: =IFERROR(100%-(M25/AE25),0) -> -0.04416574 | AH25: 0 | AI25: =IFERROR(100%-(M25/AH25),0) -> 0 | AK25: 0 | AL25: =IFERROR(100%-(M25/AK25),0) -> 0 | AN25: 0 | AO25: =IFERROR(100%-(M25/AN25),0) -> 0 | AR25: =IFERROR(100%-(P25/AQ25),0) -> 0 | AT25: 38.29 | AU25: 30.55 | AV25: 40.98 | AW25: 35.31 | AX25: 47.16 | AY25: 37.75 | AZ25: 50.31 | BA25: 38.02 | BB25: 50.66 | BC25: 38.29 | BD25: 51.01 | BE25: 39.4 | BF25: 52.44 | BG25: 32.87 | BH25: 45.44 | BI25: 33.07 | BJ25: 45.72 | BK25: 33.27 | BL25: 45.99 | BM25: Negativa | BN25: Grupo 2
A26: Natulab | B26: Medicamentos | C26: 7899470803067 | D26: 24129 | E26: 15000114 | F26: Epaphyto Sol Or 14mg X 150ml | G26: 30044990 | H26: ATIVO | I26: 60 | J26: 10.85 | L26: 10.649524 | M26: 10.85 | N26: =IFERROR(100%-(J26/M26),0) -> 0 | P26: 11.66 | Q26: =IFERROR(100%-(M26/P26),0) -> 0.069468268 | S26: 12.54 | T26: =IFERROR(100%-(M26/S26),0) -> 0.13476874 | V26: 10.989362 | W26: =IFERROR(100%-(M26/V26),0) -> 0.01268151 | Y26: 11.738636 | Z26: =IFERROR(100%-(M26/Y26),0) -> 0.075701839 | AB26: 12.597561 | AC26: =IFERROR(100%-(M26/AB26),0) -> 0.13872217 | AE26: 10.33 | AF26: =IFERROR(100%-(M26/AE26),0) -> -0.050338819 | AH26: 0 | AI26: =IFERROR(100%-(M26/AH26),0) -> 0 | AK26: 0 | AL26: =IFERROR(100%-(M26/AK26),0) -> 0 | AN26: 0 | AO26: =IFERROR(100%-(M26/AN26),0) -> 0 | AR26: =IFERROR(100%-(P26/AQ26),0) -> 0 | AT26: 43.4 | AU26: 34.63 | AV26: 46.45 | AW26: 40.02 | AX26: 53.45 | AY26: 42.79 | AZ26: 57.03 | BA26: 43.09 | BB26: 57.42 | BC26: 43.4 | BD26: 57.82 | BE26: 44.66 | BF26: 59.44 | BG26: 37.26 | BH26: 51.51 | BI26: 37.48 | BJ26: 51.81 | BK26: 37.71 | BL26: 52.13 | BM26: Negativa | BN26: Grupo 2
A27: Natulab | B27: Medicamentos | C27: 7899470802299 | D27: 23830 | E27: 15000160 | F27: Espinheira Santa Natulab 380mg 3bl X 15cap X 50ct - Farma | G27: 30049099 | H27: ATIVO | I27: 50 | J27: 11.03 | L27: 10.82 | M27: 11.03 | N27: =IFERROR(100%-(J27/M27),0) -> 0 | P27: 11.86 | Q27: =IFERROR(100%-(M27/P27),0) -> 0.069983137 | S27: 12.76 | T27: =IFERROR(100%-(M27/S27),0) -> 0.13557994 | V27: 11.178337 | W27: =IFERROR(100%-(M27/V27),0) -> 0.013270003 | Y27: 11.940496 | Z27: =IFERROR(100%-(M27/Y27),0) -> 0.076252769 | AB27: 12.814191 | AC27: =IFERROR(100%-(M27/AB27),0) -> 0.13923553 | AE27: 10.073604 | AF27: =IFERROR(100%-(M27/AE27),0) -> -0.094940791 | AH27: 0 | AI27: =IFERROR(100%-(M27/AH27),0) -> 0 | AK27: 0 | AL27: =IFERROR(100%-(M27/AK27),0) -> 0 | AN27: 0 | AO27: =IFERROR(100%-(M27/AN27),0) -> 0 | AR27: =IFERROR(100%-(P27/AQ27),0) -> 0 | AT27: 52.01 | AU27: 41.5 | AV27: 55.67 | AW27: 47.96 | AX27: 64.06 | AY27: 51.28 | AZ27: 68.35 | BA27: 51.64 | BB27: 68.81 | BC27: 52.01 | BD27: 69.29 | BE27: 53.52 | BF27: 71.24 | BG27: 44.65 | BH27: 61.73 | BI27: 44.92 | BJ27: 62.1 | BK27: 45.19 | BL27: 62.47 | BM27: Negativa | BN27: Grupo 2
A28: Natulab | B28: Medicamentos | C28: 7898133131110 | D28: 23825 | E28: 15000273 | F28: EXPECTOFLUI XPE 13.33MG/ML X 120ML | G28: 30049039 | H28: ATIVO | I28: 30 | J28: 3.62 | L28: 3.55 | M28: 3.62 | N28: =IFERROR(100%-(J28/M28),0) -> 0 | P28: 3.89 | Q28: =IFERROR(100%-(M28/P28),0) -> 0.06940874 | S28: 4.18 | T28: =IFERROR(100%-(M28/S28),0) -> 0.13397129 | V28: 3.6643026 | W28: =IFERROR(100%-(M28/V28),0) -> 0.012090323 | Y28: 3.9141414 | Z28: =IFERROR(100%-(M28/Y28),0) -> 0.075148387 | AB28: 4.200542 | AC28: =IFERROR(100%-(M28/AB28),0) -> 0.13820645 | AE28: 3.3045685 | AF28: =IFERROR(100%-(M28/AE28),0) -> -0.095453149 | AH28: 0 | AI28: =IFERROR(100%-(M28/AH28),0) -> 0 | AK28: 0 | AL28: =IFERROR(100%-(M28/AK28),0) -> 0 | AN28: 0 | AO28: =IFERROR(100%-(M28/AN28),0) -> 0 | AR28: =IFERROR(100%-(P28/AQ28),0) -> 0 | AT28: 15.13 | AU28: 12.07 | AV28: 16.19 | AW28: 13.95 | AX28: 18.63 | AY28: 14.92 | AZ28: 19.88 | BA28: 15.02 | BB28: 20.01 | BC28: 15.13 | BD28: 20.16 | BE28: 15.57 | BF28: 20.72 | BG28: 12.99 | BH28: 17.96 | BI28: 13.07 | BJ28: 18.07 | BK28: 13.15 | BL28: 18.18 | BM28: Negativa | BN28: Grupo 2
A29: Natulab | B29: Medicamentos | C29: 7898133131400 | D29: 23828 | E29: 15000079 | F29: Helmilab S/Acucar 30m 1ct X 200fr - Farma | G29: 30049099 | H29: ATIVO | I29: 200 | J29: 1.48 | L29: 1.45 | M29: 1.48 | N29: =IFERROR(100%-(J29/M29),0) -> 0 | P29: 1.59 | Q29: =IFERROR(100%-(M29/P29),0) -> 0.06918239 | S29: 1.71 | T29: =IFERROR(100%-(M29/S29),0) -> 0.13450292 | V29: 1.5 | W29: =IFERROR(100%-(M29/V29),0) -> 0.013333333 | Y29: 1.6022727 | Z29: =IFERROR(100%-(M29/Y29),0) -> 0.076312057 | AB29: 1.7195122 | AC29: =IFERROR(100%-(M29/AB29),0) -> 0.13929078 | AE29: 1.41 | AF29: =IFERROR(100%-(M29/AE29),0) -> -0.04964539 | AH29: 1.4 | AI29: =IFERROR(100%-(M29/AH29),0) -> -0.057142857 | AK29: 0 | AL29: =IFERROR(100%-(M29/AK29),0) -> 0 | AN29: 0 | AO29: =IFERROR(100%-(M29/AN29),0) -> 0 | AR29: =IFERROR(100%-(P29/AQ29),0) -> 0 | AT29: 6.92 | AU29: 5.52 | AV29: 7.4 | AW29: 6.38 | AX29: 8.52 | AY29: 6.82 | AZ29: 9.09 | BA29: 6.87 | BB29: 9.15 | BC29: 6.92 | BD29: 9.22 | BE29: 7.12 | BF29: 9.48 | BG29: 5.94 | BH29: 8.21 | BI29: 5.98 | BJ29: 8.27 | BK29: 6.01 | BL29: 8.31 | BM29: Negativa | BN29: Grupo 2
... A42: Natulab | B42: Medicamentos | C42: 7898133134760 | D42: 23857 | E42: 15000086 | F42: Ibuprotrat Infantil C/Seringa 100ml 1ct X 50fr - Farma | G42: 30049029 | H42: ATIVO | I42: 50 | J42: 4.34 | L42: 4.2622 | M42: 4.34 | N42: =IFERROR(100%-(J42/M42),0) -> 0 | P42: 4.66 | Q42: =IFERROR(100%-(M42/P42),0) -> 0.068669528 | S42: 5.01 | T42: =IFERROR(100%-(M42/S42),0) -> 0.13373253 | V42: 4.393617 | W42: =IFERROR(100%-(M42/V42),0) -> 0.01220339 | Y42: 4.6931818 | Z42: =IFERROR(100%-(M42/Y42),0) -> 0.075254237 | AB42: 5.0365854 | AC42: =IFERROR(100%-(M42/AB42),0) -> 0.13830508 | AE42: 4.13 | AF42: =IFERROR(100%-(M42/AE42),0) -> -0.050847458 | AH42: 0 | AI42: =IFERROR(100%-(M42/AH42),0) -> 0 | AK42: 0 | AL42: =IFERROR(100%-(M42/AK42),0) -> 0 | AN42: 0 | AO42: =IFERROR(100%-(M42/AN42),0) -> 0 | AR42: =IFERROR(100%-(P42/AQ42),0) -> 0 | AT42: 23.93 | AU42: 19.09 | AV42: 25.6 | AW42: 22.06 | AX42: 29.46 | AY42: 23.59 | AZ42: 31.44 | BA42: 23.76 | BB42: 31.66 | BC42: 23.93 | BD42: 31.88 | BE42: 24.62 | BF42: 32.77 | BG42: 20.54 | BH42: 28.4 | BI42: 20.67 | BJ42: 28.58 | BK42: 20.79 | BL42: 28.74 | BM42: Negativa | BN42: Grupo 2
A43: Natulab | B43: Medicamentos | C43: 7898133130281 | D43: 23863 | E43: 15000087 | F43: Iodenax 100ml 1ct X 50fr - Farma | G43: 30049099 | H43: ATIVO | I43: 50 | J43: 3.54 | M43: 3.54 | N43: =IFERROR(100%-(J43/M43),0) -> 0 | P43: 3.81 | Q43: =IFERROR(100%-(M43/P43),0) -> 0.070866142 | S43: 4.1 | T43: =IFERROR(100%-(M43/S43),0) -> 0.13658537 | V43: 3.5890823 | W43: =IFERROR(100%-(M43/V43),0) -> 0.013675449 | Y43: 3.8337925 | Z43: =IFERROR(100%-(M43/Y43),0) -> 0.076632335 | AB43: 4.1143139 | AC43: =IFERROR(100%-(M43/AB43),0) -> 0.13958922 | AE43: 3.2299492 | AF43: =IFERROR(100%-(M43/AE43),0) -> -0.095992456 | AH43: 0 | AI43: =IFERROR(100%-(M43/AH43),0) -> 0 | AK43: 0 | AL43: =IFERROR(100%-(M43/AK43),0) -> 0 | AN43: 0 | AO43: =IFERROR(100%-(M43/AN43),0) -> 0 | AR43: =IFERROR(100%-(P43/AQ43),0) -> 0 | AT43: 21.63 | AU43: 17.26 | AV43: 23.15 | AW43: 19.94 | AX43: 26.63 | AY43: 21.33 | AZ43: 28.43 | BA43: 21.47 | BB43: 28.61 | BC43: 21.63 | BD43: 28.82 | BE43: 22.26 | BF43: 29.63 | BG43: 18.57 | BH43: 25.67 | BI43: 18.68 | BJ43: 25.82 | BK43: 18.8 | BL43: 25.99 | BM43: Negativa | BN43: Grupo 1
A44: Natulab | B44: Medicamentos | C44: 7898133134753 | D44: 23868 | E44: 15000277 | F44: KALONAT 20% X 10ML | G44: 30049029 | H44: ATIVO | I44: 100 | J44: 5.09 | M44: 0 | N44: =IFERROR(100%-(J44/M44),0) -> 0 | P44: 0 | Q44: =IFERROR(100%-(M44/P44),0) -> 0 | S44: 0 | T44: =IFERROR(100%-(M44/S44),0) -> 0 | V44: 0 | W44: =IFERROR(100%-(M44/V44),0) -> 0 | Y44: 0 | Z44: =IFERROR(100%-(M44/Y44),0) -> 0 | AB44: 0 | AC44: =IFERROR(100%-(M44/AB44),0) -> 0 | AE44: 4.6477157 | AF44: =IFERROR(100%-(M44/AE44),0) -> 1 | AH44: 4.85 | AI44: =IFERROR(100%-(M44/AH44),0) -> 1 | AK44: 9.8115 | AL44: =IFERROR(100%-(M44/AK44),0) -> 1 | AN44: 0 | AO44: =IFERROR(100%-(M44/AN44),0) -> 0 | AR44: =IFERROR(100%-(P44/AQ44),0) -> 0 | AT44: 31.65 | AU44: 25.25 | AV44: 33.87 | AW44: 29.18 | AX44: 38.97 | AY44: 31.21 | AZ44: 41.6 | BA44: 31.42 | BB44: 41.87 | BC44: 31.65 | BD44: 42.17 | BE44: 32.57 | BF44: 43.35 | BG44: 27.17 | BH44: 37.56 | BI44: 27.34 | BJ44: 37.8 | BK44: 27.5 | BL44: 38.02 | BM44: Negativa | BN44: Grupo 1
A45: Natulab | B45: Medicamentos | C45: 7898133136092 | D45: 28605 | E45: 15000122 | F45: Kollangel 150ml Hortela Fn 1ct X 60fr - Farma | G45: 30039099 | H45: ATIVO | I45: 60 | J45: 4.93 | L45: 4.84 | M45: 4.93 | N45: =IFERROR(100%-(J45/M45),0) -> 0 | P45: 5.3 | Q45: =IFERROR(100%-(M45/P45),0) -> 0.069811321 | S45: 5.7 | T45: =IFERROR(100%-(M45/S45),0) -> 0.13508772 | V45: 4.9967763 | W45: =IFERROR(100%-(M45/V45),0) -> 0.013363871 | Y45: 5.3374656 | Z45: =IFERROR(100%-(M45/Y45),0) -> 0.076340645 | AB45: 5.7280118 | AC45: =IFERROR(100%-(M45/AB45),0) -> 0.13931742 | AE45: 4.7208122 | AF45: =IFERROR(100%-(M45/AE45),0) -> -0.044311828 | AH45: 0 | AI45: =IFERROR(100%-(M45/AH45),0) -> 0 | AK45: 0 | AL45: =IFERROR(100%-(M45/AK45),0) -> 0 | AN45: 0 | AO45: =IFERROR(100%-(M45/AN45),0) -> 0 | AR45: =IFERROR(100%-(P45/AQ45),0) -> 0 | AT45: 24.4 | AU45: 19.47 | AV45: 26.11 | AW45: 22.5 | AX45: 30.05 | AY45: 24.06 | AZ45: 32.07 | BA45: 24.23 | BB45: 32.28 | BC45: 24.4 | BD45: 32.51 | BE45: 25.11 | BF45: 33.42 | BG45: 20.95 | BH45: 28.96 | BI45: 21.07 | BJ45: 29.13 | BK45: 21.2 | BL45: 29.31 | BM45: Negativa | BN45: Grupo 1
A46: Natulab | B46: Medicamentos | C46: 7898133136085 | D46: 28607 | E46: 15000123 | F46: Kollangel 150ml Morango Fn 1ct X 60fr - Farma | G46: 30039099 | H46: ATIVO | I46: 60 | J46: 4.93 | L46: 4.84 | M46: 4.93 | N46: =IFERROR(100%-(J46/M46),0) -> 0 | P46: 5.3 | Q46: =IFERROR(100%-(M46/P46),0) -> 0.069811321 | S46: 5.7 | T46: =IFERROR(100%-(M46/S46),0) -> 0.13508772 | V46: 4.9967763 | W46: =IFERROR(100%-(M46/V46),0) -> 0.013363871 | Y46: 5.3374656 | Z46: =IFERROR(100%-(M46/Y46),0) -> 0.076340645 | AB46: 5.7280118 | AC46: =IFERROR(100%-(M46/AB46),0) -> 0.13931742 | AE46: 4.7208122 | AF46: =IFERROR(100%-(M46/AE46),0) -> -0.044311828 | AH46: 0 | AI46: =IFERROR(100%-(M46/AH46),0) -> 0 | AK46: 0 | AL46: =IFERROR(100%-(M46/AK46),0) -> 0 | AN46: 0 | AO46: =IFERROR(100%-(M46/AN46),0) -> 0 | AR46: =IFERROR(100%-(P46/AQ46),0) -> 0 | AT46: 25.57 | AU46: 20.4 | AV46: 27.36 | AW46: 23.58 | AX46: 31.49 | AY46: 25.21 | AZ46: 33.6 | BA46: 25.39 | BB46: 33.83 | BC46: 25.57 | BD46: 34.07 | BE46: 26.31 | BF46: 35.02 | BG46: 21.95 | BH46: 30.35 | BI46: 22.08 | BJ46: 30.52 | BK46: 22.22 | BL46: 30.72 | BM46: Negativa | BN46: Grupo 1
A47: Natulab | B47: Medicamentos | C47: 7898133134661 | D47: 28603 | E47: 15000121 | F47: Kollangel 150ml Papaia Fn 1ct X 60fr - Farma | G47: 30039099 | H47: ATIVO | I47: 60 | J47: 4.93 | M47: 4.93 | N47: =IFERROR(100%-(J47/M47),0) -> 0 | P47: 5.3 | Q47: =IFERROR(100%-(M47/P47),0) -> 0.069811321 | S47: 5.7 | T47: =IFERROR(100%-(M47/S47),0) -> 0.13508772 | V47: 4.9967763 | W47: =IFERROR(100%-(M47/V47),0) -> 0.013363871 | Y47: 5.3374656 | Z47: =IFERROR(100%-(M47/Y47),0) -> 0.076340645 | AB47: 5.7280118 | AC47: =IFERROR(100%-(M47/AB47),0) -> 0.13931742 | AE47: 4.7208122 | AF47: =IFERROR(100%-(M47/AE47),0) -> -0.044311828 | AH47: 0 | AI47: =IFERROR(100%-(M47/AH47),0) -> 0 | AK47: 0 | AL47: =IFERROR(100%-(M47/AK47),0) -> 0 | AN47: 0 | AO47: =IFERROR(100%-(M47/AN47),0) -> 0 | AR47: =IFERROR(100%-(P47/AQ47),0) -> 0 | AT47: 25.57 | AU47: 20.4 | AV47: 27.36 | AW47: 23.58 | AX47: 31.49 | AY47: 25.21 | AZ47: 33.6 | BA47: 25.39 | BB47: 33.83 | BC47: 25.57 | BD47: 34.07 | BE47: 26.31 | BF47: 35.02 | BG47: 21.95 | BH47: 30.35 | BI47: 22.08 | BJ47: 30.52 | BK47: 22.22 | BL47: 30.72 | BM47: Negativa | BN47: Grupo 1
A48: Natulab | B48: Medicamentos | C48: 7898133139420 | D48: 23876 | E48: 15000090 | F48: L-Enema 130ml 1ct X 50fr - Farma | G48: 30049099 | H48: ATIVO | I48: 50 | J48: 7.65 | L48: 7.5 | M48: 7.65 | N48: =IFERROR(100%-(J48/M48),0) -> 0 | P48: 8.22 | Q48: =IFERROR(100%-(M48/P48),0) -> 0.069343066 | S48: 8.84 | T48: =IFERROR(100%-(M48/S48),0) -> 0.13461538 | V48: 7.7479476 | W48: =IFERROR(100%-(M48/V48),0) -> 0.012641743 | Y48: 8.2762167 | Z48: =IFERROR(100%-(M48/Y48),0) -> 0.07566461 | AB48: 8.8817935 | AC48: =IFERROR(100%-(M48/AB48),0) -> 0.13868748 | AE48: 6.9847716 | AF48: =IFERROR(100%-(M48/AE48),0) -> -0.095239826 | AH48: 7.28 | AI48: =IFERROR(100%-(M48/AH48),0) -> -0.050824176 | AK48: 8.88 | AL48: =IFERROR(100%-(M48/AK48),0) -> 0.13851351 | AN48: 8.3916 | AO48: =IFERROR(100%-(M48/AN48),0) -> 0.088374088 | AR48: =IFERROR(100%-(P48/AQ48),0) -> 0 | AT48: 11.7 | AU48: 9.33 | AV48: 12.51 | AW48: 10.78 | AX48: 14.4 | AY48: 11.53 | AZ48: 15.36 | BA48: 11.61 | BB48: 15.47 | BC48: 11.7 | BD48: 15.59 | BE48: 12.04 | BF48: 16.03 | BG48: 10.04 | BH48: 13.88 | BI48: 10.11 | BJ48: 13.98 | BK48: 10.17 | BL48: 14.06 | BM48: Negativa | BN48: Grupo 1
A49: Natulab | B49: Medicamentos | C49: 7898133134715 | D49: 23879 | E49: 15000091 | F49: Limonada Purgativa 200ml 1 X 60fr - Farma | G49: 30039099 | H49: ATIVO | I49: 60 | J49: 4.36 | L49: 4.27 | M49: 4.36 | N49: =IFERROR(100%-(J49/M49),0) -> 0 | P49: 4.69 | Q49: =IFERROR(100%-(M49/P49),0) -> 0.070362473 | S49: 5.04 | T49: =IFERROR(100%-(M49/S49),0) -> 0.13492063 | V49: 4.4165055 | W49: =IFERROR(100%-(M49/V49),0) -> 0.012794161 | Y49: 4.7176309 | Z49: =IFERROR(100%-(M49/Y49),0) -> 0.075807299 | AB49: 5.0628234 | AC49: =IFERROR(100%-(M49/AB49),0) -> 0.13882044 | AE49: 3.9761421 | AF49: =IFERROR(100%-(M49/AE49),0) -> -0.096540278 | AH49: 0 | AI49: =IFERROR(100%-(M49/AH49),0) -> 0 | AK49: 0 | AL49: =IFERROR(100%-(M49/AK49),0) -> 0 | AN49: 0 | AO49: =IFERROR(100%-(M49/AN49),0) -> 0 | AR49: =IFERROR(100%-(P49/AQ49),0) -> 0 | AT49: 29.33 | AU49: 23.4 | AV49: 31.39 | AW49: 27.04 | AX49: 36.12 | AY49: 28.92 | AZ49: 38.54 | BA49: 29.12 | BB49: 38.8 | BC49: 29.33 | BD49: 39.08 | BE49: 30.18 | BF49: 40.17 | BG49: 25.18 | BH49: 34.81 | BI49: 25.33 | BJ49: 35.02 | BK49: 25.49 | BL49: 35.24 | BM49: Negativa | BN49: Grupo 1
A50: Natulab | B50: Medicamentos | C50: 7898133137969 | D50: 35686 | E50: 15000135 | F50: Lufbem Gotas 15ml 1ct X 100 - Farma | G50: 30049099 | H50: ATIVO | I50: 100 | J50: 1.78 | L50: 1.75 | M50: 1.78 | N50: =IFERROR(100%-(J50/M50),0) -> 0 | P50: 1.92 | Q50: =IFERROR(100%-(M50/P50),0) -> 0.072916667 | S50: 2.06 | T50: =IFERROR(100%-(M50/S50),0) -> 0.13592233 | V50: 1.8052869 | W50: =IFERROR(100%-(M50/V50),0) -> 0.014007143 | Y50: 1.9283747 | Z50: =IFERROR(100%-(M50/Y50),0) -> 0.076942857 | AB50: 2.0694752 | AC50: =IFERROR(100%-(M50/AB50),0) -> 0.13987857 | AE50: 1.7 | AF50: =IFERROR(100%-(M50/AE50),0) -> -0.047058824 | AH50: 1.45 | AI50: =IFERROR(100%-(M50/AH50),0) -> -0.22758621 | AK50: 5.2775 | AL50: =IFERROR(100%-(M50/AK50),0) -> 0.66271909 | AN50: 0 | AO50: =IFERROR(100%-(M50/AN50),0) -> 0 | AR50: =IFERROR(100%-(P50/AQ50),0) -> 0 | AT50: 21.11 | AU50: 16.84 | AV50: 22.59 | AW50: 19.46 | AX50: 25.99 | AY50: 20.81 | AZ50: 27.73 | BA50: 20.96 | BB50: 27.93 | BC50: 21.11 | BD50: 28.13 | BE50: 21.72 | BF50: 28.91 | BG50: 18.12 | BH50: 25.05 | BI50: 18.23 | BJ50: 25.2 | BK50: 18.34 | BL50: 25.35 | BM50: Negativa | BN50: Grupo 1
A51: Natulab | B51: Medicamentos | C51: 7899470802275 | D51: 23883 | E51: 15000093 | F51: Magmax Hortela 100ml 1 X 100fr - Farma | G51: 30049099 | H51: ATIVO | I51: 100 | J51: 3.07 | L51: 3.01 | M51: 3.07 | N51: =IFERROR(100%-(J51/M51),0) -> 0 | P51: 3.3 | Q51: =IFERROR(100%-(M51/P51),0) -> 0.06969697 | S51: 3.54 | T51: =IFERROR(100%-(M51/S51),0) -> 0.13276836 | V51: 3.1055233 | W51: =IFERROR(100%-(M51/V51),0) -> 0.011438754 | Y51: 3.3172635 | Z51: =IFERROR(100%-(M51/Y51),0) -> 0.074538408 | AB51: 3.5599901 | AC51: =IFERROR(100%-(M51/AB51),0) -> 0.13763806 | AE51: 2.9340102 | AF51: =IFERROR(100%-(M51/AE51),0) -> -0.046349481 | AH51: 2.92 | AI51: =IFERROR(100%-(M51/AH51),0) -> -0.051369863 | AK51: 0 | AL51: =IFERROR(100%-(M51/AK51),0) -> 0 | AN51: 0 | AO51: =IFERROR(100%-(M51/AN51),0) -> 0 | AR51: =IFERROR(100%-(P51/AQ51),0) -> 0 | AT51: 15.38 | AU51: 12.27 | AV51: 16.46 | AW51: 14.18 | AX51: 18.94 | AY51: 15.16 | AZ51: 20.2 | BA51: 15.27 | BB51: 20.34 | BC51: 15.38 | BD51: 20.49 | BE51: 15.83 | BF51: 21.07 | BG51: 13.2 | BH51: 18.25 | BI51: 13.28 | BJ51: 18.36 | BK51: 13.36 | BL51: 18.47 | BM51: Negativa | BN51: Grupo 1
A52: Natulab | B52: Medicamentos | C52: 7899470802268 | D52: 23881 | E52: 15000092 | F52: Magmax Tradicional 100ml 1 X 100fr - Farma | G52: 30049099 | H52: ATIVO | I52: 100 | J52: 3.07 | L52: 3.01 | M52: 3.07 | N52: =IFERROR(100%-(J52/M52),0) -> 0 | P52: 3.3 | Q52: =IFERROR(100%-(M52/P52),0) -> 0.06969697 | S52: 3.54 | T52: =IFERROR(100%-(M52/S52),0) -> 0.13276836 | V52: 3.1055233 | W52: =IFERROR(100%-(M52/V52),0) -> 0.011438754 | Y52: 3.3172635 | Z52: =IFERROR(100%-(M52/Y52),0) -> 0.074538408 | AB52: 3.5599901 | AC52: =IFERROR(100%-(M52/AB52),0) -> 0.13763806 | AE52: 2.9340102 | AF52: =IFERROR(100%-(M52/AE52),0) -> -0.046349481 | AH52: 2.92 | AI52: =IFERROR(100%-(M52/AH52),0) -> -0.051369863 | AK52: 4.944 | AL52: =IFERROR(100%-(M52/AK52),0) -> 0.37904531 | AN52: 3.212055 | AO52: =IFERROR(100%-(M52/AN52),0) -> 0.044225581 | AR52: =IFERROR(100%-(P52/AQ52),0) -> 0 | AT52: 15.45 | AU52: 12.32 | AV52: 16.52 | AW52: 14.24 | AX52: 19.02 | AY52: 15.23 | AZ52: 20.3 | BA52: 15.34 | BB52: 20.44 | BC52: 15.45 | BD52: 20.58 | BE52: 15.9 | BF52: 21.16 | BG52: 13.26 | BH52: 18.33 | BI52: 13.34 | BJ52: 18.44 | BK52: 13.43 | BL52: 18.57 | BM52: Negativa | BN52: Grupo 1
A53: Natulab | B53: Medicamentos | C53: 7899470807225 | D53: 38804 | E53: 15000194 | F53: Masferol Comprimidos 109mg 2bl X 20com X 200ct - Farma | G53: 30039099 | H53: ATIVO | I53: 200 | J53: 3.25 | L53: 3.18 | M53: 3.25 | N53: =IFERROR(100%-(J53/M53),0) -> 0 | P53: 3.49 | Q53: =IFERROR(100%-(M53/P53),0) -> 0.068767908 | S53: 3.75 | T53: =IFERROR(100%-(M53/S53),0) -> 0.13333333 | V53: 3.2884419 | W53: =IFERROR(100%-(M53/V53),0) -> 0.011689994 | Y53: 3.5126538 | Z53: =IFERROR(100%-(M53/Y53),0) -> 0.074773611 | AB53: 3.7696773 | AC53: =IFERROR(100%-(M53/AB53),0) -> 0.13785723 | AE53: 3.035533 | AF53: =IFERROR(100%-(M53/AE53),0) -> -0.070652174 | AH53: 3.09 | AI53: =IFERROR(100%-(M53/AH53),0) -> -0.051779935 | AK53: 4.1752 | AL53: =IFERROR(100%-(M53/AK53),0) -> 0.22159418 | AN53: 0 | AO53: =IFERROR(100%-(M53/AN53),0) -> 0 | AR53: =IFERROR(100%-(P53/AQ53),0) -> 0 | AT53: 12.28 | AU53: 9.8 | AV53: 13.14 | AW53: 11.32 | AX53: 15.12 | AY53: 12.11 | AZ53: 16.14 | BA53: 12.19 | BB53: 16.24 | BC53: 12.28 | BD53: 16.36 | BE53: 12.64 | BF53: 16.82 | BG53: 10.54 | BH53: 14.57 | BI53: 10.61 | BJ53: 14.67 | BK53: 10.67 | BL53: 14.75 | BM53: Negativa | BN53: Grupo 1
A54: Natulab | B54: Medicamentos | C54: 7898133134999 | D54: 41484 | E54: 15000143 | F54: MASFEROL SOL OR 25MG/ML X 100ML | G54: 30039099 | H54: ATIVO | I54: 50 | J54: 2.19 | L54: 2.15 | M54: 2.19 | N54: =IFERROR(100%-(J54/M54),0) -> 0 | P54: 2.36 | Q54: =IFERROR(100%-(M54/P54),0) -> 0.072033898 | S54: 2.54 | T54: =IFERROR(100%-(M54/S54),0) -> 0.13779528 | V54: 2.2238384 | W54: =IFERROR(100%-(M54/V54),0) -> 0.015216206 | Y54: 2.3754637 | Z54: =IFERROR(100%-(M54/Y54),0) -> 0.078074746 | AB54: 2.5492781 | AC54: =IFERROR(100%-(M54/AB54),0) -> 0.14093329 | AE54: 2.0040609 | AF54: =IFERROR(100%-(M54/AE54),0) -> -0.092781155 | AH54: 2.09 | AI54: =IFERROR(100%-(M54/AH54),0) -> -0.04784689 | AK54: 2.7792 | AL54: =IFERROR(100%-(M54/AK54),0) -> 0.21200345 | AN54: 0 | AO54: =IFERROR(100%-(M54/AN54),0) -> 0 | AR54: =IFERROR(100%-(P54/AQ54),0) -> 0 | AT54: 11.58 | AU54: 9.24 | AV54: 12.39 | AW54: 10.67 | AX54: 14.25 | AY54: 11.41 | AZ54: 15.2 | BA54: 11.49 | BB54: 15.31 | BC54: 11.58 | BD54: 15.43 | BE54: 11.92 | BF54: 15.87 | BG54: 9.94 | BH54: 13.74 | BI54: 10 | BJ54: 13.82 | BK54: 10.06 | BL54: 13.91 | BM54: Negativa | BN54: Grupo 2
A55: Natulab | B55: Medicamentos | C55: 7898133131028 | D55: 23912 | E55: 15000096 | F55: Maxalgina 100ml 1ct X 50fr - Farma | G55: 30049069 | H55: ATIVO | I55: 50 | J55: 2.85 | L55: 2.8 | M55: 2.85 | N55: =IFERROR(100%-(J55/M55),0) -> 0 | P55: 3.07 | Q55: =IFERROR(100%-(M55/P55),0) -> 0.071661238 | S55: 3.3 | T55: =IFERROR(100%-(M55/S55),0) -> 0.13636364 | V55: 2.8906082 | W55: =IFERROR(100%-(M55/V55),0) -> 0.014048327 | Y55: 3.0876951 | Z55: =IFERROR(100%-(M55/Y55),0) -> 0.076981413 | AB55: 3.313624 | AC55: =IFERROR(100%-(M55/AB55),0) -> 0.1399145 | AE55: 2.7309645 | AF55: =IFERROR(100%-(M55/AE55),0) -> -0.043587361 | AH55: 0 | AI55: =IFERROR(100%-(M55/AH55),0) -> 0 | AK55: 0 | AL55: =IFERROR(100%-(M55/AK55),0) -> 0 | AN55: 2.7479844 | AO55: =IFERROR(100%-(M55/AN55),0) -> -0.037123792 | AR55: =IFERROR(100%-(P55/AQ55),0) -> 0 | AT55: 17.84 | AU55: 14.23 | AV55: 19.08 | AW55: 16.45 | AX55: 21.97 | AY55: 17.59 | AZ55: 23.44 | BA55: 17.71 | BB55: 23.6 | BC55: 17.84 | BD55: 23.77 | BE55: 18.36 | BF55: 24.44 | BG55: 15.32 | BH55: 21.18 | BI55: 15.41 | BJ55: 21.3 | BK55: 15.5 | BL55: 21.43 | BM55: Negativa | BN55: Grupo 2
...

Sheet Proposta Distr e Redes única
F2: Tabela retail de out/21 - última atualização 2021 | N2: DPN - AUTONOMIA GR | V2: RCA | W2: PRIME | Y2: * OBS: REVISAR EM 2022 TABELAS REDES. CRIAR TABELAS PRO CANA, POIS TEM REDES EM DPN/PRIME, DIFICULTANDO A PRECIFICAÇÃO DAS REDES
N3: 0.15 | O3: 0.14 | P3: 0.13 | Q3: 0.12 | R3: 0.11 | S3: 0.1 | T3: 0.09 | U3: 0.08 | V3: 0.07 | W3: 0.1 | X3: 0
A4: LISTA DE PREÇO: Nº 052021 - Vigência: 01/08/2021
A5: LISTA DE PREÇO FABRICA E PREÇO MÁXIMO CONSUMIDOR | J5: Preço Lista | M5: 0.17 | N5: AUTONOMIA GNR | O5: Autonomia - KAM | Y5: REVISAR EM 2022* | AD5: ICMS 0% | AF5: ICMS 12% | AH5: ICMS 17% | AJ5: ICMS 17,5% | AL5: ICMS 18% | AN5: ICMS 20% | AP5: ICMS 17% (ALC) | AR5: ICMS 17,5% (ALC) | AT5: ICMS 18% (ALC)
A6: Empresa | B6: Canal | C6: EAN | D6: Código CIGAM | E6: Código SAP | F6: Descrição | G6: NCM | H6: Status | I6: UN/CX | J6: PV BASE | L6: Preço Médio | M6: Nova PV Base | N6: 0.15 | O6: 0.14 | P6: 0.13 | Q6: 0.12 | R6: 0.11 | S6: 0.1 | T6: 0.09 | U6: 0.08 | V6: 0.07 | W6: 0.035 | X6: 0 | Y6: PAGUE MENOS | Z6: RD | AA6: DPSP | AC6: PF 18% (SAP) | AD6: PF | AE6: PMC | AF6: PF | AG6: PMC | AH6: PF | AI6: PMC | AJ6: PF | AK6: PMC | AL6: PF | AM6: PMC | AN6: PF | AO6: PMC | AP6: PF | AQ6: PMC | AR6: PF | AS6: PMC | AT6: PF | AU6: PMC | AV6: Lista PIS/COFINS | AW6: Categoria de Grupo CMED
A7: Natulab | B7: Medicamentos | C7: 7899470804828 | D7: 43890 | E7: 15000145 | F7: AD-VITAM SOL GOT X 20ML | G7: 30045040 | H7: ATIVO | I7: 50 | J7: ='LISTA PREÇO 2022-Vigen 01.02.22'!J7 -> 4.23 | L7: 4.15 | M7: =J7/(100%-$M$5) -> 5.0963855 | N7: =$M7*(100%-N$6) -> 4.3319277 | O7: =$M7*(100%-O$6) -> 4.3828916 | P7: =$M7*(100%-P$6) -> 4.4338554 | Q7: =$M7*(100%-Q$6) -> 4.4848193 | R7: =$M7*(100%-R$6) -> 4.5357831 | S7: =$M7*(100%-S$6) -> 4.586747 | T7: =$M7*(100%-T$6) -> 4.6377108 | U7: =$M7*(100%-U$6) -> 4.6886747 | ... X7: =$M7*(100%-X$6) -> 5.0963855 | Y7: 0 | Z7: 0 | AA7: 0 | AC7: 12.14 | AD7: 9.68 | AE7: 12.98 | AF7: 11.19 | AG7: 14.94 | AH7: 11.97 | AI7: 15.95 | AJ7: 12.05 | AK7: 16.05 | AL7: 12.14 | AM7: 16.17 | AN7: 12.49 | AO7: 16.63 | AP7: 10.42 | AQ7: 14.41 | AR7: 10.49 | AS7: 14.5 | AT7: 10.55 | AU7: 14.59 | AV7: Negativa | AW7: Grupo 2
A8: Natulab | B8: Medicamentos | C8: 7898133136535 | D8: 23646 | E8: 15000153 | F8: Afolic Comprimido 5mg 1bl X 20com X 200ct - Farma | G8: 30045090 | H8: ATIVO | I8: 200 | J8: ='LISTA PREÇO 2022-Vigen 01.02.22'!J8 -> 1.47 | L8: 1.54 | M8: =J8/(100%-$M$5) -> 1.7710843 | N8: =$M8*(100%-N$6) -> 1.5054217 | O8: =$M8*(100%-O$6) -> 1.5231325 | P8: =$M8*(100%-P$6) -> 1.5408434 | Q8: =$M8*(100%-Q$6) -> 1.5585542 | R8: =$M8*(100%-R$6) -> 1.5762651 | S8: =$M8*(100%-S$6) -> 1.5939759 | T8: =$M8*(100%-T$6) -> 1.6116867 | U8: =$M8*(100%-U$6) -> 1.6293976 | ... X8: =$M8*(100%-X$6) -> 1.7710843 | Y8: 1.4 | Z8: 4.3575 | AA8: 0 | AC8: 8.83 | AD8: 7.04 | AE8: 9.44 | AF8: 8.14 | AG8: 10.87 | AH8: 8.7 | AI8: 11.59 | AJ8: 8.76 | AK8: 11.67 | AL8: 8.83 | AM8: 11.76 | AN8: 9.09 | AO8: 12.1 | AP8: 7.58 | AQ8: 10.48 | AR8: 7.63 | AS8: 10.55 | AT8: 7.67 | AU8: 10.6 | AV8: Negativa | AW8: Grupo 3
A9: Natulab | B9: Medicamentos | C9: 7898133139741 | D9: 34232 | E9: 15000133 | F9: Aftliv 25ml 1ct X 100fr - Farma | G9: 30042029 | H9: ATIVO | I9: 200 | J9: ='LISTA PREÇO 2022-Vigen 01.02.22'!J9 -> 7.12 | L9: 6.98 | M9: =J9/(100%-$M$5) -> 8.5783133 | N9: =$M9*(100%-N$6) -> 7.2915663 | O9: =$M9*(100%-O$6) -> 7.3773494 | P9: =$M9*(100%-P$6) -> 7.4631325 | Q9: =$M9*(100%-Q$6) -> 7.5489157 | R9: =$M9*(100%-R$6) -> 7.6346988 | S9: =$M9*(100%-S$6) -> 7.7204819 | T9: =$M9*(100%-T$6) -> 7.8062651 | U9: =$M9*(100%-U$6) -> 7.8920482 | ... X9: =$M9*(100%-X$6) -> 8.5783133 | Y9: 6.78 | Z9: 9.9596 | AA9: 0 | AC9: 35.57 | AD9: 28.38 | AE9: 38.07 | AF9: 32.8 | AG9: 43.81 | AH9: 35.07 | AI9: 46.74 | AJ9: 35.32 | AK9: 47.06 | AL9: 35.57 | AM9: 47.39 | AN9: 36.6 | AO9: 48.72 | AP9: 30.54 | AQ9: 42.22 | AR9: 30.72 | AS9: 42.47 | AT9: 30.91 | AU9: 42.73 | AV9: Negativa | AW9: Grupo 1
A10: Natulab | B10: Medicamentos | C10: 7899470801414 | D10: 23719 | E10: 15000155 | F10: Alcachofra Natulab 300mg 2bl X 15cap X 50ct - Farma | G10: 30044990 | H10: ATIVO | I10: 50 | J10: ='LISTA PREÇO 2022-Vigen 01.02.22'!J10 -> 7.85 | L10: 7.69 | M10: =J10/(100%-$M$5) -> 9.4578313 | N10: =$M10*(100%-N$6) -> 8.0391566 | O10: =$M10*(100%-O$6) -> 8.1337349 | P10: =$M10*(100%-P$6) -> 8.2283133 | Q10: =$M10*(100%-Q$6) -> 8.3228916 | R10: =$M10*(100%-R$6) -> 8.4174699 | S10: =$M10*(100%-S$6) -> 8.5120482 | T10: =$M10*(100%-T$6) -> 8.6066265 | U10: =$M10*(100%-U$6) -> 8.7012048 | ... X10: =$M10*(100%-X$6) -> 9.4578313 | Y10: 0 | Z10: 0 | AA10: 0 | AC10: 28.88 | AD10: 23.04 | AE10: 30.9 | AF10: 26.63 | AG10: 35.57 | AH10: 28.47 | AI10: 37.94 | AJ10: 28.67 | AK10: 38.2 | AL10: 28.88 | AM10: 38.48 | AN10: 29.72 | AO10: 39.56 | AP10: 24.79 | AQ10: 34.27 | AR10: 24.94 | AS10: 34.48 | AT10: 25.09 | AU10: 34.69 | AV10: Negativa | AW10: Grupo 2
A11: Natulab | B11: Medicamentos | C11: 7898133134456 | D11: 28582 | E11: 15000120 | F11: Alumimax 100ml Fn 1ct X 50fr - Farma | G11: 30049099 | H11: ATIVO | I11: 50 | J11: ='LISTA PREÇO 2022-Vigen 01.02.22'!J11 -> 3.04 | L11: 2.98 | M11: =J11/(100%-$M$5) -> 3.6626506 | N11: =$M11*(100%-N$6) -> 3.113253 | O11: =$M11*(100%-O$6) -> 3.1498795 | P11: =$M11*(100%-P$6) -> 3.186506 | Q11: =$M11*(100%-Q$6) -> 3.2231325 | R11: =$M11*(100%-R$6) -> 3.259759 | S11: =$M11*(100%-S$6) -> 3.2963855 | T11: =$M11*(100%-T$6) -> 3.333012 | U11: =$M11*(100%-U$6) -> 3.3696386 | ... X11: =$M11*(100%-X$6) -> 3.6626506 | Y11: 0 | Z11: 0 | AA11: 0 | AC11: 16.84 | AD11: 13.43 | AE11: 18.01 | AF11: 15.52 | AG11: 20.73 | AH11: 16.6 | AI11: 22.12 | AJ11: 16.72 | AK11: 22.28 | AL11: 16.84 | AM11: 22.44 | AN11: 17.33 | AO11: 23.07 | AP11: 14.46 | AQ11: 19.99 | AR11: 14.54 | AS11: 20.1 | AT11: 14.63 | AU11: 20.23 | AV11: Negativa | AW11: Grupo 1
A12: Natulab | B12: Medicamentos | C12: 7898133134630 | D12: 28578 | E12: 15000119 | F12: Alumimax 150ml Fn 1ct X 60fr - Farma | G12: 30049099 | H12: ATIVO | I12: 60 | J12: ='LISTA PREÇO 2022-Vigen 01.02.22'!J12 -> 4.02 | L12: 3.94 | M12: =J12/(100%-$M$5) -> 4.8433735 | N12: =$M12*(100%-N$6) -> 4.1168675 | O12: =$M12*(100%-O$6) -> 4.1653012 | P12: =$M12*(100%-P$6) -> 4.2137349 | Q12: =$M12*(100%-Q$6) -> 4.2621687 | R12: =$M12*(100%-R$6) -> 4.3106024 | S12: =$M12*(100%-S$6) -> 4.3590361 | T12: =$M12*(100%-T$6) -> 4.4074699 | U12: =$M12*(100%-U$6) -> 4.4559036 | ... X12: =$M12*(100%-X$6) -> 4.8433735 | Y12: 0 | Z12: 0 | AA12: 0 | AC12: 20.91 | AD12: 16.68 | AE12: 22.37 | AF12: 19.28 | AG12: 25.75 | AH12: 20.62 | AI12: 27.48 | AJ12: 20.76 | AK12: 27.66 | AL12: 20.91 | AM12: 27.86 | AN12: 21.52 | AO12: 28.64 | AP12: 17.95 | AQ12: 24.82 | AR12: 18.06 | AS12: 24.97 | AT12: 18.17 | AU12: 25.12 | AV12: Negativa | AW12: Grupo 1
A13: Natulab | B13: Medicamentos | C13: 7898133136634 | D13: 23792 | E13: 15000068 | F13: Arlivry 100ml Cereja 1ct X 50fr - Farma | G13: 30049099 | H13: ATIVO | I13: 50 | J13: ='LISTA PREÇO 2022-Vigen 01.02.22'!J13 -> 3.61 | L13: 3.54 | M13: =J13/(100%-$M$5) -> 4.3493976 | N13: =$M13*(100%-N$6) -> 3.696988 | O13: =$M13*(100%-O$6) -> 3.7404819 | P13: =$M13*(100%-P$6) -> 3.7839759 | Q13: =$M13*(100%-Q$6) -> 3.8274699 | R13: =$M13*(100%-R$6) -> 3.8709639 | S13: =$M13*(100%-S$6) -> 3.9144578 | T13: =$M13*(100%-T$6) -> 3.9579518 | U13: =$M13*(100%-U$6) -> 4.0014458 | ... X13: =$M13*(100%-X$6) -> 4.3493976 | Y13: 3.3 | Z13: 13.133 | AA13: 12.515 | AC13: 19.93 | AD13: 15.9 | AE13: 21.32 | AF13: 18.37 | AG13: 24.53 | AH13: 19.65 | AI13: 26.19 | AJ13: 19.79 | AK13: 26.37 | AL13: 19.93 | AM13: 26.55 | AN13: 20.51 | AO13: 27.3 | AP13: 17.11 | AQ13: 23.65 | AR13: 17.21 | AS13: 23.79 | AT13: 17.32 | AU13: 23.94 | AV13: Negativa | AW13: Grupo 2
A14: Natulab | B14: Medicamentos | C14: 7898133136757 | D14: 23794 | E14: 15000069 | F14: Arlivry 100ml Mel 1ct X 50fr - Farma | G14: 30049099 | H14: ATIVO | I14: 50 | J14: ='LISTA PREÇO 2022-Vigen 01.02.22'!J14 -> 3.61 | L14: 3.54 | M14: =J14/(100%-$M$5) -> 4.3493976 | N14: =$M14*(100%-N$6) -> 3.696988 | O14: =$M14*(100%-O$6) -> 3.7404819 | P14: =$M14*(100%-P$6) -> 3.7839759 | Q14: =$M14*(100%-Q$6) -> 3.8274699 | R14: =$M14*(100%-R$6) -> 3.8709639 | S14: =$M14*(100%-S$6) -> 3.9144578 | T14: =$M14*(100%-T$6) -> 3.9579518 | U14: =$M14*(100%-U$6) -> 4.0014458 | ... X14: =$M14*(100%-X$6) -> 4.3493976 | Y14: 3.3 | Z14: 13.144 | AA14: 12.515 | AC14: 25.03 | AD14: 19.97 | AE14: 26.78 | AF14: 23.08 | AG14: 30.83 | AH14: 24.68 | AI14: 32.89 | AJ14: 24.85 | AK14: 33.11 | AL14: 25.03 | AM14: 33.35 | AN14: 25.76 | AO14: 34.29 | AP14: 21.49 | AQ14: 29.71 | AR14: 21.62 | AS14: 29.89 | AT14: 21.75 | AU14: 30.07 | AV14: Negativa | AW14: Grupo 2
A15: Natulab | B15: Medicamentos | C15: 7899470802725 | D15: 23670 | E15: 15000154 | F15: Arpynflan 450mg 2bl X 15cap X 100ct - Farma | G15: 30049099 | H15: ATIVO | I15: 100 | J15: ='LISTA PREÇO 2022-Vigen 01.02.22'!J15 -> 21.2 | L15: 20.79 | M15: =J15/(100%-$M$5) -> 25.542169 | N15: =$M15*(100%-N$6) -> 21.710843 | O15: =$M15*(100%-O$6) -> 21.966265 | P15: =$M15*(100%-P$6) -> 22.221687 | Q15: =$M15*(100%-Q$6) -> 22.477108 | R15: =$M15*(100%-R$6) -> 22.73253 | S15: =$M15*(100%-S$6) -> 22.987952 | T15: =$M15*(100%-T$6) -> 23.243373 | U15: =$M15*(100%-U$6) -> 23.498795 | ... X15: =$M15*(100%-X$6) -> 25.542169 | Y15: 0 | Z15: 0 | AA15: 0 | AC15: 82.28 | AD15: 65.66 | AE15: 88.08 | AF15: 75.87 | AG15: 101.34 | AH15: 81.13 | AI15: 108.14 | AJ15: 81.7 | AK15: 108.87 | AL15: 82.28 | AM15: 109.62 | AN15: 84.66 | AO15: 112.69 | AP15: 70.63 | AQ15: 97.64 | AR15: 71.06 | AS15: 98.24 | AT15: 71.49 | AU15: 98.83 | AV15: Negativa | AW15: Grupo 2
A16: Natulab | B16: Medicamentos | C16: 7899470805726 | D16: 27414 | E16: 15000220 | F16: Baby D - Pomada Para Assadura 45g 1bg X 100ct - Farma | G16: 30049099 | H16: ATIVO | I16: 100 | J16: ='LISTA PREÇO 2022-Vigen 01.02.22'!J16 -> 3.79 | L16: 3.71 | M16: =J16/(100%-$M$5) -> 4.5662651 | N16: =$M16*(100%-N$6) -> 3.8813253 | O16: =$M16*(100%-O$6) -> 3.926988 | P16: =$M16*(100%-P$6) -> 3.9726506 | Q16: =$M16*(100%-Q$6) -> 4.0183133 | R16: =$M16*(100%-R$6) -> 4.0639759 | S16: =$M16*(100%-S$6) -> 4.1096386 | T16: =$M16*(100%-T$6) -> 4.1553012 | U16: =$M16*(100%-U$6) -> 4.2009639 | ... X16: =$M16*(100%-X$6) -> 4.5662651 | Y16: 0 | Z16: 0 | AA16: 0 | AC16: 20.49 | AD16: 16.35 | AE16: 21.93 | AF16: 18.89 | AG16: 25.23 | AH16: 20.2 | AI16: 26.92 | AJ16: 20.34 | AK16: 27.1 | AL16: 20.49 | AM16: 27.3 | AN16: 21.08 | AO16: 28.06 | AP16: 17.59 | AQ16: 24.32 | AR16: 17.7 | AS16: 24.47 | AT16: 17.8 | AU16: 24.61 | AV16: Negativa | AW16: Grupo 1
A17: Natulab | B17: Medicamentos | C17: 7899470805955 | D17: 30023 | E17: 15000130 | F17: Bronqtrat 100ml 1ct X 50fr - Farma Novo | G17: 30049039 | H17: ATIVO | I17: 50 | J17: ='LISTA PREÇO 2022-Vigen 01.02.22'!J17 -> 2.69 | M17: =J17/(100%-$M$5) -> 3.2409639 | N17: =$M17*(100%-N$6) -> 2.7548193 | O17: =$M17*(100%-O$6) -> 2.7872289 | P17: =$M17*(100%-P$6) -> 2.8196386 | Q17: =$M17*(100%-Q$6) -> 2.8520482 | R17: =$M17*(100%-R$6) -> 2.8844578 | S17: =$M17*(100%-S$6) -> 2.9168675 | T17: =$M17*(100%-T$6) -> 2.9492771 | U17: =$M17*(100%-U$6) -> 2.9816867 | ... X17: =$M17*(100%-X$6) -> 3.2409639 | Y17: 0 | Z17: 0 | AA17: 0 | AC17: 26.65 | AD17: 21.26 | AE17: 28.52 | AF17: 24.57 | AG17: 32.82 | AH17: 26.28 | AI17: 35.02 | AJ17: 26.46 | AK17: 35.26 | AL17: 26.65 | AM17: 35.51 | AN17: 27.42 | AO17: 36.5 | AP17: 22.88 | AQ17: 31.63 | AR17: 23.02 | AS17: 31.82 | AT17: 23.16 | AU17: 32.02 | AV17: Negativa | AW17: Grupo 2
A18: Natulab | B18: Medicamentos | C18: 7898133135941 | D18: 23805 | E18: 15000071 | F18: Bronqtrat Infantil 100ml 1ct X 50fr - Farma | G18: 30049039 | H18: ATIVO | I18: 50 | J18: ='LISTA PREÇO 2022-Vigen 01.02.22'!J18 -> 2.81 | L18: 2.76 | M18: =J18/(100%-$M$5) -> 3.3855422 | N18: =$M18*(100%-N$6) -> 2.8777108 | O18: =$M18*(100%-O$6) -> 2.9115663 | P18: =$M18*(100%-P$6) -> 2.9454217 | Q18: =$M18*(100%-Q$6) -> 2.9792771 | R18: =$M18*(100%-R$6) -> 3.0131325 | S18: =$M18*(100%-S$6) -> 3.046988 | T18: =$M18*(100%-T$6) -> 3.0808434 | U18: =$M18*(100%-U$6) -> 3.1146988 | ... X18: =$M18*(100%-X$6) -> 3.3855422 | Y18: 0 | Z18: 0 | AA18: 0 | AC18: 27.79 | AD18: 22.17 | AE18: 29.74 | AF18: 25.62 | AG18: 34.22 | AH18: 27.4 | AI18: 36.52 | AJ18: 27.59 | AK18: 36.76 | AL18: 27.79 | AM18: 37.03 | AN18: 28.6 | AO18: 38.07 | AP18: 23.86 | AQ18: 32.99 | AR18: 24 | AS18: 33.18 | AT18: 24.15 | AU18: 33.39 | AV18: Negativa | AW18: Grupo 2
A19: Natulab | B19: Medicamentos | C19: 7899470802565 | D19: 28440 | E19: 15000117 | F19: Buscoplex Composto Gotas 20ml 1ct X 200fr - Farma | G19: 30044990 | H19: ATIVO | I19: 200 | J19: ='LISTA PREÇO 2022-Vigen 01.02.22'!J19 -> 5.6 | L19: 5.45 | M19: =J19/(100%-$M$5) -> 6.746988 | N19: =$M19*(100%-N$6) -> 5.7349398 | O19: =$M19*(100%-O$6) -> 5.8024096 | P19: =$M19*(100%-P$6) -> 5.8698795 | Q19: =$M19*(100%-Q$6) -> 5.9373494 | R19: =$M19*(100%-R$6) -> 6.0048193 | S19: =$M19*(100%-S$6) -> 6.0722892 | T19: =$M19*(100%-T$6) -> 6.139759 | U19: =$M19*(100%-U$6) -> 6.2072289 | ... X19: =$M19*(100%-X$6) -> 6.746988 | Y19: 5.29 | Z19: 8.1765 | AA19: 0 | AC19: 10.84 | AD19: 8.65 | AE19: 11.6 | AF19: 9.99 | AG19: 13.34 | AH19: 10.69 | AI19: 14.24 | AJ19: 10.76 | AK19: 14.33 | AL19: 10.84 | AM19: 14.44 | AN19: 11.15 | AO19: 14.84 | AP19: 9.31 | AQ19: 12.87 | AR19: 9.36 | AS19: 12.94 | AT19: 9.42 | AU19: 13.02 | AV19: Negativa | AW19: Grupo 2
A20: Natulab | B20: Medicamentos | C20: 7899470805849 | D20: 33549 | E20: 15000131 | F20: Butalab C/ Cp Med 100ml 1ct X 50fr - Farma | G20: 30039099 | H20: ATIVO | I20: 50 | J20: ='LISTA PREÇO 2022-Vigen 01.02.22'!J20 -> 1.77 | L20: 1.74 | M20: =J20/(100%-$M$5) -> 2.1325301 | N20: =$M20*(100%-N$6) -> 1.8126506 | O20: =$M20*(100%-O$6) -> 1.8339759 | P20: =$M20*(100%-P$6) -> 1.8553012 | Q20: =$M20*(100%-Q$6) -> 1.8766265 | R20: =$M20*(100%-R$6) -> 1.8979518 | S20: =$M20*(100%-S$6) -> 1.9192771 | T20: =$M20*(100%-T$6) -> 1.9406024 | U20: =$M20*(100%-U$6) -> 1.9619277 | ... X20: =$M20*(100%-X$6) -> 2.1325301 | Y20: 0 | Z20: 0 | AA20: 0 | AC20: 5.48 | AD20: 4.49 | AE20: 6.2 | AF20: 5.1 | AG20: 7.05 | AH20: 5.41 | AI20: 7.47 | AJ20: 5.44 | AK20: 7.52 | AL20: 5.48 | AM20: 7.58 | AN20: 5.62 | AO20: 7.77 | AP20: 5.41 | AQ20: 7.48 | AR20: 5.45 | AS20: 7.53 | AT20: 5.48 | AU20: 7.58 | AV20: Positiva | AW20: Grupo 3
A21: Natulab | B21: Medicamentos | C21: 7899470804200 | D21: 44983 | E21: 15000211 | F21: Cardomarin 127mg 2bl X 10com X 100ct - Farma | G21: 30049099 | H21: ATIVO | I21: 100 | J21: ='LISTA PREÇO 2022-Vigen 01.02.22'!J21 -> 11.98 | L21: 11.75 | M21: =J21/(100%-$M$5) -> 14.433735 | N21: =$M21*(100%-N$6) -> 12.268675 | O21: =$M21*(100%-O$6) -> 12.413012 | P21: =$M21*(100%-P$6) -> 12.557349 | Q21: =$M21*(100%-Q$6) -> 12.701687 | R21: =$M21*(100%-R$6) -> 12.846024 | S21: =$M21*(100%-S$6) -> 12.990361 | T21: =$M21*(100%-T$6) -> 13.134699 | U21: =$M21*(100%-U$6) -> 13.279036 | ... X21: =$M21*(100%-X$6) -> 14.433735 | Y21: 0 | Z21: 0 | AA21: 0 | AC21: 50.38 | AD21: 40.2 | AE21: 53.92 | AF21: 46.45 | AG21: 62.04 | AH21: 49.68 | AI21: 66.22 | AJ21: 50.02 | AK21: 66.65 | AL21: 50.38 | AM21: 67.12 | AN21: 51.84 | AO21: 69 | AP21: 43.25 | AQ21: 59.79 | AR21: 43.51 | AS21: 60.15 | AT21: 43.78 | AU21: 60.52 | AV21: Negativa | AW21: Grupo 1
