Workbook
Name \\\: #REF!
Name \0: #REF!
Name \A: #N/A
Name \B: #N/A
Name \C: #REF!
Name \d: #REF!
Name \E: #REF!
Name \F: [1]recobob20022!#REF!
Name \i: #REF!
Name \INC: '[2]jan''04'!#REF!
Name \M: #REF!
Name \P: #REF!
Name \Q: #REF!
Name \R: #REF!
Name \S: #REF!
Name \T: [1]recobob20022!#REF!
Name \V: #REF!
Name \x: #N/A
Name \z: #N/A
Name _____________________________hr4: #REF!
Name _____________________________rh1234: #REF!
Name ____________________________hr4: #REF!
Name ____________________________PG13: #REF!
Name ____________________________rh1234: #REF!
Name ____________________________xlnm.Print_Area_1: #REF!
Name ___________________________hr4: #REF!
Name ___________________________PG1: #REF!
Name ___________________________PG13: '[3]Strt Archi'!#REF!
Name ___________________________PG8: #REF!
Name ___________________________rh1234: #REF!
Name ___________________________sp2: #REF!
Name ___________________________xlnm.Print_Area_1: #REF!
Name ___________________________xlnm.Print_Area_10: #REF!
Name ___________________________xlnm.Print_Area_2: #REF!
Name ___________________________xlnm.Print_Area_25: #REF!
Name ___________________________xlnm.Print_Area_46: #REF!
Name ___________________________xlnm.Print_Titles_28: #REF!
Name ___________________________xlnm.Print_Titles_7: #REF!
Name __________________________hr4: #REF!
Name __________________________PG1: #REF!
Name __________________________PG10: #REF!
Name __________________________PG11: #REF!
Name __________________________PG12: #REF!
Name __________________________PG13: '[4]Strt Archi'!#REF!
Name __________________________PG2: #REF!
Name __________________________PG3: #REF!
Name __________________________PG4: #REF!
Name __________________________PG5: #REF!
Name __________________________PG6: #REF!
Name __________________________PG7: #REF!
Name __________________________PG8: #REF!
Name __________________________rh1234: #REF!
Name __________________________sp2: #REF!
Name __________________________xlnm.Print_Area_1: #REF!
Name __________________________xlnm.Print_Area_10: #REF!
Name __________________________xlnm.Print_Area_11: #REF!
Name __________________________xlnm.Print_Area_15: #REF!
Name __________________________xlnm.Print_Area_17: #REF!
Name __________________________xlnm.Print_Area_2: #REF!
Name __________________________xlnm.Print_Area_25: #REF!

Sheet Grupo Alfamed
A1: CONDIÇÃO COMERCIAL ALFAMED - DIMEBRAS
A2: VÁLIDA PARA COMPRA DIRETO DA RANBAXY | F2: VIGÊNCIA: | G2: 46057 | H2: ATÉ | I2: 46234
A3: Cód | B3: Produto/Apresentação | C3: EAN | D3: Produto Referência | E3: Caixa de Embarque | F3: Sellin | G3: OL | H3: DESCONTO FINAL ENTRADA | I3: DESC. FV DISTRIBUIDOR
A4: 931 | B4: ACECLOFENACO 100 MG C/ 12 COMP. REV. | C4: 7897076909312 | D4: PROFLAN | E4: 128 | F4: 0.78 | G4: 0.05 | H4: =F4+G4 -> 0.83 | I4: 0.75
A5: 934 | B5: ACECLOFENACO 100 MG C/ 24 COMP. REV. | C5: 7897076909343 | D5: PROFLAN | E5: 80 | F5: 0.75 | G5: 0.05 | H5: =F5+G5 -> 0.8 | I5: 0.72
A6: 740 | B6: ACICLOVIR 200 MG C/ 10 COMP. | C6: 7897076907400 | D6: ZOVIRAX | E6: 192 | F6: 0.75 | G6: 0.05 | H6: =F6+G6 -> 0.8 | I6: 0.72
A7: 741 | B7: ACICLOVIR 200 MG C/ 25 COMP. | C7: 7897076907417 | D7: ZOVIRAX | E7: 60 | F7: 0.8 | G7: 0.05 | H7: =F7+G7 -> 0.85 | I7: 0.77
A8: 2202 | B8: ACICLOVIR 200 MG C/ 30 COMP. | C8: 7897076922021 | D8: ZOVIRAX | E8: 240 | F8: 0.75 | G8: 0.05 | H8: =F8+G8 -> 0.8 | I8: 0.72
A9: 742 | B9: ACICLOVIR 400 MG C/ 10 COMP. | C9: 7897076907424 | D9: ZOVIRAX | E9: 192 | F9: 0.75 | G9: 0.05 | H9: =F9+G9 -> 0.8 | I9: 0.72
A10: 743 | B10: ACICLOVIR 400 MG C/ 25 COMP. | C10: 7897076907431 | D10: ZOVIRAX | E10: 60 | F10: 0.77 | G10: 0.05 | H10: =F10+G10 -> 0.82 | I10: 0.74
A11: 2182 | B11: ACICLOVIR 400 MG C/ 30 COMP. | C11: 7897076921826 | D11: ZOVIRAX | E11: 144 | F11: 0.8 | G11: 0.05 | H11: =F11+G11 -> 0.85 | I11: 0.77
A12: 1155 | B12: AMIODARONA, CLORIDRATO DE 100 MG C/ 20 COMP. | C12: 7897076911551 | D12: ATLANSIL | E12: 216 | F12: 0.27 | G12: 0.05 | H12: =F12+G12 -> 0.32 | I12: 0.24
A13: 1156 | B13: AMIODARONA, CLORIDRATO DE 100 MG C/ 30 COMP. | C13: 7897076911568 | D13: ATLANSIL | E13: 216 | F13: 0.31 | G13: 0.05 | H13: =F13+G13 -> 0.36 | I13: 0.28
A14: 1157 | B14: AMIODARONA, CLORIDRATO DE 200 MG C/ 20 COMP. | C14: 7897076911575 | D14: ATLANSIL | E14: 216 | F14: 0.3 | G14: 0.05 | H14: =F14+G14 -> 0.35 | I14: 0.27
A15: 1158 | B15: AMIODARONA, CLORIDRATO DE 200 MG C/ 30 COMP. | C15: 7897076911582 | D15: ATLANSIL | E15: 180 | F15: 0.49 | G15: 0.05 | H15: =F15+G15 -> 0.54 | I15: 0.46
... A28: 1114 | B28: AXETILCEFUROXIMA PÓ SUSP ORAL 250 MG/5ML C/ 70 ML | C28: 7897076911148 | D28: ZINNAT | E28: 30 | F28: 0.08 | G28: 0.05 | H28: =F28+G28 -> 0.13 | I28: 0.07
A29: 2300 | B29: BISOPROLOL, HEMIFUMARATO DE 10 MG C/ 30 COMP. REV. | C29: 7897076923004 | D29: CONCOR | E29: 55 | F29: 0.65 | H29: =F29+G29 -> 0.65 | I29: 0.63
A30: 2298 | B30: BISOPROLOL, HEMIFUMARATO DE 2,5 MG C/ 30 COMP. REV. | C30: 7897076922984 | D30: CONCOR | E30: 77 | F30: 0.69 | H30: =F30+G30 -> 0.69 | I30: 0.67
A31: 2299 | B31: BISOPROLOL, HEMIFUMARATO DE 5 MG C/ 30 COMP. REV. | C31: 7897076922991 | D31: CONCOR | E31: 55 | F31: 0.66 | H31: =F31+G31 -> 0.66 | I31: 0.64
A32: 2343 | B32: BUPROPIONA, CLORIDRATO DE 150 MG C/ 30 COMP | C32: 7897076923431 | D32: WELLBUTRIN XL | E32: 40 | F32: 0.78 | G32: 0.05 | H32: =F32+G32 -> 0.83 | I32: 0.77
A33: 2344 | B33: BUPROPIONA, CLORIDRATO DE 300 MG C/ 30 COMP | C33: 7897076923448 | D33: WELLBUTRIN XL | E33: 40 | F33: 0.53 | G33: 0.05 | H33: =F33+G33 -> 0.58 | I33: 0.5
A34: 2213 | B34: CABERGOLINA 0,5 MG C/ 2 COMP. | C34: 7897076922137 | D34: DOSTINEX | E34: 360 | F34: 0.65 | G34: 0.05 | H34: =F34+G34 -> 0.7 | I34: 0.65
A35: 2214 | B35: CABERGOLINA 0,5 MG C/ 8 COMP. | C35: 7897076922144 | D35: DOSTINEX | E35: 360 | F35: 0.65 | G35: 0.05 | H35: =F35+G35 -> 0.7 | I35: 0.65
A36: 790 | B36: CEFALEXINA 500MG C/8 COMP REV | C36: 7897076907905 | D36: KEPLEX ® - BAGÓ | E36: 192 | F36: 0.7 | H36: =F36+G36 -> 0.7 | I36: 0.68
A37: 791 | B37: CEFALEXINA 500MG C/10 COMP REV | C37: 7897076907912 | D37: KEPLEX ® - BAGÓ | E37: 160 | F37: 0.7 | H37: =F37+G37 -> 0.7 | I37: 0.68
A38: 2224 | B38: CELECOXIBE 200 MG C/ 10 CAP. DURA | C38: 7897076922243 | D38: CELEBRA | E38: 336 | F38: 0.8 | G38: 0.05 | H38: =F38+G38 -> 0.85 | I38: 0.77
A39: 2225 | B39: CELECOXIBE 200 MG C/ 15 CAP. DURA | C39: 7897076922250 | D39: CELEBRA | E39: 144 | F39: 0.77 | G39: 0.05 | H39: =F39+G39 -> 0.82 | I39: 0.77
A40: 1090 | B40: CINARIZINA 25 MG C/ 30 COMP. | C40: 7897076910905 | D40: STUGERON | E40: 144 | F40: 0.32 | G40: 0.05 | H40: =F40+G40 -> 0.37 | I40: 0.3
A41: 1092 | B41: CINARIZINA 75 MG C/ 30 COMP. | C41: 7897076910929 | D41: STUGERON | E41: 144 | F41: 0.26 | G41: 0.05 | H41: =F41+G41 -> 0.31 | I41: 0.24
A42: 1270 | B42: CITALOPRAM, BROMIDRATO DE 20 MG C/ 30 COMP. REV. | C42: 7897076912701 | D42: CIPRAMIL | E42: 288 | F42: 0.84 | H42: =F42+G42 -> 0.84 | I42: 0.82
A43: 1233 | B43: CLOPIDOGREL, BISSULFATO DE 75 MG C/ 28 COMP. REV. | C43: 7897076912336 | D43: PLAVIX | E43: 168 | F43: 0.78 | G43: 0.05 | H43: =F43+G43 -> 0.83 | I43: 0.75
A44: 1234 | B44: CLOPIDOGREL, BISSULFATO DE 75 MG C/ 30 COMP. REV. | C44: 7897076912343 | D44: PLAVIX | E44: 180 | F44: 0.78 | G44: 0.05 | H44: =F44+G44 -> 0.83 | I44: 0.75
A45: 2363 | B45: CLORID. DE DORZOLAMIDA + MAL. TIMOLOL 20 + 5 MG/ML SOL OFT | C45: 7897076923639 | D45: COSOPT | E45: 420 | F45: 0.35 | G45: 0.05 | H45: =F45+G45 -> 0.4 | I45: 0.32
A46: 2187 | B46: DIVALPROATO DE SÓDIO 250 MG C/ 30 COMP. REV. LIB. PROL. | C46: 7897076921871 | D46: DEPAKOTE | E46: 108 | F46: 0.45 | G46: 0.05 | H46: =F46+G46 -> 0.5 | I46: 0.42
A47: 2190 | B47: DIVALPROATO DE SÓDIO 500 MG C/ 30 COMP. REV. LIB. PROL. | C47: 7897076921901 | D47: DEPAKOTE | E47: 72 | F47: 0.45 | G47: 0.05 | H47: =F47+G47 -> 0.5 | I47: 0.42
A48: 2329 | B48: DIVALPROATO DE SÓDIO 500 MG C/ 60 COMP. REV. LIB. PROL. | C48: 7897076923295 | D48: DEPAKOTE | E48: 48 | F48: 0.55 | G48: 0.05 | H48: =F48+G48 -> 0.6 | I48: 0.52
A49: 1218 | B49: DOMPERIDONA 10 MG C/ 30 COMP. | C49: 7897076912183 | D49: MOTILIUM | E49: 144 | F49: 0.75 | G49: 0.05 | H49: =F49+G49 -> 0.8 | I49: 0.72
A50: 1219 | B50: DOMPERIDONA 10 MG C/ 60 COMP. | C50: 7897076912190 | D50: MOTILIUM | E50: 120 | F50: 0.75 | G50: 0.05 | H50: =F50+G50 -> 0.8 | I50: 0.72
A51: 1206 | B51: DONEPEZILA, CLORIDRATO DE 10 MG C/ 30 COMP. REV. | C51: 7897076912060 | D51: ERANZ | E51: 288 | F51: 0.85 | H51: =F51+G51 -> 0.85 | I51: 0.83
A52: 1142 | B52: DONEPEZILA, CLORIDRATO DE 5 MG C/ 30 COMP. REV. | C52: 7897076911421 | D52: ERANZ | E52: 192 | F52: 0.82 | H52: =F52+G52 -> 0.82 | I52: 0.8
...

Sheet SC
B1: RANBAXY FARMACÊUTICA LTDA
B2: a SUN PHARMA company
B3: AV. EUGÊNIO BORGES, 1.060 - ARSENAL - SG - RJ
B4: C.N.P.J 73.663.650/0001-90 INSC. EST. 85.396.757
B6: CONDIÇÃO COMERCIAL Fevereiro/26
B8: Cód | C8: Produto/Apresentação | D8: EAN | E8: Pis-Cofins | F8: Caixa de Embarque | G8: PF - 12% | H8: DESCONTO COMPRA | I8: SPREAD | J8: Desc Final | K8: Repasse | L8: Vlr Liquido
B9: 931 | C9: ACECLOFENACO 100 MG C/ 12 COMP. REV. | D9: 7897076909312 | E9: Positivo | F9: 128 | G9: =VLOOKUP(B9,tABELA!C:BO,62,0) -> 35.186138 | H9: =VLOOKUP(B9,'Grupo Alfamed'!A:I,6,0) -> 0.78 | I9: 0.05 | J9: =H9+I9 -> 0.83 | K9: 0.0833 | L9: =(G9-G9*J9)*(1-K9) -> 5.4833725
B10: 934 | C10: ACECLOFENACO 100 MG C/ 24 COMP. REV. | D10: 7897076909343 | E10: Positivo | F10: 80 | G10: =VLOOKUP(B10,tABELA!C:BO,62,0) -> 65.853177 | H10: =VLOOKUP(B10,'Grupo Alfamed'!A:I,6,0) -> 0.75 | I10: 0.05 | J10: =H10+I10 -> 0.8 | K10: 0.0833 | L10: =(G10-G10*J10)*(1-K10) -> 12.073521
B11: 740 | C11: ACICLOVIR 200 MG C/ 10 COMP. | D11: 7897076907400 | E11: Positivo | F11: 192 | G11: =VLOOKUP(B11,tABELA!C:BO,62,0) -> 40.418143 | H11: =VLOOKUP(B11,'Grupo Alfamed'!A:I,6,0) -> 0.75 | I11: 0.05 | J11: =H11+I11 -> 0.8 | K11: 0.0833 | L11: =(G11-G11*J11)*(1-K11) -> 7.4102622
B12: 741 | C12: ACICLOVIR 200 MG C/ 25 COMP. | D12: 7897076907417 | E12: Positivo | F12: 60 | G12: =VLOOKUP(B12,tABELA!C:BO,62,0) -> 84.340399 | H12: =VLOOKUP(B12,'Grupo Alfamed'!A:I,6,0) -> 0.8 | I12: 0.05 | J12: =H12+I12 -> 0.85 | K12: 0.0833 | L12: =(G12-G12*J12)*(1-K12) -> 11.597227
B13: 2202 | C13: ACICLOVIR 200 MG C/ 30 COMP. | D13: 7897076922021 | E13: Positivo | F13: 240 | G13: =VLOOKUP(B13,tABELA!C:BO,62,0) -> 111.27374 | H13: =VLOOKUP(B13,'Grupo Alfamed'!A:I,6,0) -> 0.75 | I13: 0.05 | J13: =H13+I13 -> 0.8 | K13: 0.0833 | L13: =(G13-G13*J13)*(1-K13) -> 20.400928
B14: 742 | C14: ACICLOVIR 400 MG C/ 10 COMP. | D14: 7897076907424 | E14: Positivo | F14: 192 | G14: =VLOOKUP(B14,tABELA!C:BO,62,0) -> 80.945033 | H14: =VLOOKUP(B14,'Grupo Alfamed'!A:I,6,0) -> 0.75 | I14: 0.05 | J14: =H14+I14 -> 0.8 | K14: 0.0833 | L14: =(G14-G14*J14)*(1-K14) -> 14.840462
B15: 743 | C15: ACICLOVIR 400 MG C/ 25 COMP. | D15: 7897076907431 | E15: Positivo | F15: 60 | G15: =VLOOKUP(B15,tABELA!C:BO,62,0) -> 168.6808 | H15: =VLOOKUP(B15,'Grupo Alfamed'!A:I,6,0) -> 0.77 | I15: 0.05 | J15: =H15+I15 -> 0.82 | K15: 0.0833 | L15: =(G15-G15*J15)*(1-K15) -> 27.833344
B16: 2182 | C16: ACICLOVIR 400 MG C/ 30 COMP. | D16: 7897076921826 | E16: Positivo | F16: 144 | G16: =VLOOKUP(B16,tABELA!C:BO,62,0) -> 222.71665 | H16: =VLOOKUP(B16,'Grupo Alfamed'!A:I,6,0) -> 0.8 | I16: 0.05 | J16: =H16+I16 -> 0.85 | K16: 0.0833 | L16: =(G16-G16*J16)*(1-K16) -> 30.624653
B17: 1155 | C17: AMIODARONA, CLORIDRATO DE 100 MG C/ 20 COMP. | D17: 7897076911551 | E17: Positivo | F17: 216 | G17: =VLOOKUP(B17,tABELA!C:BO,62,0) -> 11.330821 | H17: =VLOOKUP(B17,'Grupo Alfamed'!A:I,6,0) -> 0.27 | I17: 0.05 | J17: =H17+I17 -> 0.32 | K17: 0.0833 | L17: =(G17-G17*J17)*(1-K17) -> 7.0631353
B18: 1156 | C18: AMIODARONA, CLORIDRATO DE 100 MG C/ 30 COMP. | D18: 7897076911568 | E18: Positivo | F18: 216 | G18: =VLOOKUP(B18,tABELA!C:BO,62,0) -> 17.008159 | H18: =VLOOKUP(B18,'Grupo Alfamed'!A:I,6,0) -> 0.31 | I18: 0.05 | J18: =H18+I18 -> 0.36 | K18: 0.0833 | L18: =(G18-G18*J18)*(1-K18) -> 9.9784826
B19: 1157 | C19: AMIODARONA, CLORIDRATO DE 200 MG C/ 20 COMP. | D19: 7897076911575 | E19: Positivo | F19: 216 | G19: =VLOOKUP(B19,tABELA!C:BO,62,0) -> 22.709351 | H19: =VLOOKUP(B19,'Grupo Alfamed'!A:I,6,0) -> 0.3 | I19: 0.05 | J19: =H19+I19 -> 0.35 | K19: 0.0833 | L19: =(G19-G19*J19)*(1-K19) -> 13.53148
B20: 1158 | C20: AMIODARONA, CLORIDRATO DE 200 MG C/ 30 COMP. | D20: 7897076911582 | E20: Positivo | F20: 180 | G20: =VLOOKUP(B20,tABELA!C:BO,62,0) -> 34.064026 | H20: =VLOOKUP(B20,'Grupo Alfamed'!A:I,6,0) -> 0.49 | I20: 0.05 | J20: =H20+I20 -> 0.54 | K20: 0.0833 | L20: =(G20-G20*J20)*(1-K20) -> 14.364187
... B33: 1114 | C33: AXETILCEFUROXIMA PÓ SUSP ORAL 250 MG/5ML C/ 70 ML | D33: 7897076911148 | E33: Positivo | F33: 30 | G33: =VLOOKUP(B33,tABELA!C:BO,62,0) -> 111.28059 | H33: =VLOOKUP(B33,'Grupo Alfamed'!A:I,6,0) -> 0.08 | I33: 0.05 | J33: =H33+I33 -> 0.13 | K33: 0.0833 | L33: =(G33-G33*J33)*(1-K33) -> 88.749497
A34: * | B34: 2300 | C34: BISOPROLOL, HEMIFUMARATO DE 10 MG C/ 30 COMP. REV. | D34: 7897076923004 | E34: Positivo | F34: 55 | G34: =VLOOKUP(B34,tABELA!C:BO,62,0) -> 57.358721 | H34: =VLOOKUP(B34,'Grupo Alfamed'!A:I,6,0) -> 0.65 | I34: 0.05 | J34: =H34+I34 -> 0.7 | K34: 0.0833 | L34: =(G34-G34*J34)*(1-K34) -> 15.774222
A35: * | B35: 2298 | C35: BISOPROLOL, HEMIFUMARATO DE 2,5 MG C/ 30 COMP. REV. | D35: 7897076922984 | E35: Positivo | F35: 77 | G35: =VLOOKUP(B35,tABELA!C:BO,62,0) -> 41.372712 | H35: =VLOOKUP(B35,'Grupo Alfamed'!A:I,6,0) -> 0.69 | I35: 0.05 | J35: =H35+I35 -> 0.74 | K35: 0.0833 | L35: =(G35-G35*J35)*(1-K35) -> 9.8608548
A36: * | B36: 2299 | C36: BISOPROLOL, HEMIFUMARATO DE 5 MG C/ 30 COMP. REV. | D36: 7897076922991 | E36: Positivo | F36: 55 | G36: =VLOOKUP(B36,tABELA!C:BO,62,0) -> 50.326327 | H36: =VLOOKUP(B36,'Grupo Alfamed'!A:I,6,0) -> 0.66 | I36: 0.05 | J36: =H36+I36 -> 0.71 | K36: 0.0833 | L36: =(G36-G36*J36)*(1-K36) -> 13.378902
B37: 2343 | C37: BUPROPIONA, CLORIDRATO DE 150 MG C/ 30 COMP | D37: 7897076923431 | E37: Positivo | F37: 40 | G37: =VLOOKUP(B37,tABELA!C:BO,62,0) -> 124.66188 | H37: =VLOOKUP(B37,'Grupo Alfamed'!A:I,6,0) -> 0.78 | I37: 0.05 | J37: =H37+I37 -> 0.83 | K37: 0.0833 | L37: =(G37-G37*J37)*(1-K37) -> 19.427182
B38: 2344 | C38: BUPROPIONA, CLORIDRATO DE 300 MG C/ 30 COMP | D38: 7897076923448 | E38: Positivo | F38: 40 | G38: =VLOOKUP(B38,tABELA!C:BO,62,0) -> 140.52705 | H38: =VLOOKUP(B38,'Grupo Alfamed'!A:I,6,0) -> 0.53 | I38: 0.05 | J38: =H38+I38 -> 0.58 | K38: 0.0833 | L38: =(G38-G38*J38)*(1-K38) -> 54.104883
B39: 2213 | C39: CABERGOLINA 0,5 MG C/ 2 COMP. | D39: 7897076922137 | E39: Positivo | F39: 360 | G39: =VLOOKUP(B39,tABELA!C:BO,62,0) -> 69.475824 | H39: =VLOOKUP(B39,'Grupo Alfamed'!A:I,6,0) -> 0.65 | I39: 0.05 | J39: =H39+I39 -> 0.7 | K39: 0.0833 | L39: =(G39-G39*J39)*(1-K39) -> 19.106546
B40: 2214 | C40: CABERGOLINA 0,5 MG C/ 8 COMP. | D40: 7897076922144 | E40: Positivo | F40: 360 | G40: =VLOOKUP(B40,tABELA!C:BO,62,0) -> 240.38039 | H40: =VLOOKUP(B40,'Grupo Alfamed'!A:I,6,0) -> 0.65 | I40: 0.05 | J40: =H40+I40 -> 0.7 | K40: 0.0833 | L40: =(G40-G40*J40)*(1-K40) -> 66.10701
A41: * | B41: 791 | C41: CEFALEXINA 500MG C/10 COMP REV | D41: 7897076907912 | E41: Positivo | F41: 160 | G41: =VLOOKUP(B41,tABELA!C:BO,62,0) -> 22.971749 | H41: =VLOOKUP(B41,'Grupo Alfamed'!A:I,6,0) -> 0.7 | I41: 0.05 | J41: =H41+I41 -> 0.75 | K41: 0.0833 | L41: =(G41-G41*J41)*(1-K41) -> 5.2645505
A42: * | B42: 790 | C42: CEFALEXINA 500MG C/8 COMP REV | D42: 7897076907905 | E42: Positivo | F42: 192 | G42: =VLOOKUP(B42,tABELA!C:BO,62,0) -> 18.379784 | H42: =VLOOKUP(B42,'Grupo Alfamed'!A:I,6,0) -> 0.7 | I42: 0.05 | J42: =H42+I42 -> 0.75 | K42: 0.0833 | L42: =(G42-G42*J42)*(1-K42) -> 4.2121871
B43: 2224 | C43: CELECOXIBE 200 MG C/ 10 CAP. DURA | D43: 7897076922243 | E43: Positivo | F43: 336 | G43: =VLOOKUP(B43,tABELA!C:BO,62,0) -> 37.64218 | H43: =VLOOKUP(B43,'Grupo Alfamed'!A:I,6,0) -> 0.8 | I43: 0.05 | J43: =H43+I43 -> 0.85 | K43: 0.0833 | L43: =(G43-G43*J43)*(1-K43) -> 5.175988
B44: 2225 | C44: CELECOXIBE 200 MG C/ 15 CAP. DURA | D44: 7897076922250 | E44: Positivo | F44: 144 | G44: =VLOOKUP(B44,tABELA!C:BO,62,0) -> 55.735712 | H44: =VLOOKUP(B44,'Grupo Alfamed'!A:I,6,0) -> 0.77 | I44: 0.05 | J44: =H44+I44 -> 0.82 | K44: 0.0833 | L44: =(G44-G44*J44)*(1-K44) -> 9.1967269
B45: 1090 | C45: CINARIZINA 25 MG C/ 30 COMP. | D45: 7897076910905 | E45: Positivo | F45: 144 | G45: =VLOOKUP(B45,tABELA!C:BO,62,0) -> 12.489252 | H45: =VLOOKUP(B45,'Grupo Alfamed'!A:I,6,0) -> 0.32 | I45: 0.05 | J45: =H45+I45 -> 0.37 | K45: 0.0833 | L45: =(G45-G45*J45)*(1-K45) -> 7.2128053
B46: 1092 | C46: CINARIZINA 75 MG C/ 30 COMP. | D46: 7897076910929 | E46: Positivo | F46: 144 | G46: =VLOOKUP(B46,tABELA!C:BO,62,0) -> 17.503787 | H46: =VLOOKUP(B46,'Grupo Alfamed'!A:I,6,0) -> 0.26 | I46: 0.05 | J46: =H46+I46 -> 0.31 | K46: 0.0833 | L46: =(G46-G46*J46)*(1-K46) -> 11.071548
A47: * | B47: 1270 | C47: CITALOPRAM, BROMIDRATO DE 20 MG C/ 30 COMP. REV. | D47: 7897076912701 | E47: Positivo | F47: 288 | G47: =VLOOKUP(B47,tABELA!C:BO,62,0) -> 45.4689 | H47: =VLOOKUP(B47,'Grupo Alfamed'!A:I,6,0) -> 0.84 | I47: 0.05 | J47: =H47+I47 -> 0.89 | K47: 0.0833 | L47: =(G47-G47*J47)*(1-K47) -> 4.5849475
B48: 1233 | C48: CLOPIDOGREL, BISSULFATO DE 75 MG C/ 28 COMP. REV. | D48: 7897076912336 | E48: Positivo | F48: 168 | G48: =VLOOKUP(B48,tABELA!C:BO,62,0) -> 63.303632 | H48: =VLOOKUP(B48,'Grupo Alfamed'!A:I,6,0) -> 0.78 | I48: 0.05 | J48: =H48+I48 -> 0.83 | K48: 0.0833 | L48: =(G48-G48*J48)*(1-K48) -> 9.8651747
B49: 1234 | C49: CLOPIDOGREL, BISSULFATO DE 75 MG C/ 30 COMP. REV. | D49: 7897076912343 | E49: Positivo | F49: 180 | G49: =VLOOKUP(B49,tABELA!C:BO,62,0) -> 56.887478 | H49: =VLOOKUP(B49,'Grupo Alfamed'!A:I,6,0) -> 0.78 | I49: 0.05 | J49: =H49+I49 -> 0.83 | K49: 0.0833 | L49: =(G49-G49*J49)*(1-K49) -> 8.8652877
B50: 2363 | C50: CLORID. DE DORZOLAMIDA + MAL. TIMOLOL 20 + 5 MG/ML SOL OFT | D50: 7897076923639 | E50: Positivo | F50: 420 | G50: =VLOOKUP(B50,tABELA!C:BO,62,0) -> 88.320768 | H50: =VLOOKUP(B50,'Grupo Alfamed'!A:I,6,0) -> 0.35 | I50: 0.05 | J50: =H50+I50 -> 0.4 | K50: 0.0833 | L50: =(G50-G50*J50)*(1-K50) -> 48.578189
B51: 2187 | C51: DIVALPROATO DE SÓDIO 250 MG C/ 30 COMP. REV. LIB. PROL. | D51: 7897076921871 | E51: Positivo | F51: 72 | G51: =VLOOKUP(B51,tABELA!C:BO,62,0) -> 36.80528 | H51: =VLOOKUP(B51,'Grupo Alfamed'!A:I,6,0) -> 0.45 | I51: 0.05 | J51: =H51+I51 -> 0.5 | K51: 0.0833 | L51: =(G51-G51*J51)*(1-K51) -> 16.8697
B52: 2190 | C52: DIVALPROATO DE SÓDIO 500 MG C/ 30 COMP. REV. LIB. PROL. | D52: 7897076921901 | E52: Positivo | F52: 72 | G52: =VLOOKUP(B52,tABELA!C:BO,62,0) -> 73.731392 | H52: =VLOOKUP(B52,'Grupo Alfamed'!A:I,6,0) -> 0.45 | I52: 0.05 | J52: =H52+I52 -> 0.5 | K52: 0.0833 | L52: =(G52-G52*J52)*(1-K52) -> 33.794783
B53: 2329 | C53: DIVALPROATO DE SÓDIO 500 MG C/ 60 COMP. REV. LIB. PROL. | D53: 7897076923295 | E53: Positivo | F53: 48 | G53: =VLOOKUP(B53,tABELA!C:BO,62,0) -> 147.08821 | H53: =VLOOKUP(B53,'Grupo Alfamed'!A:I,6,0) -> 0.55 | I53: 0.05 | J53: =H53+I53 -> 0.6 | K53: 0.0833 | L53: =(G53-G53*J53)*(1-K53) -> 53.934303
B54: 1218 | C54: DOMPERIDONA 10 MG C/ 30 COMP. | D54: 7897076912183 | E54: Negativo | F54: 144 | G54: =VLOOKUP(B54,tABELA!C:BO,62,0) -> 15.44 | H54: =VLOOKUP(B54,'Grupo Alfamed'!A:I,6,0) -> 0.75 | I54: 0.05 | J54: =H54+I54 -> 0.8 | K54: 0 | L54: =(G54-G54*J54)*(1-K54) -> 3.088
...

Sheet PR
B1: RANBAXY FARMACÊUTICA LTDA
B2: a SUN PHARMA company
B3: AV. EUGÊNIO BORGES, 1.060 - ARSENAL - SG - RJ
B4: C.N.P.J 73.663.650/0001-90 INSC. EST. 85.396.757
B6: CONDIÇÃO COMERCIAL Fevereiro/26
B8: Cód | C8: Produto/Apresentação | D8: EAN | E8: Pis-Cofins | F8: Caixa de Embarque | G8: PF - 19,5% | H8: DESCONTO COMPRA | I8: SPREAD | J8: Desc Final | K8: Repasse | L8: Vlr Liquido
B9: 931 | C9: ACECLOFENACO 100 MG C/ 12 COMP. REV. | D9: 7897076909312 | E9: Positivo | F9: 128 | G9: =VLOOKUP(B9,tABELA!C:BO,46,0) -> 38.46434 | H9: =SC!H9 -> 0.78 | I9: 0.05 | J9: =H9+I9 -> 0.83 | K9: 0.1615 | L9: =(G9-G9*J9)*(1-K9) -> 5.4828993
B10: 934 | C10: ACECLOFENACO 100 MG C/ 24 COMP. REV. | D10: 7897076909343 | E10: Positivo | F10: 80 | G10: =VLOOKUP(B10,tABELA!C:BO,46,0) -> 71.988548 | H10: =SC!H10 -> 0.75 | I10: 0.05 | J10: =H10+I10 -> 0.8 | K10: 0.1615 | L10: =(G10-G10*J10)*(1-K10) -> 12.072479
B11: 740 | C11: ACICLOVIR 200 MG C/ 10 COMP. | D11: 7897076907400 | E11: Positivo | F11: 192 | G11: =VLOOKUP(B11,tABELA!C:BO,46,0) -> 44.183797 | H11: =SC!H11 -> 0.75 | I11: 0.05 | J11: =H11+I11 -> 0.8 | K11: 0.1615 | L11: =(G11-G11*J11)*(1-K11) -> 7.4096227
B12: 741 | C12: ACICLOVIR 200 MG C/ 25 COMP. | D12: 7897076907417 | E12: Positivo | F12: 60 | G12: =VLOOKUP(B12,tABELA!C:BO,46,0) -> 92.198177 | H12: =SC!H12 -> 0.8 | I12: 0.05 | J12: =H12+I12 -> 0.85 | K12: 0.1615 | L12: =(G12-G12*J12)*(1-K12) -> 11.596226
B13: 2202 | C13: ACICLOVIR 200 MG C/ 30 COMP. | D13: 7897076922021 | E13: Positivo | F13: 240 | G13: =VLOOKUP(B13,tABELA!C:BO,46,0) -> 121.64083 | H13: =SC!H13 -> 0.75 | I13: 0.05 | J13: =H13+I13 -> 0.8 | K13: 0.1615 | L13: =(G13-G13*J13)*(1-K13) -> 20.399168
B14: 742 | C14: ACICLOVIR 400 MG C/ 10 COMP. | D14: 7897076907424 | E14: Positivo | F14: 192 | G14: =VLOOKUP(B14,tABELA!C:BO,46,0) -> 88.486473 | H14: =SC!H14 -> 0.75 | I14: 0.05 | J14: =H14+I14 -> 0.8 | K14: 0.1615 | L14: =(G14-G14*J14)*(1-K14) -> 14.839182
B15: 743 | C15: ACICLOVIR 400 MG C/ 25 COMP. | D15: 7897076907431 | E15: Positivo | F15: 60 | G15: =VLOOKUP(B15,tABELA!C:BO,46,0) -> 184.39635 | H15: =SC!H15 -> 0.77 | I15: 0.05 | J15: =H15+I15 -> 0.82 | K15: 0.1615 | L15: =(G15-G15*J15)*(1-K15) -> 27.830942
B16: 2182 | C16: ACICLOVIR 400 MG C/ 30 COMP. | D16: 7897076921826 | E16: Positivo | F16: 144 | G16: =VLOOKUP(B16,tABELA!C:BO,46,0) -> 243.46659 | H16: =SC!H16 -> 0.8 | I16: 0.05 | J16: =H16+I16 -> 0.85 | K16: 0.1615 | L16: =(G16-G16*J16)*(1-K16) -> 30.62201
B17: 1155 | C17: AMIODARONA, CLORIDRATO DE 100 MG C/ 20 COMP. | D17: 7897076911551 | E17: Positivo | F17: 216 | G17: =VLOOKUP(B17,tABELA!C:BO,46,0) -> 12.386484 | H17: =SC!H17 -> 0.27 | I17: 0.05 | J17: =H17+I17 -> 0.32 | K17: 0.1615 | L17: =(G17-G17*J17)*(1-K17) -> 7.0625257
B18: 1156 | C18: AMIODARONA, CLORIDRATO DE 100 MG C/ 30 COMP. | D18: 7897076911568 | E18: Positivo | F18: 216 | G18: =VLOOKUP(B18,tABELA!C:BO,46,0) -> 18.592765 | H18: =SC!H18 -> 0.31 | I18: 0.05 | J18: =H18+I18 -> 0.36 | K18: 0.1615 | L18: =(G18-G18*J18)*(1-K18) -> 9.9776214
B19: 1157 | C19: AMIODARONA, CLORIDRATO DE 200 MG C/ 20 COMP. | D19: 7897076911575 | E19: Positivo | F19: 216 | G19: =VLOOKUP(B19,tABELA!C:BO,46,0) -> 24.825122 | H19: =SC!H19 -> 0.3 | I19: 0.05 | J19: =H19+I19 -> 0.35 | K19: 0.1615 | L19: =(G19-G19*J19)*(1-K19) -> 13.530312
B20: 1158 | C20: AMIODARONA, CLORIDRATO DE 200 MG C/ 30 COMP. | D20: 7897076911582 | E20: Positivo | F20: 180 | G20: =VLOOKUP(B20,tABELA!C:BO,46,0) -> 37.237684 | H20: =SC!H20 -> 0.49 | I20: 0.05 | J20: =H20+I20 -> 0.54 | K20: 0.1615 | L20: =(G20-G20*J20)*(1-K20) -> 14.362947
... B33: 1114 | C33: AXETILCEFUROXIMA PÓ SUSP ORAL 250 MG/5ML C/ 70 ML | D33: 7897076911148 | E33: Positivo | F33: 30 | G33: =VLOOKUP(B33,tABELA!C:BO,46,0) -> 121.64832 | H33: =SC!H33 -> 0.08 | I33: 0.05 | J33: =H33+I33 -> 0.13 | K33: 0.1615 | L33: =(G33-G33*J33)*(1-K33) -> 88.741838
A34: * | B34: 2300 | C34: BISOPROLOL, HEMIFUMARATO DE 10 MG C/ 30 COMP. REV. | D34: 7897076923004 | E34: Positivo | F34: 55 | G34: =VLOOKUP(B34,tABELA!C:BO,46,0) -> 62.702685 | H34: =SC!H34 -> 0.65 | I34: 0.05 | J34: =H34+I34 -> 0.7 | K34: 0.1615 | L34: =(G34-G34*J34)*(1-K34) -> 15.772861
A35: * | B35: 2298 | C35: BISOPROLOL, HEMIFUMARATO DE 2,5 MG C/ 30 COMP. REV. | D35: 7897076922984 | E35: Positivo | F35: 77 | G35: =VLOOKUP(B35,tABELA!C:BO,46,0) -> 45.2273 | H35: =SC!H35 -> 0.69 | I35: 0.05 | J35: =H35+I35 -> 0.74 | K35: 0.1615 | L35: =(G35-G35*J35)*(1-K35) -> 9.8600037
A36: * | B36: 2299 | C36: BISOPROLOL, HEMIFUMARATO DE 5 MG C/ 30 COMP. REV. | D36: 7897076922991 | E36: Positivo | F36: 55 | G36: =VLOOKUP(B36,tABELA!C:BO,46,0) -> 55.015101 | H36: =SC!H36 -> 0.66 | I36: 0.05 | J36: =H36+I36 -> 0.71 | K36: 0.1615 | L36: =(G36-G36*J36)*(1-K36) -> 13.377747
B37: 2343 | C37: BUPROPIONA, CLORIDRATO DE 150 MG C/ 30 COMP | D37: 7897076923431 | E37: Positivo | F37: 40 | G37: =VLOOKUP(B37,tABELA!C:BO,46,0) -> 136.2763 | H37: =SC!H37 -> 0.78 | I37: 0.05 | J37: =H37+I37 -> 0.83 | K37: 0.1615 | L37: =(G37-G37*J37)*(1-K37) -> 19.425505
B38: 2344 | C38: BUPROPIONA, CLORIDRATO DE 300 MG C/ 30 COMP | D38: 7897076923448 | E38: Positivo | F38: 40 | G38: =VLOOKUP(B38,tABELA!C:BO,46,0) -> 153.6196 | H38: =SC!H38 -> 0.53 | I38: 0.05 | J38: =H38+I38 -> 0.58 | K38: 0.1615 | L38: =(G38-G38*J38)*(1-K38) -> 54.100214
B39: 2213 | C39: CABERGOLINA 0,5 MG C/ 2 COMP. | D39: 7897076922137 | E39: Positivo | F39: 360 | G39: =VLOOKUP(B39,tABELA!C:BO,46,0) -> 75.948707 | H39: =SC!H39 -> 0.65 | I39: 0.05 | J39: =H39+I39 -> 0.7 | K39: 0.1615 | L39: =(G39-G39*J39)*(1-K39) -> 19.104897
B40: 2214 | C40: CABERGOLINA 0,5 MG C/ 8 COMP. | D40: 7897076922144 | E40: Positivo | F40: 360 | G40: =VLOOKUP(B40,tABELA!C:BO,46,0) -> 262.77601 | H40: =SC!H40 -> 0.65 | I40: 0.05 | J40: =H40+I40 -> 0.7 | K40: 0.1615 | L40: =(G40-G40*J40)*(1-K40) -> 66.101304
A41: * | B41: 791 | C41: CEFALEXINA 500MG C/10 COMP REV | D41: 7897076907912 | E41: Positivo | F41: 160 | G41: =VLOOKUP(B41,tABELA!C:BO,46,0) -> 25.111967 | H41: =SC!H41 -> 0.7 | I41: 0.05 | J41: =H41+I41 -> 0.75 | K41: 0.1615 | L41: =(G41-G41*J41)*(1-K41) -> 5.2640961
A42: * | B42: 790 | C42: CEFALEXINA 500MG C/8 COMP REV | D42: 7897076907905 | E42: Positivo | F42: 192 | G42: =VLOOKUP(B42,tABELA!C:BO,46,0) -> 20.092182 | H42: =SC!H42 -> 0.7 | I42: 0.05 | J42: =H42+I42 -> 0.75 | K42: 0.1615 | L42: =(G42-G42*J42)*(1-K42) -> 4.2118235
B43: 2224 | C43: CELECOXIBE 200 MG C/ 10 CAP. DURA | D43: 7897076922243 | E43: Positivo | F43: 336 | G43: =VLOOKUP(B43,tABELA!C:BO,46,0) -> 41.149205 | H43: =SC!H43 -> 0.8 | I43: 0.05 | J43: =H43+I43 -> 0.85 | K43: 0.1615 | L43: =(G43-G43*J43)*(1-K43) -> 5.1755413
B44: 2225 | C44: CELECOXIBE 200 MG C/ 15 CAP. DURA | D44: 7897076922250 | E44: Positivo | F44: 144 | G44: =VLOOKUP(B44,tABELA!C:BO,46,0) -> 60.928465 | H44: =SC!H44 -> 0.77 | I44: 0.05 | J44: =H44+I44 -> 0.82 | K44: 0.1615 | L44: =(G44-G44*J44)*(1-K44) -> 9.1959332
B45: 1090 | C45: CINARIZINA 25 MG C/ 30 COMP. | D45: 7897076910905 | E45: Positivo | F45: 144 | G45: =VLOOKUP(B45,tABELA!C:BO,46,0) -> 13.652843 | H45: =SC!H45 -> 0.32 | I45: 0.05 | J45: =H45+I45 -> 0.37 | K45: 0.1615 | L45: =(G45-G45*J45)*(1-K45) -> 7.2121828
B46: 1092 | C46: CINARIZINA 75 MG C/ 30 COMP. | D46: 7897076910929 | E46: Positivo | F46: 144 | G46: =VLOOKUP(B46,tABELA!C:BO,46,0) -> 19.134569 | H46: =SC!H46 -> 0.26 | I46: 0.05 | J46: =H46+I46 -> 0.31 | K46: 0.1615 | L46: =(G46-G46*J46)*(1-K46) -> 11.070592
A47: * | B47: 1270 | C47: CITALOPRAM, BROMIDRATO DE 20 MG C/ 30 COMP. REV. | D47: 7897076912701 | E47: Positivo | F47: 288 | G47: =VLOOKUP(B47,tABELA!C:BO,46,0) -> 49.70512 | H47: =SC!H47 -> 0.84 | I47: 0.05 | J47: =H47+I47 -> 0.89 | K47: 0.1615 | L47: =(G47-G47*J47)*(1-K47) -> 4.5845518
B48: 1233 | C48: CLOPIDOGREL, BISSULFATO DE 75 MG C/ 28 COMP. REV. | D48: 7897076912336 | E48: Positivo | F48: 168 | G48: =VLOOKUP(B48,tABELA!C:BO,46,0) -> 69.201468 | H48: =SC!H48 -> 0.78 | I48: 0.05 | J48: =H48+I48 -> 0.83 | K48: 0.1615 | L48: =(G48-G48*J48)*(1-K48) -> 9.8643233
B49: 1234 | C49: CLOPIDOGREL, BISSULFATO DE 75 MG C/ 30 COMP. REV. | D49: 7897076912343 | E49: Positivo | F49: 180 | G49: =VLOOKUP(B49,tABELA!C:BO,46,0) -> 62.187538 | H49: =SC!H49 -> 0.78 | I49: 0.05 | J49: =H49+I49 -> 0.83 | K49: 0.1615 | L49: =(G49-G49*J49)*(1-K49) -> 8.8645226
B50: 2363 | C50: CLORID. DE DORZOLAMIDA + MAL. TIMOLOL 20 + 5 MG/ML SOL OFT | D50: 7897076923639 | E50: Positivo | F50: 420 | G50: =VLOOKUP(B50,tABELA!C:BO,46,0) -> 96.549386 | H50: =SC!H50 -> 0.35 | I50: 0.05 | J50: =H50+I50 -> 0.4 | K50: 0.1615 | L50: =(G50-G50*J50)*(1-K50) -> 48.573996
B51: 2187 | C51: DIVALPROATO DE SÓDIO 250 MG C/ 30 COMP. REV. LIB. PROL. | D51: 7897076921871 | E51: Positivo | F51: 72 | G51: =VLOOKUP(B51,tABELA!C:BO,46,0) -> 40.234333 | H51: =SC!H51 -> 0.45 | I51: 0.05 | J51: =H51+I51 -> 0.5 | K51: 0.1615 | L51: =(G51-G51*J51)*(1-K51) -> 16.868244
B52: 2190 | C52: DIVALPROATO DE SÓDIO 500 MG C/ 30 COMP. REV. LIB. PROL. | D52: 7897076921901 | E52: Positivo | F52: 72 | G52: =VLOOKUP(B52,tABELA!C:BO,46,0) -> 80.600755 | H52: =SC!H52 -> 0.45 | I52: 0.05 | J52: =H52+I52 -> 0.5 | K52: 0.1615 | L52: =(G52-G52*J52)*(1-K52) -> 33.791867
B53: 2329 | C53: DIVALPROATO DE SÓDIO 500 MG C/ 60 COMP. REV. LIB. PROL. | D53: 7897076923295 | E53: Positivo | F53: 48 | G53: =VLOOKUP(B53,tABELA!C:BO,46,0) -> 160.79203 | H53: =SC!H53 -> 0.55 | I53: 0.05 | J53: =H53+I53 -> 0.6 | K53: 0.1615 | L53: =(G53-G53*J53)*(1-K53) -> 53.929648
B54: 1218 | C54: DOMPERIDONA 10 MG C/ 30 COMP. | D54: 7897076912183 | E54: Negativo | F54: 144 | G54: =VLOOKUP(B54,tABELA!C:BO,46,0) -> 16.88 | H54: =SC!H54 -> 0.75 | I54: 0.05 | J54: =H54+I54 -> 0.8 | K54: 0.1344 | L54: =(G54-G54*J54)*(1-K54) -> 2.9222656
...

Sheet MT-MS
B1: RANBAXY FARMACÊUTICA LTDA
B2: a SUN PHARMA company
B3: AV. EUGÊNIO BORGES, 1.060 - ARSENAL - SG - RJ
B4: C.N.P.J 73.663.650/0001-90 INSC. EST. 85.396.757
B6: CONDIÇÃO COMERCIAL Fevereiro/26
B8: Cód | C8: Produto/Apresentação | D8: EAN | E8: Pis-Cofins | F8: Caixa de Embarque | G8: PF - 19,5% | H8: DESCONTO COMPRA | I8: SPREAD | J8: Desc Final | K8: Repasse | L8: Vlr Liquido
B9: 931 | C9: ACECLOFENACO 100 MG C/ 12 COMP. REV. | D9: 7897076909312 | E9: Positivo | F9: 128 | G9: =VLOOKUP(B9,tABELA!C:BO,58,0) -> 37.305781 | H9: =PR!H9 -> 0.78 | I9: 0.05 | J9: =H9+I9 -> 0.83 | K9: 0.1354 | L9: =(G9-G9*J9)*(1-K9) -> 5.4832784
B10: 934 | C10: ACECLOFENACO 100 MG C/ 24 COMP. REV. | D10: 7897076909343 | E10: Positivo | F10: 80 | G10: =VLOOKUP(B10,tABELA!C:BO,58,0) -> 69.82023 | H10: =PR!H10 -> 0.75 | I10: 0.05 | J10: =H10+I10 -> 0.8 | K10: 0.1354 | L10: =(G10-G10*J10)*(1-K10) -> 12.073314
B11: 740 | C11: ACICLOVIR 200 MG C/ 10 COMP. | D11: 7897076907400 | E11: Positivo | F11: 192 | G11: =VLOOKUP(B11,tABELA!C:BO,58,0) -> 42.852967 | H11: =PR!H11 -> 0.75 | I11: 0.05 | J11: =H11+I11 -> 0.8 | K11: 0.1354 | L11: =(G11-G11*J11)*(1-K11) -> 7.410135
B12: 741 | C12: ACICLOVIR 200 MG C/ 25 COMP. | D12: 7897076907417 | E12: Positivo | F12: 60 | G12: =VLOOKUP(B12,tABELA!C:BO,58,0) -> 89.421138 | H12: =PR!H12 -> 0.8 | I12: 0.05 | J12: =H12+I12 -> 0.85 | K12: 0.1354 | L12: =(G12-G12*J12)*(1-K12) -> 11.597027
B13: 2202 | C13: ACICLOVIR 200 MG C/ 30 COMP. | D13: 7897076922021 | E13: Positivo | F13: 240 | G13: =VLOOKUP(B13,tABELA!C:BO,58,0) -> 117.97697 | H13: =PR!H13 -> 0.75 | I13: 0.05 | J13: =H13+I13 -> 0.8 | K13: 0.1354 | L13: =(G13-G13*J13)*(1-K13) -> 20.400578
B14: 742 | C14: ACICLOVIR 400 MG C/ 10 COMP. | D14: 7897076907424 | E14: Positivo | F14: 192 | G14: =VLOOKUP(B14,tABELA!C:BO,58,0) -> 85.821233 | H14: =PR!H14 -> 0.75 | I14: 0.05 | J14: =H14+I14 -> 0.8 | K14: 0.1354 | L14: =(G14-G14*J14)*(1-K14) -> 14.840208
B15: 743 | C15: ACICLOVIR 400 MG C/ 25 COMP. | D15: 7897076907431 | E15: Positivo | F15: 60 | G15: =VLOOKUP(B15,tABELA!C:BO,58,0) -> 178.84228 | H15: =PR!H15 -> 0.77 | I15: 0.05 | J15: =H15+I15 -> 0.82 | K15: 0.1354 | L15: =(G15-G15*J15)*(1-K15) -> 27.832866
B16: 2182 | C16: ACICLOVIR 400 MG C/ 30 COMP. | D16: 7897076921826 | E16: Positivo | F16: 144 | G16: =VLOOKUP(B16,tABELA!C:BO,58,0) -> 236.1333 | H16: =PR!H16 -> 0.8 | I16: 0.05 | J16: =H16+I16 -> 0.85 | K16: 0.1354 | L16: =(G16-G16*J16)*(1-K16) -> 30.624127
B17: 1155 | C17: AMIODARONA, CLORIDRATO DE 100 MG C/ 20 COMP. | D17: 7897076911551 | E17: Positivo | F17: 216 | G17: =VLOOKUP(B17,tABELA!C:BO,58,0) -> 12.0134 | H17: =PR!H17 -> 0.27 | I17: 0.05 | J17: =H17+I17 -> 0.32 | K17: 0.1354 | L17: =(G17-G17*J17)*(1-K17) -> 7.063014
B18: 1156 | C18: AMIODARONA, CLORIDRATO DE 100 MG C/ 30 COMP. | D18: 7897076911568 | E18: Positivo | F18: 216 | G18: =VLOOKUP(B18,tABELA!C:BO,58,0) -> 18.032745 | H18: =PR!H18 -> 0.31 | I18: 0.05 | J18: =H18+I18 -> 0.36 | K18: 0.1354 | L18: =(G18-G18*J18)*(1-K18) -> 9.9783112
B19: 1157 | C19: AMIODARONA, CLORIDRATO DE 200 MG C/ 20 COMP. | D19: 7897076911575 | E19: Positivo | F19: 216 | G19: =VLOOKUP(B19,tABELA!C:BO,58,0) -> 24.077382 | H19: =PR!H19 -> 0.3 | I19: 0.05 | J19: =H19+I19 -> 0.35 | K19: 0.1354 | L19: =(G19-G19*J19)*(1-K19) -> 13.531248
B20: 1158 | C20: AMIODARONA, CLORIDRATO DE 200 MG C/ 30 COMP. | D20: 7897076911582 | E20: Positivo | F20: 180 | G20: =VLOOKUP(B20,tABELA!C:BO,58,0) -> 36.116073 | H20: =PR!H20 -> 0.49 | I20: 0.05 | J20: =H20+I20 -> 0.54 | K20: 0.1354 | L20: =(G20-G20*J20)*(1-K20) -> 14.36394
... B33: 1114 | C33: AXETILCEFUROXIMA PÓ SUSP ORAL 250 MG/5ML C/ 70 ML | D33: 7897076911148 | E33: Positivo | F33: 30 | G33: =VLOOKUP(B33,tABELA!C:BO,58,0) -> 117.98423 | H33: =PR!H33 -> 0.08 | I33: 0.05 | J33: =H33+I33 -> 0.13 | K33: 0.1354 | L33: =(G33-G33*J33)*(1-K33) -> 88.747973
A34: * | B34: 2300 | C34: BISOPROLOL, HEMIFUMARATO DE 10 MG C/ 30 COMP. REV. | D34: 7897076923004 | E34: Positivo | F34: 55 | G34: =VLOOKUP(B34,tABELA!C:BO,58,0) -> 60.81406 | H34: =PR!H34 -> 0.65 | I34: 0.05 | J34: =H34+I34 -> 0.7 | K34: 0.1354 | L34: =(G34-G34*J34)*(1-K34) -> 15.773951
A35: * | B35: 2298 | C35: BISOPROLOL, HEMIFUMARATO DE 2,5 MG C/ 30 COMP. REV. | D35: 7897076922984 | E35: Positivo | F35: 77 | G35: =VLOOKUP(B35,tABELA!C:BO,58,0) -> 43.86504 | H35: =PR!H35 -> 0.69 | I35: 0.05 | J35: =H35+I35 -> 0.74 | K35: 0.1354 | L35: =(G35-G35*J35)*(1-K35) -> 9.8606854
A36: * | B36: 2299 | C36: BISOPROLOL, HEMIFUMARATO DE 5 MG C/ 30 COMP. REV. | D36: 7897076922991 | E36: Positivo | F36: 55 | G36: =VLOOKUP(B36,tABELA!C:BO,58,0) -> 53.358029 | H36: =PR!H36 -> 0.66 | I36: 0.05 | J36: =H36+I36 -> 0.71 | K36: 0.1354 | L36: =(G36-G36*J36)*(1-K36) -> 13.378672
B37: 2343 | C37: BUPROPIONA, CLORIDRATO DE 150 MG C/ 30 COMP | D37: 7897076923431 | E37: Positivo | F37: 40 | G37: =VLOOKUP(B37,tABELA!C:BO,58,0) -> 132.17162 | H37: =PR!H37 -> 0.78 | I37: 0.05 | J37: =H37+I37 -> 0.83 | K37: 0.1354 | L37: =(G37-G37*J37)*(1-K37) -> 19.426848
B38: 2344 | C38: BUPROPIONA, CLORIDRATO DE 300 MG C/ 30 COMP | D38: 7897076923448 | E38: Positivo | F38: 40 | G38: =VLOOKUP(B38,tABELA!C:BO,58,0) -> 148.99253 | H38: =PR!H38 -> 0.53 | I38: 0.05 | J38: =H38+I38 -> 0.58 | K38: 0.1354 | L38: =(G38-G38*J38)*(1-K38) -> 54.103954
B39: 2213 | C39: CABERGOLINA 0,5 MG C/ 2 COMP. | D39: 7897076922137 | E39: Positivo | F39: 360 | G39: =VLOOKUP(B39,tABELA!C:BO,58,0) -> 73.661108 | H39: =PR!H39 -> 0.65 | I39: 0.05 | J39: =H39+I39 -> 0.7 | K39: 0.1354 | L39: =(G39-G39*J39)*(1-K39) -> 19.106218
B40: 2214 | C40: CABERGOLINA 0,5 MG C/ 8 COMP. | D40: 7897076922144 | E40: Positivo | F40: 360 | G40: =VLOOKUP(B40,tABELA!C:BO,58,0) -> 254.86111 | H40: =PR!H40 -> 0.65 | I40: 0.05 | J40: =H40+I40 -> 0.7 | K40: 0.1354 | L40: =(G40-G40*J40)*(1-K40) -> 66.105875
A41: * | B41: 791 | C41: CEFALEXINA 500MG C/10 COMP REV | D41: 7897076907912 | E41: Positivo | F41: 160 | G41: =VLOOKUP(B41,tABELA!C:BO,58,0) -> 24.355587 | H41: =PR!H41 -> 0.7 | I41: 0.05 | J41: =H41+I41 -> 0.75 | K41: 0.1354 | L41: =(G41-G41*J41)*(1-K41) -> 5.2644601
A42: * | B42: 790 | C42: CEFALEXINA 500MG C/8 COMP REV | D42: 7897076907905 | E42: Positivo | F42: 192 | G42: =VLOOKUP(B42,tABELA!C:BO,58,0) -> 19.486999 | H42: =PR!H42 -> 0.7 | I42: 0.05 | J42: =H42+I42 -> 0.75 | K42: 0.1354 | L42: =(G42-G42*J42)*(1-K42) -> 4.2121147
B43: 2224 | C43: CELECOXIBE 200 MG C/ 10 CAP. DURA | D43: 7897076922243 | E43: Positivo | F43: 336 | G43: =VLOOKUP(B43,tABELA!C:BO,58,0) -> 39.909778 | H43: =PR!H43 -> 0.8 | I43: 0.05 | J43: =H43+I43 -> 0.85 | K43: 0.1354 | L43: =(G43-G43*J43)*(1-K43) -> 5.1758991
B44: 2225 | C44: CELECOXIBE 200 MG C/ 15 CAP. DURA | D44: 7897076922250 | E44: Positivo | F44: 144 | G44: =VLOOKUP(B44,tABELA!C:BO,58,0) -> 59.09328 | H44: =PR!H44 -> 0.77 | I44: 0.05 | J44: =H44+I44 -> 0.82 | K44: 0.1354 | L44: =(G44-G44*J44)*(1-K44) -> 9.196569
B45: 1090 | C45: CINARIZINA 25 MG C/ 30 COMP. | D45: 7897076910905 | E45: Positivo | F45: 144 | G45: =VLOOKUP(B45,tABELA!C:BO,58,0) -> 13.241615 | H45: =PR!H45 -> 0.32 | I45: 0.05 | J45: =H45+I45 -> 0.37 | K45: 0.1354 | L45: =(G45-G45*J45)*(1-K45) -> 7.2126814
B46: 1092 | C46: CINARIZINA 75 MG C/ 30 COMP. | D46: 7897076910929 | E46: Positivo | F46: 144 | G46: =VLOOKUP(B46,tABELA!C:BO,58,0) -> 18.55823 | H46: =PR!H46 -> 0.26 | I46: 0.05 | J46: =H46+I46 -> 0.31 | K46: 0.1354 | L46: =(G46-G46*J46)*(1-K46) -> 11.071358
A47: * | B47: 1270 | C47: CITALOPRAM, BROMIDRATO DE 20 MG C/ 30 COMP. REV. | D47: 7897076912701 | E47: Positivo | F47: 288 | G47: =VLOOKUP(B47,tABELA!C:BO,58,0) -> 48.207986 | H47: =PR!H47 -> 0.84 | I47: 0.05 | J47: =H47+I47 -> 0.89 | K47: 0.1354 | L47: =(G47-G47*J47)*(1-K47) -> 4.5848687
B48: 1233 | C48: CLOPIDOGREL, BISSULFATO DE 75 MG C/ 28 COMP. REV. | D48: 7897076912336 | E48: Positivo | F48: 168 | G48: =VLOOKUP(B48,tABELA!C:BO,58,0) -> 67.117098 | H48: =PR!H48 -> 0.78 | I48: 0.05 | J48: =H48+I48 -> 0.83 | K48: 0.1354 | L48: =(G48-G48*J48)*(1-K48) -> 9.8650053
B49: 1234 | C49: CLOPIDOGREL, BISSULFATO DE 75 MG C/ 30 COMP. REV. | D49: 7897076912343 | E49: Positivo | F49: 180 | G49: =VLOOKUP(B49,tABELA!C:BO,58,0) -> 60.314429 | H49: =PR!H49 -> 0.78 | I49: 0.05 | J49: =H49+I49 -> 0.83 | K49: 0.1354 | L49: =(G49-G49*J49)*(1-K49) -> 8.8651355
B50: 2363 | C50: CLORID. DE DORZOLAMIDA + MAL. TIMOLOL 20 + 5 MG/ML SOL OFT | D50: 7897076923639 | E50: Positivo | F50: 420 | G50: =VLOOKUP(B50,tABELA!C:BO,58,0) -> 93.641288 | H50: =PR!H50 -> 0.35 | I50: 0.05 | J50: =H50+I50 -> 0.4 | K50: 0.1354 | L50: =(G50-G50*J50)*(1-K50) -> 48.577354
B51: 2187 | C51: DIVALPROATO DE SÓDIO 250 MG C/ 30 COMP. REV. LIB. PROL. | D51: 7897076921871 | E51: Positivo | F51: 72 | G51: =VLOOKUP(B51,tABELA!C:BO,58,0) -> 39.022462 | H51: =PR!H51 -> 0.45 | I51: 0.05 | J51: =H51+I51 -> 0.5 | K51: 0.1354 | L51: =(G51-G51*J51)*(1-K51) -> 16.86941
B52: 2190 | C52: DIVALPROATO DE SÓDIO 500 MG C/ 30 COMP. REV. LIB. PROL. | D52: 7897076921901 | E52: Positivo | F52: 72 | G52: =VLOOKUP(B52,tABELA!C:BO,58,0) -> 78.173035 | H52: =PR!H52 -> 0.45 | I52: 0.05 | J52: =H52+I52 -> 0.5 | K52: 0.1354 | L52: =(G52-G52*J52)*(1-K52) -> 33.794203
B53: 2329 | C53: DIVALPROATO DE SÓDIO 500 MG C/ 60 COMP. REV. LIB. PROL. | D53: 7897076923295 | E53: Positivo | F53: 48 | G53: =VLOOKUP(B53,tABELA!C:BO,58,0) -> 155.94893 | H53: =PR!H53 -> 0.55 | I53: 0.05 | J53: =H53+I53 -> 0.6 | K53: 0.1354 | L53: =(G53-G53*J53)*(1-K53) -> 53.933377
B54: 1218 | C54: DOMPERIDONA 10 MG C/ 30 COMP. | D54: 7897076912183 | E54: Negativo | F54: 144 | G54: =VLOOKUP(B54,tABELA!C:BO,58,0) -> 16.37 | H54: =PR!H54 -> 0.75 | I54: 0.05 | J54: =H54+I54 -> 0.8 | K54: 0.1075 | L54: =(G54-G54*J54)*(1-K54) -> 2.922045
...

Sheet tABELA
J1: RANBAXY FARMACÊUTICA LTDA | K1: LISTA DE PREÇOS Nº SOB ANALISE | S1: POSITIVA | V1: 1.012146 | W1: 0.725481 | X1: 1.314475 | Y1: 0.725481 | AA1: 0.72332696 | AB1: 1.305995 | AC1: =Y1 -> 0.725481 | AE1: 0.7233019 | AF1: 1.297623 | AG1: =AC1 -> 0.725481 | AI1: 0.72341662 | AJ1: 1.281197 | AK1: =AG1 -> 0.725481 | AM1: 0.72336669 | AN1: 1.273139 | AO1: =AK1 -> 0.725481 | AQ1: 0.72339585 | AR1: 1.265182 | AS1: =AO1 -> 0.725481 | AU1: 0.72342539 | AV1: 1.257324 | AW1: =AS1 -> 0.725481 | AY1: 0.72336598 | AZ1: 1.249563 | BA1: =AW1 -> 0.725481 | BC1: 0.7233957 | BD1: 1.234324 | BE1: 0.72342159 | BG1: 0.72341733 | BH1: 1.219453 | BI1: =BE1 -> 0.72342159 | BK1: 0.72341303 | BL1: 1.150166 | BM1: =BI1 -> 0.72342159 | BO1: 0.72333916
J2: a SUN PHARMA company | S2: NEGATIVA | V2: 1 | W2: 0.745454 | X2: 1.298701 | Y2: 0.745454 | AA2: 0.72339682 | AB2: 1.290323 | AC2: 0.745454 | AE2: 0.72335561 | AF2: 1.282051 | AG2: 0.745454 | AI2: 0.72336283 | AJ2: 1.265823 | AK2: 0.745454 | AM2: 0.72337755 | AN2: 1.257862 | AO2: 0.745454 | AQ2: 0.72338506 | AR2: 1.25 | AS2: 0.745454 | AU2: 0.72331155 | AV2: 1.242236 | AW2: 0.745454 | AY2: 0.7234198 | AZ2: 1.234568 | BA2: 0.745454 | BC2: 0.72334559 | BD2: 1.219512 | BE2: 0.745454 | BG2: 0.72329736 | BH2: 1.204819 | BI2: 0.745454 | BK2: 0.72330006 | BL2: 1.136364 | BM2: 0.745454 | BO2: 0.72338726
J3: AV. EUGÊNIO BORGES, 1.060 - ARSENAL - SG - RJ | K3: VIGENTE À PARTIR DE | X3: =100%-X7 -> 0.77 | AB3: =100%-AB7 -> 0.775 | AF3: =100%-AF7 -> 0.78 | AJ3: =100%-AJ7 -> 0.79 | AN3: =100%-AN7 -> 0.795 | AR3: =100%-AR7 -> 0.8 | AV3: =100%-AV7 -> 0.805 | AZ3: =100%-AZ7 -> 0.81 | BD3: =100%-BD7 -> 0.82 | BJ3: =100%-BH7 -> 0.83 | BN3: =100%-BL7 -> 0.88
J4: C.N.P.J 73.663.650/0001-90 INSC. EST. 85.396.757 | S4: CALCULO REPASSE ALIQUOTA 4%,7% E 12% | T4: 0.04 | X4: =((1-T4)-(1-X7))/(1-T4) -> 0.19791667 | AB4: =((1-T4)-(1-AB7))/(1-T4) -> 0.19270833 | AF4: =((1-T4)-(1-AF7))/(1-T4) -> 0.1875 | AJ4: =((1-T4)-(1-AJ7))/(1-T4) -> 0.17708333 | AN4: =((1-T4)-(1-AN7))/(1-T4) -> 0.171875 | AR4: =((1-T4)-(1-AR7))/(1-T4) -> 0.16666667 | AV4: =((1-T4)-(1-AV7))/(1-T4) -> 0.16145833 | AZ4: =((1-T4)-(1-AZ7))/(1-T4) -> 0.15625 | BD4: =((1-T4)-(1-BD7))/(1-T4) -> 0.14583333 | BI4: =((1-T4)-(1-BH7))/(1-T4) -> 0.13541667 | BM4: =((1-T4)-(1-BL7))/(1-T4) -> 0.083333333
T5: 0.07 | X5: =((1-T5)-(1-X7))/(1-T5) -> 0.17204301 | AB5: =((1-T5)-(1-AB7))/(1-T5) -> 0.16666667 | AF5: =((1-T5)-(1-AF7))/(1-T5) -> 0.16129032 | AJ5: =((1-T5)-(1-AJ7))/(1-T5) -> 0.15053763 | AN5: =((1-T5)-(1-AN7))/(1-T5) -> 0.14516129 | AR5: =((1-T5)-(1-AR7))/(1-T5) -> 0.13978495 | AV5: =((1-T5)-(1-AV7))/(1-T5) -> 0.1344086 | AZ5: =((1-T5)-(1-AZ7))/(1-T5) -> 0.12903226 | BD5: =((1-T5)-(1-BD7))/(1-T5) -> 0.11827957 | BI5: =((1-T5)-(1-BH7))/(1-T5) -> 0.10752688
T6: 0.12 | AV6: =((1-T6)-(1-AV7))/(1-T6) -> 0.085227273 | BI6: =((1-T6)-(1-BH7))/(1-T6) -> 0.056818182 | BM6: =((1-T6)-(1-BL7))/(1-T6) -> 0
U7: ALIQUOTA INTERNA | V7: 0 | X7: 0.23 | AB7: 0.225 | AF7: 0.22 | AJ7: 0.21 | AN7: 0.205 | AR7: 0.2 | AV7: 0.195 | AZ7: 0.19 | BD7: 0.18 | BH7: 0.17 | BL7: 0.12
Q8: 2025 | U8: ESTADOS | X8: MA | AB8: PI | AF8: RJ | AN8: BA - PE | AR8: AM - CE - PB - RN - RR - TO | AV8: PR - RO | AZ8: AC - AL - GO - PA - SE | BD8: AP | BH8: DF - ES - MT - MS - RS | BL8: MG - SC - SP
A9: <> | B9: VARIAÇÃO PREÇO | C9: CÓDIGO | D9: EAN | E9: CODIGO ANVISA | F9: GGREM | G9: NIVEL AJUSTE | H9: % Ajuste 2026 | I9: INDICE LISTA POSITIVA | J9: PRODUTO | K9: APRESENTAÇÃO | L9: CX - FECHADA | M9: PRODUTO REFERENCIA | N9: ESTADO DE DESTINO | O9: ICMS ALIQUOTA INTERESTADUAL | P9: PIS e Cofins | Q9: PF 0% | R9: PMC 0% | S9: NCM | T9: CST | U9: CEST | V9: PF - PREÇO FABRICA | W9: PMC | X9: PF - PREÇO FABRICA | Y9: PMC | Z9: PF - PREÇO FABRICA ALC | AA9: PMC ALC | AB9: PF - PREÇO FABRICA | AC9: PMC | AD9: PF - PREÇO FABRICA ALC | AE9: PMC ALC | AF9: PF - PREÇO FABRICA | AG9: PMC | AH9: PF - PREÇO FABRICA ALC | AI9: PMC ALC | AJ9: PF - PREÇO FABRICA | AK9: PMC | AL9: PF - PREÇO FABRICA ALC | AM9: PMC ALC | AN9: PF - PREÇO FABRICA | AO9: PMC | AP9: PF - PREÇO FABRICA ALC | AQ9: PMC ALC | AR9: PF - PREÇO FABRICA | AS9: PMC | AT9: PF - PREÇO FABRICA ALC | AU9: PMC ALC | AV9: PF - PREÇO FABRICA | AW9: PMC | AX9: PF - PREÇO FABRICA ALC | AY9: PMC ALC | AZ9: PF - PREÇO FABRICA | BA9: PMC | BB9: PF - PREÇO FABRICA ALC | BC9: PMC ALC | BD9: PF - PREÇO FABRICA | BE9: PMC | BF9: PF - PREÇO FABRICA ALC | BG9: PMC ALC | BH9: PF - PREÇO FABRICA | BI9: PMC | BJ9: PF - PREÇO FABRICA ALC | BK9: PMC ALC | BL9: PF - PREÇO FABRICA | BM9: PMC | BN9: PF - PREÇO FABRICA ALC | BO9: PMC ALC
B10: NÃO | C10: 1095 | D10: 7897076910950 | E10: 1235201420016 | F10: 529902801112117 | G10: Nível 1 | H10: 0.0381 | I10: 0 | J10: CLORID. DE FEXOFENADINA 120 MG | K10: ESTOJO,BLISTER C/ 10 COMP. | L10: 160 | M10: ALLEGRA | N10: SP | O10: =IF(T10=1,4%,IF(N10="RJ",22,IF(OR(N10="MG",N10="SP",N10="SC",N10="PR"),12%,7%))) -> 0.04 | P10: Negativa | Q10: 35.69 | R10: 47.88 | S10: 30049069 | T10: 1 | U10: 13.002.01 | V10: 37.04 | W10: 49.687841 | X10: 49.93 | Y10: 66.979317 | Z10: 48.103896 | AA10: 66.497246 | AB10: 47.8 | AC10: 64.121998 | AD10: 47.793548 | AE10: 66.071995 | AF10: 47.49 | AG10: 63.706144 | AH10: 47.487179 | AI10: 65.647801 | AJ10: 46.89 | AK10: 62.901266 | AL10: 46.886076 | AM10: 64.815497 | AN10: 46.6 | AO10: 62.512241 | AP10: 46.591195 | AQ10: 64.407184 | AR10: 46.31 | AS10: 62.123216 | AT10: 46.3 | AU10: 64.011145 | AV10: 46.02 | AW10: 61.734192 | AX10: 46.012422 | AY10: 63.60404 | AZ10: 45.74 | BA10: 61.358581 | BB10: 45.728395 | BC10: 63.217908 | BD10: 45.18 | BE10: 60.607361 | BF10: 45.170732 | BG10: 62.451122 | BH10: 44.63 | BI10: 59.869556 | BJ10: 44.626506 | BK10: 61.698469 | BL10: 42.1 | BM10: 56.475651 | BN10: 42.090909 | BO10: 58.185859
B11: NÃO | C11: 1097 | D11: 7897076910974 | E11: 1235201420024 | F11: 529902802119115 | G11: Nível 1 | H11: 0.0381 | I11: 0 | J11: CLORID. DE FEXOFENADINA 180 MG | K11: ESTOJO,BLISTER C/ 10 COMP. | L11: 160 | M11: ALLEGRA | N11: SP | O11: =IF(T11=1,4%,IF(N11="RJ",22,IF(OR(N11="MG",N11="SP",N11="SC",N11="PR"),12%,7%))) -> 0.04 | P11: Negativa | Q11: 54.5 | R11: 73.11 | S11: 30049069 | T11: 1 | U11: 13.002.01 | V11: 56.57 | W11: 75.886641 | X11: 76.26 | Y11: 102.30007 | Z11: 73.467532 | AA11: 101.5591 | AB11: 73 | AC11: 97.926901 | AD11: 72.993548 | AE11: 100.90963 | AF11: 72.53 | AG11: 97.296413 | AH11: 72.525641 | AI11: 100.26177 | AJ11: 71.61 | AK11: 96.062265 | AL11: 71.607595 | AM11: 98.990623 | AN11: 71.16 | AO11: 95.458606 | AP11: 71.157233 | AQ11: 98.36702 | AR11: 70.72 | AS11: 94.868362 | AT11: 70.7125 | AU11: 97.762161 | AV11: 70.28 | AW11: 94.278118 | AX11: 70.273292 | AY11: 97.140404 | AZ11: 69.84 | BA11: 93.687873 | BB11: 69.839506 | BC11: 96.550677 | BD11: 68.99 | BE11: 92.547629 | BF11: 68.987805 | BG11: 95.379589 | BH11: 68.16 | BI11: 91.434213 | BJ11: 68.156627 | BK11: 94.230086 | BL11: 64.29 | BM11: 86.242746 | BN11: 64.284091 | BO11: 88.86539
B12: NÃO | C12: 907 | D12: 7897076909077 | E12: 1235201960029 | F12: 529914602111114 | G12: Nível 3 | H12: 0.0113 | I12: 0 | J12: CLORID. DE TIZANIDINA 2 MG | K12: ESTOJO,BLISTER C/ 30 COMP. | L12: 112 | M12: SIDARLUD | N12: SP | O12: =IF(T12=1,4%,IF(N12="RJ",22,IF(OR(N12="MG",N12="SP",N12="SC",N12="PR"),12%,7%))) -> 0.04 | P12: Negativa | Q12: 27.85 | R12: 37.36 | S12: 30049077 | T12: 1 | U12: 13.002.01 | V12: 28.16 | W12: 37.775637 | X12: 36.98 | Y12: 49.607353 | Z12: 36.571429 | AA12: 50.555141 | AB12: 36.34 | AC12: 48.748816 | AD12: 36.335484 | AE12: 50.231841 | AF12: 36.1 | AG12: 48.426865 | AH12: 36.102564 | AI12: 49.909344 | AJ12: 35.65 | AK12: 47.823206 | AL12: 35.64557 | AM12: 49.276577 | AN12: 35.42 | AO12: 47.514669 | AP12: 35.421384 | AQ12: 48.966153 | AR12: 35.2 | AS12: 47.219547 | AT12: 35.2 | AU12: 48.66506 | AV12: 34.98 | AW12: 46.924425 | AX12: 34.981366 | AY12: 48.355556 | AZ12: 34.77 | BA12: 46.642717 | BB12: 34.765432 | BC12: 48.061995 | BD12: 34.34 | BE12: 46.065887 | BF12: 34.341463 | BG12: 47.479039 | BH12: 33.93 | BI12: 45.515887 | BJ12: 33.927711 | BK12: 46.906827 | BL12: 32 | BM12: 42.926861 | BN12: 32 | BO12: 44.236334
B13: NÃO | C13: 2149 | D13: 7897076921499 | E13: 1235202490026 | F13: 529918020056806 | G13: Nível 1 | H13: 0.0381 | I13: 0 | J13: DICLORID. DE LEVOCETIRIZINA 5 MG | K13: ESTOJO,BLISTER C/ 10 COMP. | L13: 160 | M13: ZYXEM | N13: SP | O13: =IF(T13=1,4%,IF(N13="RJ",22,IF(OR(N13="MG",N13="SP",N13="SC",N13="PR"),12%,7%))) -> 0.04 | P13: Negativa | Q13: 28.99 | R13: 38.9 | S13: 30049069 | T13: 1 | U13: 13.002.01 | V13: 30.09 | W13: 40.364664 | X13: 40.56 | Y13: 54.409796 | Z13: 39.077922 | AA13: 54.020036 | AB13: 38.83 | AC13: 52.089063 | AD13: 38.825806 | AE13: 53.674577 | AF13: 38.58 | AG13: 51.753696 | AH13: 38.576923 | AI13: 53.329977 | AJ13: 38.09 | AK13: 51.096379 | AL13: 38.088608 | AM13: 52.653842 | AN13: 37.85 | AO13: 50.774427 | AP13: 37.849057 | AQ13: 52.322143 | AR13: 37.61 | AS13: 50.452476 | AT13: 37.6125 | AU13: 52.000414 | AV13: 37.38 | AW13: 50.143939 | AX13: 37.378882 | AY13: 51.669697 | AZ13: 37.15 | BA13: 49.835402 | BB13: 37.148148 | BC13: 51.356017 | BD13: 36.7 | BE13: 49.231743 | BF13: 36.695122 | BG13: 50.733107 | BH13: 36.25 | BI13: 48.628084 | BJ13: 36.253012 | BK13: 50.121677 | BL13: 34.19 | BM13: 45.864668 | BN13: 34.193182 | BO13: 47.268156
B14: NÃO | C14: 1218 | D14: 7897076912183 | E14: 1235201920027 | F14: 529914502115118 | G14: Nível 1 | H14: 0.0381 | I14: 0 | J14: DOMPERIDONA 10 MG | K14: ESTOJO,BLISTER C/ 30 COMP. | L14: 144 | M14: MOTILIUM | N14: SP | O14: =IF(T14=1,4%,IF(N14="RJ",22,IF(OR(N14="MG",N14="SP",N14="SC",N14="PR"),12%,7%))) -> 0.04 | P14: Negativa | Q14: 13.09 | R14: 17.57 | S14: 30049069 | T14: 1 | U14: 13.002.01 | V14: 13.58 | W14: 18.217087 | X14: 18.3 | Y14: 24.548798 | Z14: 17.636364 | AA14: 24.37993 | AB14: 17.53 | AC14: 23.515871 | AD14: 17.522581 | AE14: 24.22402 | AF14: 17.42 | AG14: 23.36831 | AH14: 17.410256 | AI14: 24.068497 | AJ14: 17.2 | AK14: 23.073188 | AL14: 17.189873 | AM14: 23.763349 | AN14: 17.09 | AO14: 22.925627 | AP14: 17.081761 | AQ14: 23.613649 | AR14: 16.98 | AS14: 22.778065 | AT14: 16.975 | AU14: 23.468449 | AV14: 16.88 | AW14: 22.643919 | AX14: 16.869565 | AY14: 23.319192 | AZ14: 16.77 | BA14: 22.496358 | BB14: 16.765432 | BC14: 23.177624 | BD14: 16.57 | BE14: 22.228065 | BF14: 16.560976 | BG14: 22.896497 | BH14: 16.37 | BI14: 21.959772 | BJ14: 16.361446 | BK14: 22.620551 | BL14: 15.44 | BM14: 20.71221 | BN14: 15.431818 | BO14: 21.33272
B15: NÃO | C15: 1219 | D15: 7897076912190 | E15: 1235201920035 | F15: 529914501119111 | G15: Nível 1 | H15: 0.0381 | I15: 0 | J15: DOMPERIDONA 10 MG | K15: ESTOJO,BLISTER C/ 60 COMP. | L15: 120 | M15: MOTILIUM | N15: SP | O15: =IF(T15=1,4%,IF(N15="RJ",22,IF(OR(N15="MG",N15="SP",N15="SC",N15="PR"),12%,7%))) -> 0.04 | P15: Negativa | Q15: 23.43 | R15: 31.43 | S15: 30049069 | T15: 1 | U15: 13.002.01 | V15: 24.32 | W15: 32.624414 | X15: 32.78 | Y15: 43.973203 | Z15: 31.584416 | AA15: 43.661259 | AB15: 31.38 | AC15: 42.095153 | AD15: 31.380645 | AE15: 43.382044 | AF15: 31.18 | AG15: 41.82686 | AH15: 31.179487 | AI15: 43.103524 | AJ15: 30.78 | AK15: 41.290274 | AL15: 30.78481 | AM15: 42.557044 | AN15: 30.59 | AO15: 41.035396 | AP15: 30.591195 | AQ15: 42.28895 | AR15: 30.4 | AS15: 40.780518 | AT15: 30.4 | AU15: 42.028916 | AV15: 30.21 | AW15: 40.525639 | AX15: 30.21118 | AY15: 41.761616 | AZ15: 30.02 | BA15: 40.270761 | BB15: 30.024691 | BC15: 41.508087 | BD15: 29.66 | BE15: 39.787834 | BF15: 29.658537 | BG15: 41.004625 | BH15: 29.3 | BI15: 39.304907 | BJ15: 29.301205 | BK15: 40.510442 | BL15: 27.63 | BM15: 37.064661 | BN15: 27.636364 | BO15: 38.204106
B16: NÃO | C16: 678 | D16: 7897076906786 | E16: 1235200790030 | F16: 529904701115110 | G16: Nível 1 | H16: 0.0381 | I16: 0 | J16: LORATADINA 10 MG | K16: ESTOJO,BLISTER C/ 12 COMP. | L16: 144 | M16: CLARITIN | N16: SP | O16: =IF(T16=1,4%,IF(N16="RJ",22,IF(OR(N16="MG",N16="SP",N16="SC",N16="PR"),12%,7%))) -> 0.04 | P16: Negativa | Q16: 29.23 | R16: 39.22 | S16: 30049069 | T16: 1 | U16: 13.002.01 | V16: 30.34 | W16: 40.70003 | X16: 40.9 | Y16: 54.865894 | Z16: 39.402597 | AA16: 54.468856 | AB16: 39.15 | AC16: 52.518331 | AD16: 39.148387 | AE16: 54.120527 | AF16: 38.9 | AG16: 52.182965 | AH16: 38.897436 | AI16: 53.773064 | AJ16: 38.4 | AK16: 51.512233 | AL16: 38.405063 | AM16: 53.091312 | AN16: 38.16 | AO16: 51.190281 | AP16: 38.163522 | AQ16: 52.756857 | AR16: 37.92 | AS16: 50.86833 | AT16: 37.925 | AU16: 52.432455 | AV16: 37.69 | AW16: 50.559793 | AX16: 37.689441 | AY16: 52.09899 | AZ16: 37.46 | BA16: 50.251256 | BB16: 37.45679 | BC16: 51.782703 | BD16: 37 | BE16: 49.634183 | BF16: 37 | BG16: 51.154618 | BH16: 36.55 | BI16: 49.030524 | BJ16: 36.554217 | BK16: 50.538109 | BL16: 34.48 | BM16: 46.253692 | BN16: 34.477273 | BO16: 47.660879
B17: NÃO | C17: 2359 | D17: 7897076923592 | E17: 1235202940013 | F17: 529924070081006 | G17: Nível 2 | H17: 0.0247 | I17: 0 | J17: ONDANSETRONA 4 MG | K17: ESTOJO,BLISTER C/ 10 COMP. | L17: 264 | M17: VONAU FLASH | N17: SP | O17: =IF(T17=1,4%,IF(N17="RJ",22,IF(OR(N17="MG",N17="SP",N17="SC",N17="PR"),12%,7%))) -> 0.04 | P17: Negativa | Q17: 17.4 | R17: 23.34 | S17: 30049069 | T17: 1 | U17: 13.002.01 | V17: 17.82 | W17: 23.904896 | X17: 23.71 | Y17: 31.806121 | Z17: 23.142857 | AA17: 31.991925 | AB17: 23 | AC17: 30.853681 | AD17: 22.993548 | AE17: 31.787337 | AF17: 22.85 | AG17: 30.652461 | AH17: 22.846154 | AI17: 31.583256 | AJ17: 22.56 | AK17: 30.263437 | AL17: 22.556962 | AM17: 31.182834 | AN17: 22.42 | AO17: 30.075632 | AP17: 22.415094 | AQ17: 30.986394 | AR17: 22.28 | AS17: 29.887827 | AT17: 22.275 | AU17: 30.795858 | AV17: 22.14 | AW17: 29.700022 | AX17: 22.136646 | AY17: 30.6 | AZ17: 22.01 | BA17: 29.525631 | BB17: 22 | BC17: 30.414231 | BD17: 21.74 | BE17: 29.163436 | BF17: 21.731707 | BG17: 30.045329 | BH17: 21.48 | BI17: 28.814655 | BJ17: 21.46988 | BK17: 29.683227 | BL17: 20.26 | BM17: 27.178069 | BN17: 20.25 | BO17: 27.993305
B18: NÃO | C18: 2360 | D18: 7897076923608 | E18: 1235202940021 | F18: 529924070081106 | G18: Nível 2 | H18: 0.0247 | I18: 0 | J18: ONDANSETRONA 4 MG | K18: ESTOJO,BLISTER C/ 30 COMP. | L18: 264 | M18: VONAU FLASH | N18: SP | O18: =IF(T18=1,4%,IF(N18="RJ",22,IF(OR(N18="MG",N18="SP",N18="SC",N18="PR"),12%,7%))) -> 0.04 | P18: Negativa | Q18: 52.19 | R18: 70 | S18: 30049069 | T18: 1 | U18: 13.002.01 | V18: 53.47 | W18: 71.728101 | X18: 71.15 | Y18: 95.445192 | Z18: 69.441558 | AA18: 95.993729 | AB18: 69 | AC18: 92.561043 | AD18: 68.993548 | AE18: 95.379848 | AF18: 68.56 | AG18: 91.970799 | AH18: 68.551282 | AI18: 94.767493 | AJ18: 67.69 | AK18: 90.803725 | AL18: 67.683544 | AM18: 93.566 | AN18: 67.26 | AO18: 90.226895 | AP18: 67.257862 | AQ18: 92.97657 | AR18: 66.84 | AS18: 89.66348 | AT18: 66.8375 | AU18: 92.404857 | AV18: 66.43 | AW18: 89.11348 | AX18: 66.42236 | AY18: 91.817172 | AZ18: 66.02 | BA18: 88.563479 | BB18: 66.012346 | BC18: 91.259761 | BD18: 65.21 | BE18: 87.476893 | BF18: 65.207317 | BG18: 90.152848 | BH18: 64.43 | BI18: 86.430551 | BJ18: 64.421687 | BK18: 89.066337 | BL18: 60.77 | BM18: 81.520791 | BN18: 60.761364 | BO18: 83.995623
B19: NÃO | C19: 2361 | D19: 7897076923615 | E19: 1235202940031 | F19: 529924070081206 | G19: Nível 2 | H19: 0.0247 | I19: 0 | J19: ONDANSETRONA 8 MG | K19: ESTOJO,BLISTER C/ 10 COMP. | L19: 264 | M19: VONAU FLASH | N19: SP | O19: =IF(T19=1,4%,IF(N19="RJ",22,IF(OR(N19="MG",N19="SP",N19="SC",N19="PR"),12%,7%))) -> 0.04 | P19: Negativa | Q19: 34.95 | R19: 46.89 | S19: 30049069 | T19: 1 | U19: 13.002.01 | V19: 35.81 | W19: 48.03784 | X19: 47.65 | Y19: 63.920778 | Z19: 46.506494 | AA19: 64.289049 | AB19: 46.21 | AC19: 61.98907 | AD19: 46.206452 | AE19: 63.87792 | AF19: 45.91 | AG19: 61.58663 | AH19: 45.910256 | AI19: 63.467812 | AJ19: 45.33 | AK19: 60.808581 | AL19: 45.329114 | AM19: 62.663147 | AN19: 45.04 | AO19: 60.419556 | AP19: 45.044025 | AQ19: 62.268393 | AR19: 44.76 | AS19: 60.043946 | AT19: 44.7625 | AU19: 61.885505 | AV19: 44.48 | AW19: 59.668336 | AX19: 44.484472 | AY19: 61.491919 | AZ19: 44.21 | BA19: 59.306141 | BB19: 44.209877 | BC19: 61.11861 | BD19: 43.67 | BE19: 58.58175 | BF19: 43.670732 | BG19: 60.377286 | BH19: 43.14 | BI19: 57.870774 | BJ19: 43.144578 | BK19: 59.649627 | BL19: 40.69 | BM19: 54.584186 | BN19: 40.693182 | BO19: 56.253661
B20: NÃO | C20: 2362 | D20: 7897076923622 | E20: 1235202940048 | F20: 529924070081306 | G20: Nível 2 | H20: 0.0247 | I20: 0 | J20: ONDANSETRONA 8 MG | K20: ESTOJO,BLISTER C/ 30 COMP. | L20: 264 | M20: VONAU FLASH | N20: SP | O20: =IF(T20=1,4%,IF(N20="RJ",22,IF(OR(N20="MG",N20="SP",N20="SC",N20="PR"),12%,7%))) -> 0.04 | P20: Negativa | Q20: 104.92 | R20: 140.74 | S20: 30049069 | T20: 1 | U20: 13.002.01 | V20: 107.51 | W20: 144.22084 | X20: 143.07 | Y20: 191.92331 | Z20: 139.62338 | AA20: 193.01077 | AB20: 138.72 | AC20: 186.08794 | AD20: 138.72258 | AE20: 191.77646 | AF20: 137.83 | AG20: 184.89404 | AH20: 137.83333 | AI20: 190.54522 | AJ20: 136.09 | AK20: 182.55989 | AL20: 136.08861 | AM20: 188.12943 | AN20: 135.23 | AO20: 181.40623 | AP20: 135.2327 | AQ20: 186.94429 | AR20: 134.38 | AS20: 180.26599 | AT20: 134.3875 | AU20: 185.79477 | AV20: 133.55 | AW20: 179.15257 | AX20: 133.5528 | AY20: 184.61313 | AZ20: 132.73 | BA20: 178.05257 | BB20: 132.7284 | BC20: 183.49237 | BD20: 131.11 | BE20: 175.8794 | BF20: 131.10976 | BG20: 181.26674 | BH20: 129.53 | BI20: 173.75988 | BJ20: 129.53012 | BK20: 179.08214 | BL20: 122.17 | BM20: 163.88671 | BN20: 122.17045 | BO20: 168.88666
B21: NÃO | C21: 1106 | D21: 7897076911063 | E21: 1235201450047 | F21: 529906001110112 | G21: Nível 2 | H21: 0.0247 | I21: 0 | J21: SECNIDAZOL 1000 MG | K21: ESTOJO,BLISTER C/ 2 COMP. | L21: 192 | M21: SECNIDAL | N21: SP | O21: =IF(T21=1,4%,IF(N21="RJ",22,IF(OR(N21="MG",N21="SP",N21="SC",N21="PR"),12%,7%))) -> 0.04 | P21: Negativa | Q21: 11.98 | R21: 16.06 | S21: 30049069 | T21: 1 | U21: 13.002.01 | V21: 12.27 | W21: 16.459768 | X21: 16.32 | Y21: 21.892699 | Z21: 15.935065 | AA21: 22.02811 | AB21: 15.83 | AC21: 21.235381 | AD21: 15.832258 | AE21: 21.88724 | AF21: 15.73 | AG21: 21.101235 | AH21: 15.730769 | AI21: 21.74672 | AJ21: 15.53 | AK21: 20.832942 | AL21: 15.531646 | AM21: 21.471008 | AN21: 15.44 | AO21: 20.71221 | AP21: 15.433962 | AQ21: 21.335749 | AR21: 15.34 | AS21: 20.578064 | AT21: 15.3375 | AU21: 21.204556 | AV21: 15.24 | AW21: 20.443917 | AX21: 15.242236 | AY21: 21.069697 | AZ21: 15.15 | BA21: 20.323186 | BB21: 15.148148 | BC21: 20.941785 | BD21: 14.97 | BE21: 20.081722 | BF21: 14.963415 | BG21: 20.687777 | BH21: 14.79 | BI21: 19.840258 | BJ21: 14.783133 | BK21: 20.438451 | BL21: 13.94 | BM21: 18.700014 | BN21: 13.943182 | BO21: 19.274851
... B66: NÃO | C66: 1408 | D66: 7897076914088 | E66: 1235202190146 | F66: 529912030037206 | G66: Nível 1 | H66: 0.0381 | I66: 0.012 | J66: ESOMEPRAZOL MAGNÉSIO 40MG | K66: ESTOJO,BLISTER C/ 28 COMP. | L66: 108 | M66: NEXIUM | N66: SP | O66: =IF(T66=1,4%,IF(N66="RJ",22,IF(OR(N66="MG",N66="SP",N66="SC",N66="PR"),12%,7%))) -> 0.04 | P66: Positiva | Q66: 179.16 | R66: 247.68 | S66: 30049069 | T66: 1 | U66: 13.002.00 | V66: 188.21 | W66: 259.42788 | X66: 247.40763 | Y66: 341.02565 | Z66: 244.42857 | AA66: 337.92266 | AB66: 245.81154 | AC66: 338.82561 | AD66: 242.85161 | AE66: 335.75415 | AF66: 244.23578 | AG66: 336.65359 | AH66: 241.29487 | AI66: 333.54898 | AJ66: 241.14412 | AK66: 332.39205 | AL66: 238.24051 | AM66: 329.34957 | AN66: 239.62746 | AO66: 330.30149 | AP66: 236.74214 | AQ66: 327.26499 | AR66: 238.12981 | AS66: 328.23714 | AT66: 235.2625 | AU66: 325.20631 | AV66: 236.65079 | AW66: 326.19847 | AX66: 233.80124 | AY66: 323.21294 | AZ66: 235.19003 | BA66: 324.18497 | BB66: 232.35802 | BC66: 321.2046 | BD66: 232.32178 | BE66: 321.143 | BF66: 229.52439 | BG66: 317.27798 | BH66: 229.52279 | BI66: 317.27391 | BJ66: 226.75904 | BK66: 313.45722 | BL66: 216.48175 | BM66: 299.24701 | BN66: 213.875 | BO66: 295.67734
A67: * | B67: NÃO | C67: 2391 | D67: 7897076923912 | E67: 1235202960022 | F67: 529924120083206 | G67: Nível 2 | H67: 0.0247 | I67: 0.012 | J67: FENOFIBRATO 160 MG | K67: COM REV CT BL AL PLAS PVC/PCTFE TRANS X 30 | L67: 180 | M67: LIPIDIL | N67: SP | O67: =IF(T67=1,4%,IF(N67="RJ",22,IF(OR(N67="MG",N67="SP",N67="SC",N67="PR"),12%,7%))) -> 0.04 | P67: Positiva | Q67: 61.7 | R67: 85.3 | S67: 30049029 | T67: 1 | U67: 13.002.00 | V67: 63.98 | W67: 88.189767 | X67: 84.103631 | Y67: 115.9281 | Z67: 83.090909 | AA67: 114.87324 | AB67: 83.561057 | AC67: 115.18021 | AD67: 82.554839 | AE67: 114.13607 | AF67: 83.025394 | AG67: 114.44186 | AH67: 82.025641 | AI67: 113.38645 | AJ67: 81.974415 | AK67: 112.99319 | AL67: 80.987342 | AM67: 111.9589 | AN67: 81.458843 | AO67: 112.28253 | AP67: 80.477987 | AQ67: 111.25027 | AR67: 80.949732 | AS67: 111.58078 | AT67: 79.975 | AU67: 110.55045 | AV67: 80.446956 | AW67: 110.88775 | AX67: 79.478261 | AY67: 109.87282 | AZ67: 79.950387 | BA67: 110.20328 | BB67: 78.987654 | BC67: 109.19011 | BD67: 78.975355 | BE67: 109.1692 | BF67: 78.02439 | BG67: 107.8553 | BH67: 78.023868 | BI67: 107.85394 | BJ67: 77.084337 | BK67: 106.55647 | BL67: 73.590701 | BM67: 101.72588 | BN67: 72.704545 | BO67: 100.51239
